Workbook

Sheet K1 (i)
A1: COERR Language Skills Center | E1: PROGRESS REPORT - SESSION : | H1: ='To Update'!E3 -> February-July 2026 | L1: Kid Program
A2: BR: | B2: ='1'!Q3 -> C2 | C2: LEVEL: | D2: ='1'!Q2 -> K1B | E2: TIME: | F2: ='1'!W2 -> 3:00-5:30 | H2: ROOM: | I2: ='1'!AD2 -> 5 | J2: TEACHER: | K2: ='1'!X3 -> Hong Leeheng
A3: NO | B3: NAME | C3: U-L CASE | D3: ALP.SOUND | E3: ALP.NAME | F3: VOCAB | G3: SPROUTS | H3: PHONICS | I3: MATH | J3: SCIENCE | K3: TRACING | L3: ART.MUS.PE | M3: CHA.DEV | N3: NOTE
A4: 1 | B4: =IF('1'!AJ5=0,"",'1'!AJ5) -> Chhim Chansithika | C4: =IF('1'!AK5=0,"",'1'!AK5) | D4: =IF('1'!AL5=0,"",'1'!AL5) | E4: =IF('1'!AM5=0,"",'1'!AM5) | F4: =IF('1'!AN5=0,"",'1'!AN5) | G4: =IF('1'!AO5=0,"",'1'!AO5) | H4: =IF('1'!AP5=0,"",'1'!AP5) | I4: =IF('1'!AQ5=0,"",'1'!AQ5) | ... M4: =IF('1'!AU5=0,"",'1'!AU5) | N4: =IF(Classes!D7=0,"",Classes!D7)
A5: 2 | B5: =IF('2'!AJ5=0,"",'2'!AJ5) -> Chhout Senghour | C5: =IF('2'!AK5=0,"",'2'!AK5) | D5: =IF('2'!AL5=0,"",'2'!AL5) | E5: =IF('2'!AM5=0,"",'2'!AM5) | F5: =IF('2'!AN5=0,"",'2'!AN5) | G5: =IF('2'!AO5=0,"",'2'!AO5) | H5: =IF('2'!AP5=0,"",'2'!AP5) | I5: =IF('2'!AQ5=0,"",'2'!AQ5) | ... M5: =IF('2'!AU5=0,"",'2'!AU5) | N5: =IF(Classes!D8=0,"",Classes!D8)
A6: 3 | B6: =IF('3'!AJ5=0,"",'3'!AJ5) -> Det Phouri | C6: =IF('3'!AK5=0,"",'3'!AK5) | D6: =IF('3'!AL5=0,"",'3'!AL5) | E6: =IF('3'!AM5=0,"",'3'!AM5) | F6: =IF('3'!AN5=0,"",'3'!AN5) | G6: =IF('3'!AO5=0,"",'3'!AO5) | H6: =IF('3'!AP5=0,"",'3'!AP5) | I6: =IF('3'!AQ5=0,"",'3'!AQ5) | ... M6: =IF('3'!AU5=0,"",'3'!AU5) | N6: =IF(Classes!D9=0,"",Classes!D9)
A7: 4 | B7: =IF('4'!AJ5=0,"",'4'!AJ5) -> Dy Chanto | C7: =IF('4'!AK5=0,"",'4'!AK5) | D7: =IF('4'!AL5=0,"",'4'!AL5) | E7: =IF('4'!AM5=0,"",'4'!AM5) | F7: =IF('4'!AN5=0,"",'4'!AN5) | G7: =IF('4'!AO5=0,"",'4'!AO5) | H7: =IF('4'!AP5=0,"",'4'!AP5) | I7: =IF('4'!AQ5=0,"",'4'!AQ5) | ... M7: =IF('4'!AU5=0,"",'4'!AU5) | N7: =IF(Classes!D10=0,"",Classes!D10)
A8: 5 | B8: =IF('5'!AJ5=0,"",'5'!AJ5) -> Dy Meyly | C8: =IF('5'!AK5=0,"",'5'!AK5) | D8: =IF('5'!AL5=0,"",'5'!AL5) | E8: =IF('5'!AM5=0,"",'5'!AM5) | F8: =IF('5'!AN5=0,"",'5'!AN5) | G8: =IF('5'!AO5=0,"",'5'!AO5) | H8: =IF('5'!AP5=0,"",'5'!AP5) | I8: =IF('5'!AQ5=0,"",'5'!AQ5) | ... M8: =IF('5'!AU5=0,"",'5'!AU5) | N8: =IF(Classes!D11=0,"",Classes!D11)
A9: 6 | B9: =IF('6'!AJ5=0,"",'6'!AJ5) -> Heang Limhak | C9: =IF('6'!AK5=0,"",'6'!AK5) | D9: =IF('6'!AL5=0,"",'6'!AL5) | E9: =IF('6'!AM5=0,"",'6'!AM5) | F9: =IF('6'!AN5=0,"",'6'!AN5) | G9: =IF('6'!AO5=0,"",'6'!AO5) | H9: =IF('6'!AP5=0,"",'6'!AP5) | I9: =IF('6'!AQ5=0,"",'6'!AQ5) | ... M9: =IF('6'!AU5=0,"",'6'!AU5) | N9: =IF(Classes!D12=0,"",Classes!D12)
A10: 7 | B10: =IF('7'!AJ5=0,"",'7'!AJ5) -> Keo Tepsatsjak | C10: =IF('7'!AK5=0,"",'7'!AK5) | D10: =IF('7'!AL5=0,"",'7'!AL5) | E10: =IF('7'!AM5=0,"",'7'!AM5) | F10: =IF('7'!AN5=0,"",'7'!AN5) | G10: =IF('7'!AO5=0,"",'7'!AO5) | H10: =IF('7'!AP5=0,"",'7'!AP5) | I10: =IF('7'!AQ5=0,"",'7'!AQ5) | ... M10: =IF('7'!AU5=0,"",'7'!AU5) | N10: =IF(Classes!D13=0,"",Classes!D13)
A11: 8 | B11: =IF('8'!AJ5=0,"",'8'!AJ5) -> Kong Yonghae | C11: =IF('8'!AK5=0,"",'8'!AK5) | D11: =IF('8'!AL5=0,"",'8'!AL5) | E11: =IF('8'!AM5=0,"",'8'!AM5) | F11: =IF('8'!AN5=0,"",'8'!AN5) | G11: =IF('8'!AO5=0,"",'8'!AO5) | H11: =IF('8'!AP5=0,"",'8'!AP5) | I11: =IF('8'!AQ5=0,"",'8'!AQ5) | ... M11: =IF('8'!AU5=0,"",'8'!AU5) | N11: =IF(Classes!D14=0,"",Classes!D14)
A12: 9 | B12: =IF('9'!AJ5=0,"",'9'!AJ5) -> Lim Davymulika | C12: =IF('9'!AK5=0,"",'9'!AK5) | D12: =IF('9'!AL5=0,"",'9'!AL5) | E12: =IF('9'!AM5=0,"",'9'!AM5) | F12: =IF('9'!AN5=0,"",'9'!AN5) | G12: =IF('9'!AO5=0,"",'9'!AO5) | H12: =IF('9'!AP5=0,"",'9'!AP5) | I12: =IF('9'!AQ5=0,"",'9'!AQ5) | ... M12: =IF('9'!AU5=0,"",'9'!AU5) | N12: =IF(Classes!D15=0,"",Classes!D15)
A13: 10 | B13: =IF('10'!AJ5=0,"",'10'!AJ5) -> Lot SamAngvichara | C13: =IF('10'!AK5=0,"",'10'!AK5) | D13: =IF('10'!AL5=0,"",'10'!AL5) | E13: =IF('10'!AM5=0,"",'10'!AM5) | F13: =IF('10'!AN5=0,"",'10'!AN5) | G13: =IF('10'!AO5=0,"",'10'!AO5) | H13: =IF('10'!AP5=0,"",'10'!AP5) | I13: =IF('10'!AQ5=0,"",'10'!AQ5) | ... M13: =IF('10'!AU5=0,"",'10'!AU5) | N13: =IF(Classes!D16=0,"",Classes!D16)
A14: 11 | B14: =IF('11'!AJ5=0,"",'11'!AJ5) -> Lot Vichheka | C14: =IF('11'!AK5=0,"",'11'!AK5) | D14: =IF('11'!AL5=0,"",'11'!AL5) | E14: =IF('11'!AM5=0,"",'11'!AM5) | F14: =IF('11'!AN5=0,"",'11'!AN5) | G14: =IF('11'!AO5=0,"",'11'!AO5) | H14: =IF('11'!AP5=0,"",'11'!AP5) | I14: =IF('11'!AQ5=0,"",'11'!AQ5) | ... M14: =IF('11'!AU5=0,"",'11'!AU5) | N14: =IF(Classes!D17=0,"",Classes!D17)
A15: 12 | B15: =IF('12'!AJ5=0,"",'12'!AJ5) -> Ly Kanha | C15: =IF('12'!AK5=0,"",'12'!AK5) | D15: =IF('12'!AL5=0,"",'12'!AL5) | E15: =IF('12'!AM5=0,"",'12'!AM5) | F15: =IF('12'!AN5=0,"",'12'!AN5) | G15: =IF('12'!AO5=0,"",'12'!AO5) | H15: =IF('12'!AP5=0,"",'12'!AP5) | I15: =IF('12'!AQ5=0,"",'12'!AQ5) | ... M15: =IF('12'!AU5=0,"",'12'!AU5) | N15: =IF(Classes!D18=0,"",Classes!D18)
A16: 13 | B16: =IF('13'!AJ5=0,"",'13'!AJ5) -> Ly Sanmoniroth | C16: =IF('13'!AK5=0,"",'13'!AK5) | D16: =IF('13'!AL5=0,"",'13'!AL5) | E16: =IF('13'!AM5=0,"",'13'!AM5) | F16: =IF('13'!AN5=0,"",'13'!AN5) | G16: =IF('13'!AO5=0,"",'13'!AO5) | H16: =IF('13'!AP5=0,"",'13'!AP5) | I16: =IF('13'!AQ5=0,"",'13'!AQ5) | ... M16: =IF('13'!AU5=0,"",'13'!AU5) | N16: =IF(Classes!D19=0,"",Classes!D19)
A17: 14 | B17: =IF('14'!AJ5=0,"",'14'!AJ5) -> Noun Thoreakrith | C17: =IF('14'!AK5=0,"",'14'!AK5) | D17: =IF('14'!AL5=0,"",'14'!AL5) | E17: =IF('14'!AM5=0,"",'14'!AM5) | F17: =IF('14'!AN5=0,"",'14'!AN5) | G17: =IF('14'!AO5=0,"",'14'!AO5) | H17: =IF('14'!AP5=0,"",'14'!AP5) | I17: =IF('14'!AQ5=0,"",'14'!AQ5) | ... M17: =IF('14'!AU5=0,"",'14'!AU5) | N17: =IF(Classes!D20=0,"",Classes!D20)
A18: 15 | B18: =IF('15'!AJ5=0,"",'15'!AJ5) -> OL Amara | C18: =IF('15'!AK5=0,"",'15'!AK5) | D18: =IF('15'!AL5=0,"",'15'!AL5) | E18: =IF('15'!AM5=0,"",'15'!AM5) | F18: =IF('15'!AN5=0,"",'15'!AN5) | G18: =IF('15'!AO5=0,"",'15'!AO5) | H18: =IF('15'!AP5=0,"",'15'!AP5) | I18: =IF('15'!AQ5=0,"",'15'!AQ5) | ... M18: =IF('15'!AU5=0,"",'15'!AU5) | N18: =IF(Classes!D21=0,"",Classes!D21)
A19: 16 | B19: =IF('16'!AJ5=0,"",'16'!AJ5) -> Prom Monometa | C19: =IF('16'!AK5=0,"",'16'!AK5) | D19: =IF('16'!AL5=0,"",'16'!AL5) | E19: =IF('16'!AM5=0,"",'16'!AM5) | F19: =IF('16'!AN5=0,"",'16'!AN5) | G19: =IF('16'!AO5=0,"",'16'!AO5) | H19: =IF('16'!AP5=0,"",'16'!AP5) | I19: =IF('16'!AQ5=0,"",'16'!AQ5) | ... M19: =IF('16'!AU5=0,"",'16'!AU5) | N19: =IF(Classes!D22=0,"",Classes!D22)
A20: 17 | B20: =IF('17'!AJ5=0,"",'17'!AJ5) -> Seng Moamunyriangsey | C20: =IF('17'!AK5=0,"",'17'!AK5) | D20: =IF('17'!AL5=0,"",'17'!AL5) | E20: =IF('17'!AM5=0,"",'17'!AM5) | F20: =IF('17'!AN5=0,"",'17'!AN5) | G20: =IF('17'!AO5=0,"",'17'!AO5) | H20: =IF('17'!AP5=0,"",'17'!AP5) | I20: =IF('17'!AQ5=0,"",'17'!AQ5) | ... M20: =IF('17'!AU5=0,"",'17'!AU5) | N20: =IF(Classes!D23=0,"",Classes!D23)
A21: 18 | B21: =IF('18'!AJ5=0,"",'18'!AJ5) -> Thuy Chanmeylinh | C21: =IF('18'!AK5=0,"",'18'!AK5) | D21: =IF('18'!AL5=0,"",'18'!AL5) | E21: =IF('18'!AM5=0,"",'18'!AM5) | F21: =IF('18'!AN5=0,"",'18'!AN5) | G21: =IF('18'!AO5=0,"",'18'!AO5) | H21: =IF('18'!AP5=0,"",'18'!AP5) | I21: =IF('18'!AQ5=0,"",'18'!AQ5) | ... M21: =IF('18'!AU5=0,"",'18'!AU5) | N21: =IF(Classes!D24=0,"",Classes!D24)
A22: 19 | B22: =IF('19'!AJ5=0,"",'19'!AJ5) -> Vy Monineath | C22: =IF('19'!AK5=0,"",'19'!AK5) | D22: =IF('19'!AL5=0,"",'19'!AL5) | E22: =IF('19'!AM5=0,"",'19'!AM5) | F22: =IF('19'!AN5=0,"",'19'!AN5) | G22: =IF('19'!AO5=0,"",'19'!AO5) | H22: =IF('19'!AP5=0,"",'19'!AP5) | I22: =IF('19'!AQ5=0,"",'19'!AQ5) | ... M22: =IF('19'!AU5=0,"",'19'!AU5) | N22: =IF(Classes!D25=0,"",Classes!D25)
A23: 20 | B23: =IF('20'!AJ5=0,"",'20'!AJ5) | C23: =IF('20'!AK5=0,"",'20'!AK5) | D23: =IF('20'!AL5=0,"",'20'!AL5) | E23: =IF('20'!AM5=0,"",'20'!AM5) | F23: =IF('20'!AN5=0,"",'20'!AN5) | G23: =IF('20'!AO5=0,"",'20'!AO5) | H23: =IF('20'!AP5=0,"",'20'!AP5) | I23: =IF('20'!AQ5=0,"",'20'!AQ5) | ... M23: =IF('20'!AU5=0,"",'20'!AU5) | N23: =IF(Classes!D26=0,"",Classes!D26)
A24: 21 | B24: =IF('21'!AJ5=0,"",'21'!AJ5) | C24: =IF('21'!AK5=0,"",'21'!AK5) | D24: =IF('21'!AL5=0,"",'21'!AL5) | E24: =IF('21'!AM5=0,"",'21'!AM5) | F24: =IF('21'!AN5=0,"",'21'!AN5) | G24: =IF('21'!AO5=0,"",'21'!AO5) | H24: =IF('21'!AP5=0,"",'21'!AP5) | I24: =IF('21'!AQ5=0,"",'21'!AQ5) | ... M24: =IF('21'!AU5=0,"",'21'!AU5) | N24: =IF(Classes!D27=0,"",Classes!D27)
A25: 22 | B25: =IF('22'!AJ5=0,"",'22'!AJ5) | C25: =IF('22'!AK5=0,"",'22'!AK5) | D25: =IF('22'!AL5=0,"",'22'!AL5) | E25: =IF('22'!AM5=0,"",'22'!AM5) | F25: =IF('22'!AN5=0,"",'22'!AN5) | G25: =IF('22'!AO5=0,"",'22'!AO5) | H25: =IF('22'!AP5=0,"",'22'!AP5) | I25: =IF('22'!AQ5=0,"",'22'!AQ5) | ... M25: =IF('22'!AU5=0,"",'22'!AU5) | N25: =IF(Classes!D28=0,"",Classes!D28)
A26: 23 | B26: =IF('23'!AJ5=0,"",'23'!AJ5) | C26: =IF('23'!AK5=0,"",'23'!AK5) | D26: =IF('23'!AL5=0,"",'23'!AL5) | E26: =IF('23'!AM5=0,"",'23'!AM5) | F26: =IF('23'!AN5=0,"",'23'!AN5) | G26: =IF('23'!AO5=0,"",'23'!AO5) | H26: =IF('23'!AP5=0,"",'23'!AP5) | I26: =IF('23'!AQ5=0,"",'23'!AQ5) | ... M26: =IF('23'!AU5=0,"",'23'!AU5) | N26: =IF(Classes!D29=0,"",Classes!D29)
A27: 24 | B27: =IF('24'!AJ5=0,"",'24'!AJ5) | C27: =IF('24'!AK5=0,"",'24'!AK5) | D27: =IF('24'!AL5=0,"",'24'!AL5) | E27: =IF('24'!AM5=0,"",'24'!AM5) | F27: =IF('24'!AN5=0,"",'24'!AN5) | G27: =IF('24'!AO5=0,"",'24'!AO5) | H27: =IF('24'!AP5=0,"",'24'!AP5) | I27: =IF('24'!AQ5=0,"",'24'!AQ5) | ... M27: =IF('24'!AU5=0,"",'24'!AU5) | N27: =IF(Classes!D30=0,"",Classes!D30)
A28: 25 | B28: =IF('25'!AJ5=0,"",'25'!AJ5) | C28: =IF('25'!AK5=0,"",'25'!AK5) | D28: =IF('25'!AL5=0,"",'25'!AL5) | E28: =IF('25'!AM5=0,"",'25'!AM5) | F28: =IF('25'!AN5=0,"",'25'!AN5) | G28: =IF('25'!AO5=0,"",'25'!AO5) | H28: =IF('25'!AP5=0,"",'25'!AP5) | I28: =IF('25'!AQ5=0,"",'25'!AQ5) | ... M28: =IF('25'!AU5=0,"",'25'!AU5) | N28: =IF(Classes!D31=0,"",Classes!D31)
A29: 26 | B29: =IF('26'!AJ5=0,"",'26'!AJ5) | C29: =IF('26'!AK5=0,"",'26'!AK5) | D29: =IF('26'!AL5=0,"",'26'!AL5) | E29: =IF('26'!AM5=0,"",'26'!AM5) | F29: =IF('26'!AN5=0,"",'26'!AN5) | G29: =IF('26'!AO5=0,"",'26'!AO5) | H29: =IF('26'!AP5=0,"",'26'!AP5) | I29: =IF('26'!AQ5=0,"",'26'!AQ5) | ... M29: =IF('26'!AU5=0,"",'26'!AU5) | N29: =IF(Classes!D32=0,"",Classes!D32)
A30: 27 | B30: =IF('27'!AJ5=0,"",'27'!AJ5) | C30: =IF('27'!AK5=0,"",'27'!AK5) | D30: =IF('27'!AL5=0,"",'27'!AL5) | E30: =IF('27'!AM5=0,"",'27'!AM5) | F30: =IF('27'!AN5=0,"",'27'!AN5) | G30: =IF('27'!AO5=0,"",'27'!AO5) | H30: =IF('27'!AP5=0,"",'27'!AP5) | I30: =IF('27'!AQ5=0,"",'27'!AQ5) | ... M30: =IF('27'!AU5=0,"",'27'!AU5) | N30: =IF(Classes!D33=0,"",Classes!D33)
A31: 28 | B31: =IF('28'!AJ5=0,"",'28'!AJ5) | C31: =IF('28'!AK5=0,"",'28'!AK5) | D31: =IF('28'!AL5=0,"",'28'!AL5) | E31: =IF('28'!AM5=0,"",'28'!AM5) | F31: =IF('28'!AN5=0,"",'28'!AN5) | G31: =IF('28'!AO5=0,"",'28'!AO5) | H31: =IF('28'!AP5=0,"",'28'!AP5) | I31: =IF('28'!AQ5=0,"",'28'!AQ5) | ... M31: =IF('28'!AU5=0,"",'28'!AU5) | N31: =IF(Classes!D34=0,"",Classes!D34)
A32: 29 | B32: =IF('29'!AJ5=0,"",'29'!AJ5) | C32: =IF('29'!AK5=0,"",'29'!AK5) | D32: =IF('29'!AL5=0,"",'29'!AL5) | E32: =IF('29'!AM5=0,"",'29'!AM5) | F32: =IF('29'!AN5=0,"",'29'!AN5) | G32: =IF('29'!AO5=0,"",'29'!AO5) | H32: =IF('29'!AP5=0,"",'29'!AP5) | I32: =IF('29'!AQ5=0,"",'29'!AQ5) | ... M32: =IF('29'!AU5=0,"",'29'!AU5) | N32: =IF(Classes!D35=0,"",Classes!D35)
A33: 30 | B33: =IF('30'!AJ5=0,"",'30'!AJ5) | C33: =IF('30'!AK5=0,"",'30'!AK5) | D33: =IF('30'!AL5=0,"",'30'!AL5) | E33: =IF('30'!AM5=0,"",'30'!AM5) | F33: =IF('30'!AN5=0,"",'30'!AN5) | G33: =IF('30'!AO5=0,"",'30'!AO5) | H33: =IF('30'!AP5=0,"",'30'!AP5) | I33: =IF('30'!AQ5=0,"",'30'!AQ5) | ... M33: =IF('30'!AU5=0,"",'30'!AU5) | N33: =IF(Classes!D36=0,"",Classes!D36)

Sheet K1 (ii)
A1: COERR Language Skills Center | E1: PROGRESS REPORT - SESSION : | H1: ='To Update'!E3 -> February-July 2026 | L1: Kid Program
A2: BR: | B2: ='1 (2)'!Q3 -> 0 | C2: LEVEL: | D2: ='1 (2)'!Q2 -> 0 | E2: TIME: | F2: ='1 (2)'!W2 -> 0 | H2: ROOM: | I2: ='1 (2)'!AD2 -> 0 | J2: TEACHER: | K2: ='1 (2)'!X3 -> 0
A3: NO | B3: NAME | C3: U-L CASE | D3: ALP.SOUND | E3: ALP.NAME | F3: VOCAB | G3: SPROUTS | H3: PHONICS | I3: MATH | J3: SCIENCE | K3: TRACING | L3: ART.MUS.PE | M3: CHA.DEV | N3: NOTE
A4: 1 | B4: =IF('1 (2)'!AJ5=0,"",'1 (2)'!AJ5) | C4: =IF('1 (2)'!AK5=0,"",'1 (2)'!AK5) | D4: =IF('1 (2)'!AL5=0,"",'1 (2)'!AL5) | E4: =IF('1 (2)'!AM5=0,"",'1 (2)'!AM5) | F4: =IF('1 (2)'!AN5=0,"",'1 (2)'!AN5) | G4: =IF('1 (2)'!AO5=0,"",'1 (2)'!AO5) | H4: =IF('1 (2)'!AP5=0,"",'1 (2)'!AP5) | I4: =IF('1 (2)'!AQ5=0,"",'1 (2)'!AQ5) | ... M4: =IF('1 (2)'!AU5=0,"",'1 (2)'!AU5) | N4: =IF(Classes!H7=0,"",Classes!H7)
A5: 2 | B5: =IF('2 (2)'!AJ5=0,"",'2 (2)'!AJ5) | C5: =IF('2 (2)'!AK5=0,"",'2 (2)'!AK5) | D5: =IF('2 (2)'!AL5=0,"",'2 (2)'!AL5) | E5: =IF('2 (2)'!AM5=0,"",'2 (2)'!AM5) | F5: =IF('2 (2)'!AN5=0,"",'2 (2)'!AN5) | G5: =IF('2 (2)'!AO5=0,"",'2 (2)'!AO5) | H5: =IF('2 (2)'!AP5=0,"",'2 (2)'!AP5) | I5: =IF('2 (2)'!AQ5=0,"",'2 (2)'!AQ5) | ... M5: =IF('2 (2)'!AU5=0,"",'2 (2)'!AU5) | N5: =IF(Classes!H8=0,"",Classes!H8)
A6: 3 | B6: =IF('3 (2)'!AJ5=0,"",'3 (2)'!AJ5) | C6: =IF('3 (2)'!AK5=0,"",'3 (2)'!AK5) | D6: =IF('3 (2)'!AL5=0,"",'3 (2)'!AL5) | E6: =IF('3 (2)'!AM5=0,"",'3 (2)'!AM5) | F6: =IF('3 (2)'!AN5=0,"",'3 (2)'!AN5) | G6: =IF('3 (2)'!AO5=0,"",'3 (2)'!AO5) | H6: =IF('3 (2)'!AP5=0,"",'3 (2)'!AP5) | I6: =IF('3 (2)'!AQ5=0,"",'3 (2)'!AQ5) | ... M6: =IF('3 (2)'!AU5=0,"",'3 (2)'!AU5) | N6: =IF(Classes!H9=0,"",Classes!H9)
A7: 4 | B7: =IF('4 (2)'!AJ5=0,"",'4 (2)'!AJ5) | C7: =IF('4 (2)'!AK5=0,"",'4 (2)'!AK5) | D7: =IF('4 (2)'!AL5=0,"",'4 (2)'!AL5) | E7: =IF('4 (2)'!AM5=0,"",'4 (2)'!AM5) | F7: =IF('4 (2)'!AN5=0,"",'4 (2)'!AN5) | G7: =IF('4 (2)'!AO5=0,"",'4 (2)'!AO5) | H7: =IF('4 (2)'!AP5=0,"",'4 (2)'!AP5) | I7: =IF('4 (2)'!AQ5=0,"",'4 (2)'!AQ5) | ... M7: =IF('4 (2)'!AU5=0,"",'4 (2)'!AU5) | N7: =IF(Classes!H10=0,"",Classes!H10)
A8: 5 | B8: =IF('5 (2)'!AJ5=0,"",'5 (2)'!AJ5) | C8: =IF('5 (2)'!AK5=0,"",'5 (2)'!AK5) | D8: =IF('5 (2)'!AL5=0,"",'5 (2)'!AL5) | E8: =IF('5 (2)'!AM5=0,"",'5 (2)'!AM5) | F8: =IF('5 (2)'!AN5=0,"",'5 (2)'!AN5) | G8: =IF('5 (2)'!AO5=0,"",'5 (2)'!AO5) | H8: =IF('5 (2)'!AP5=0,"",'5 (2)'!AP5) | I8: =IF('5 (2)'!AQ5=0,"",'5 (2)'!AQ5) | ... M8: =IF('5 (2)'!AU5=0,"",'5 (2)'!AU5) | N8: =IF(Classes!H11=0,"",Classes!H11)
A9: 6 | B9: =IF('6 (2)'!AJ5=0,"",'6 (2)'!AJ5) | C9: =IF('6 (2)'!AK5=0,"",'6 (2)'!AK5) | D9: =IF('6 (2)'!AL5=0,"",'6 (2)'!AL5) | E9: =IF('6 (2)'!AM5=0,"",'6 (2)'!AM5) | F9: =IF('6 (2)'!AN5=0,"",'6 (2)'!AN5) | G9: =IF('6 (2)'!AO5=0,"",'6 (2)'!AO5) | H9: =IF('6 (2)'!AP5=0,"",'6 (2)'!AP5) | I9: =IF('6 (2)'!AQ5=0,"",'6 (2)'!AQ5) | ... M9: =IF('6 (2)'!AU5=0,"",'6 (2)'!AU5) | N9: =IF(Classes!H12=0,"",Classes!H12)
A10: 7 | B10: =IF('7 (2)'!AJ5=0,"",'7 (2)'!AJ5) | C10: =IF('7 (2)'!AK5=0,"",'7 (2)'!AK5) | D10: =IF('7 (2)'!AL5=0,"",'7 (2)'!AL5) | E10: =IF('7 (2)'!AM5=0,"",'7 (2)'!AM5) | F10: =IF('7 (2)'!AN5=0,"",'7 (2)'!AN5) | G10: =IF('7 (2)'!AO5=0,"",'7 (2)'!AO5) | H10: =IF('7 (2)'!AP5=0,"",'7 (2)'!AP5) | I10: =IF('7 (2)'!AQ5=0,"",'7 (2)'!AQ5) | ... M10: =IF('7 (2)'!AU5=0,"",'7 (2)'!AU5) | N10: =IF(Classes!H13=0,"",Classes!H13)
A11: 8 | B11: =IF('8 (2)'!AJ5=0,"",'8 (2)'!AJ5) | C11: =IF('8 (2)'!AK5=0,"",'8 (2)'!AK5) | D11: =IF('8 (2)'!AL5=0,"",'8 (2)'!AL5) | E11: =IF('8 (2)'!AM5=0,"",'8 (2)'!AM5) | F11: =IF('8 (2)'!AN5=0,"",'8 (2)'!AN5) | G11: =IF('8 (2)'!AO5=0,"",'8 (2)'!AO5) | H11: =IF('8 (2)'!AP5=0,"",'8 (2)'!AP5) | I11: =IF('8 (2)'!AQ5=0,"",'8 (2)'!AQ5) | ... M11: =IF('8 (2)'!AU5=0,"",'8 (2)'!AU5) | N11: =IF(Classes!H14=0,"",Classes!H14)
A12: 9 | B12: =IF('9 (2)'!AJ5=0,"",'9 (2)'!AJ5) | C12: =IF('9 (2)'!AK5=0,"",'9 (2)'!AK5) | D12: =IF('9 (2)'!AL5=0,"",'9 (2)'!AL5) | E12: =IF('9 (2)'!AM5=0,"",'9 (2)'!AM5) | F12: =IF('9 (2)'!AN5=0,"",'9 (2)'!AN5) | G12: =IF('9 (2)'!AO5=0,"",'9 (2)'!AO5) | H12: =IF('9 (2)'!AP5=0,"",'9 (2)'!AP5) | I12: =IF('9 (2)'!AQ5=0,"",'9 (2)'!AQ5) | ... M12: =IF('9 (2)'!AU5=0,"",'9 (2)'!AU5) | N12: =IF(Classes!H15=0,"",Classes!H15)
A13: 10 | B13: =IF('10 (2)'!AJ5=0,"",'10 (2)'!AJ5) | C13: =IF('10 (2)'!AK5=0,"",'10 (2)'!AK5) | D13: =IF('10 (2)'!AL5=0,"",'10 (2)'!AL5) | E13: =IF('10 (2)'!AM5=0,"",'10 (2)'!AM5) | F13: =IF('10 (2)'!AN5=0,"",'10 (2)'!AN5) | G13: =IF('10 (2)'!AO5=0,"",'10 (2)'!AO5) | H13: =IF('10 (2)'!AP5=0,"",'10 (2)'!AP5) | I13: =IF('10 (2)'!AQ5=0,"",'10 (2)'!AQ5) | ... M13: =IF('10 (2)'!AU5=0,"",'10 (2)'!AU5) | N13: =IF(Classes!H16=0,"",Classes!H16)
A14: 11 | B14: =IF('11 (2)'!AJ5=0,"",'11 (2)'!AJ5) | C14: =IF('11 (2)'!AK5=0,"",'11 (2)'!AK5) | D14: =IF('11 (2)'!AL5=0,"",'11 (2)'!AL5) | E14: =IF('11 (2)'!AM5=0,"",'11 (2)'!AM5) | F14: =IF('11 (2)'!AN5=0,"",'11 (2)'!AN5) | G14: =IF('11 (2)'!AO5=0,"",'11 (2)'!AO5) | H14: =IF('11 (2)'!AP5=0,"",'11 (2)'!AP5) | I14: =IF('11 (2)'!AQ5=0,"",'11 (2)'!AQ5) | ... M14: =IF('11 (2)'!AU5=0,"",'11 (2)'!AU5) | N14: =IF(Classes!H17=0,"",Classes!H17)
A15: 12 | B15: =IF('12 (2)'!AJ5=0,"",'12 (2)'!AJ5) | C15: =IF('12 (2)'!AK5=0,"",'12 (2)'!AK5) | D15: =IF('12 (2)'!AL5=0,"",'12 (2)'!AL5) | E15: =IF('12 (2)'!AM5=0,"",'12 (2)'!AM5) | F15: =IF('12 (2)'!AN5=0,"",'12 (2)'!AN5) | G15: =IF('12 (2)'!AO5=0,"",'12 (2)'!AO5) | H15: =IF('12 (2)'!AP5=0,"",'12 (2)'!AP5) | I15: =IF('12 (2)'!AQ5=0,"",'12 (2)'!AQ5) | ... M15: =IF('12 (2)'!AU5=0,"",'12 (2)'!AU5) | N15: =IF(Classes!H18=0,"",Classes!H18)
A16: 13 | B16: =IF('13 (2)'!AJ5=0,"",'13 (2)'!AJ5) | C16: =IF('13 (2)'!AK5=0,"",'13 (2)'!AK5) | D16: =IF('13 (2)'!AL5=0,"",'13 (2)'!AL5) | E16: =IF('13 (2)'!AM5=0,"",'13 (2)'!AM5) | F16: =IF('13 (2)'!AN5=0,"",'13 (2)'!AN5) | G16: =IF('13 (2)'!AO5=0,"",'13 (2)'!AO5) | H16: =IF('13 (2)'!AP5=0,"",'13 (2)'!AP5) | I16: =IF('13 (2)'!AQ5=0,"",'13 (2)'!AQ5) | ... M16: =IF('13 (2)'!AU5=0,"",'13 (2)'!AU5) | N16: =IF(Classes!H19=0,"",Classes!H19)
A17: 14 | B17: =IF('14 (2)'!AJ5=0,"",'14 (2)'!AJ5) | C17: =IF('14 (2)'!AK5=0,"",'14 (2)'!AK5) | D17: =IF('14 (2)'!AL5=0,"",'14 (2)'!AL5) | E17: =IF('14 (2)'!AM5=0,"",'14 (2)'!AM5) | F17: =IF('14 (2)'!AN5=0,"",'14 (2)'!AN5) | G17: =IF('14 (2)'!AO5=0,"",'14 (2)'!AO5) | H17: =IF('14 (2)'!AP5=0,"",'14 (2)'!AP5) | I17: =IF('14 (2)'!AQ5=0,"",'14 (2)'!AQ5) | ... M17: =IF('14 (2)'!AU5=0,"",'14 (2)'!AU5) | N17: =IF(Classes!H20=0,"",Classes!H20)
A18: 15 | B18: =IF('15 (2)'!AJ5=0,"",'15 (2)'!AJ5) | C18: =IF('15 (2)'!AK5=0,"",'15 (2)'!AK5) | D18: =IF('15 (2)'!AL5=0,"",'15 (2)'!AL5) | E18: =IF('15 (2)'!AM5=0,"",'15 (2)'!AM5) | F18: =IF('15 (2)'!AN5=0,"",'15 (2)'!AN5) | G18: =IF('15 (2)'!AO5=0,"",'15 (2)'!AO5) | H18: =IF('15 (2)'!AP5=0,"",'15 (2)'!AP5) | I18: =IF('15 (2)'!AQ5=0,"",'15 (2)'!AQ5) | ... M18: =IF('15 (2)'!AU5=0,"",'15 (2)'!AU5) | N18: =IF(Classes!H21=0,"",Classes!H21)
A19: 16 | B19: =IF('16 (2)'!AJ5=0,"",'16 (2)'!AJ5) | C19: =IF('16 (2)'!AK5=0,"",'16 (2)'!AK5) | D19: =IF('16 (2)'!AL5=0,"",'16 (2)'!AL5) | E19: =IF('16 (2)'!AM5=0,"",'16 (2)'!AM5) | F19: =IF('16 (2)'!AN5=0,"",'16 (2)'!AN5) | G19: =IF('16 (2)'!AO5=0,"",'16 (2)'!AO5) | H19: =IF('16 (2)'!AP5=0,"",'16 (2)'!AP5) | I19: =IF('16 (2)'!AQ5=0,"",'16 (2)'!AQ5) | ... M19: =IF('16 (2)'!AU5=0,"",'16 (2)'!AU5) | N19: =IF(Classes!H22=0,"",Classes!H22)
A20: 17 | B20: =IF('17 (2)'!AJ5=0,"",'17 (2)'!AJ5) | C20: =IF('17 (2)'!AK5=0,"",'17 (2)'!AK5) | D20: =IF('17 (2)'!AL5=0,"",'17 (2)'!AL5) | E20: =IF('17 (2)'!AM5=0,"",'17 (2)'!AM5) | F20: =IF('17 (2)'!AN5=0,"",'17 (2)'!AN5) | G20: =IF('17 (2)'!AO5=0,"",'17 (2)'!AO5) | H20: =IF('17 (2)'!AP5=0,"",'17 (2)'!AP5) | I20: =IF('17 (2)'!AQ5=0,"",'17 (2)'!AQ5) | ... M20: =IF('17 (2)'!AU5=0,"",'17 (2)'!AU5) | N20: =IF(Classes!H23=0,"",Classes!H23)
A21: 18 | B21: =IF('18 (2)'!AJ5=0,"",'18 (2)'!AJ5) | C21: =IF('18 (2)'!AK5=0,"",'18 (2)'!AK5) | D21: =IF('18 (2)'!AL5=0,"",'18 (2)'!AL5) | E21: =IF('18 (2)'!AM5=0,"",'18 (2)'!AM5) | F21: =IF('18 (2)'!AN5=0,"",'18 (2)'!AN5) | G21: =IF('18 (2)'!AO5=0,"",'18 (2)'!AO5) | H21: =IF('18 (2)'!AP5=0,"",'18 (2)'!AP5) | I21: =IF('18 (2)'!AQ5=0,"",'18 (2)'!AQ5) | ... M21: =IF('18 (2)'!AU5=0,"",'18 (2)'!AU5) | N21: =IF(Classes!H24=0,"",Classes!H24)
A22: 19 | B22: =IF('19 (2)'!AJ5=0,"",'19 (2)'!AJ5) | C22: =IF('19 (2)'!AK5=0,"",'19 (2)'!AK5) | D22: =IF('19 (2)'!AL5=0,"",'19 (2)'!AL5) | E22: =IF('19 (2)'!AM5=0,"",'19 (2)'!AM5) | F22: =IF('19 (2)'!AN5=0,"",'19 (2)'!AN5) | G22: =IF('19 (2)'!AO5=0,"",'19 (2)'!AO5) | H22: =IF('19 (2)'!AP5=0,"",'19 (2)'!AP5) | I22: =IF('19 (2)'!AQ5=0,"",'19 (2)'!AQ5) | ... M22: =IF('19 (2)'!AU5=0,"",'19 (2)'!AU5) | N22: =IF(Classes!H25=0,"",Classes!H25)
A23: 20 | B23: =IF('20 (2)'!AJ5=0,"",'20 (2)'!AJ5) | C23: =IF('20 (2)'!AK5=0,"",'20 (2)'!AK5) | D23: =IF('20 (2)'!AL5=0,"",'20 (2)'!AL5) | E23: =IF('20 (2)'!AM5=0,"",'20 (2)'!AM5) | F23: =IF('20 (2)'!AN5=0,"",'20 (2)'!AN5) | G23: =IF('20 (2)'!AO5=0,"",'20 (2)'!AO5) | H23: =IF('20 (2)'!AP5=0,"",'20 (2)'!AP5) | I23: =IF('20 (2)'!AQ5=0,"",'20 (2)'!AQ5) | ... M23: =IF('20 (2)'!AU5=0,"",'20 (2)'!AU5) | N23: =IF(Classes!H26=0,"",Classes!H26)
A24: 21 | B24: =IF('21 (2)'!AJ5=0,"",'21 (2)'!AJ5) | C24: =IF('21 (2)'!AK5=0,"",'21 (2)'!AK5) | D24: =IF('21 (2)'!AL5=0,"",'21 (2)'!AL5) | E24: =IF('21 (2)'!AM5=0,"",'21 (2)'!AM5) | F24: =IF('21 (2)'!AN5=0,"",'21 (2)'!AN5) | G24: =IF('21 (2)'!AO5=0,"",'21 (2)'!AO5) | H24: =IF('21 (2)'!AP5=0,"",'21 (2)'!AP5) | I24: =IF('21 (2)'!AQ5=0,"",'21 (2)'!AQ5) | ... M24: =IF('21 (2)'!AU5=0,"",'21 (2)'!AU5) | N24: =IF(Classes!H27=0,"",Classes!H27)
A25: 22 | B25: =IF('22 (2)'!AJ5=0,"",'22 (2)'!AJ5) | C25: =IF('22 (2)'!AK5=0,"",'22 (2)'!AK5) | D25: =IF('22 (2)'!AL5=0,"",'22 (2)'!AL5) | E25: =IF('22 (2)'!AM5=0,"",'22 (2)'!AM5) | F25: =IF('22 (2)'!AN5=0,"",'22 (2)'!AN5) | G25: =IF('22 (2)'!AO5=0,"",'22 (2)'!AO5) | H25: =IF('22 (2)'!AP5=0,"",'22 (2)'!AP5) | I25: =IF('22 (2)'!AQ5=0,"",'22 (2)'!AQ5) | ... M25: =IF('22 (2)'!AU5=0,"",'22 (2)'!AU5) | N25: =IF(Classes!H28=0,"",Classes!H28)
A26: 23 | B26: =IF('23 (2)'!AJ5=0,"",'23 (2)'!AJ5) | C26: =IF('23 (2)'!AK5=0,"",'23 (2)'!AK5) | D26: =IF('23 (2)'!AL5=0,"",'23 (2)'!AL5) | E26: =IF('23 (2)'!AM5=0,"",'23 (2)'!AM5) | F26: =IF('23 (2)'!AN5=0,"",'23 (2)'!AN5) | G26: =IF('23 (2)'!AO5=0,"",'23 (2)'!AO5) | H26: =IF('23 (2)'!AP5=0,"",'23 (2)'!AP5) | I26: =IF('23 (2)'!AQ5=0,"",'23 (2)'!AQ5) | ... M26: =IF('23 (2)'!AU5=0,"",'23 (2)'!AU5) | N26: =IF(Classes!H29=0,"",Classes!H29)
A27: 24 | B27: =IF('24 (2)'!AJ5=0,"",'24 (2)'!AJ5) | C27: =IF('24 (2)'!AK5=0,"",'24 (2)'!AK5) | D27: =IF('24 (2)'!AL5=0,"",'24 (2)'!AL5) | E27: =IF('24 (2)'!AM5=0,"",'24 (2)'!AM5) | F27: =IF('24 (2)'!AN5=0,"",'24 (2)'!AN5) | G27: =IF('24 (2)'!AO5=0,"",'24 (2)'!AO5) | H27: =IF('24 (2)'!AP5=0,"",'24 (2)'!AP5) | I27: =IF('24 (2)'!AQ5=0,"",'24 (2)'!AQ5) | ... M27: =IF('24 (2)'!AU5=0,"",'24 (2)'!AU5) | N27: =IF(Classes!H30=0,"",Classes!H30)
A28: 25 | B28: =IF('25 (2)'!AJ5=0,"",'25 (2)'!AJ5) | C28: =IF('25 (2)'!AK5=0,"",'25 (2)'!AK5) | D28: =IF('25 (2)'!AL5=0,"",'25 (2)'!AL5) | E28: =IF('25 (2)'!AM5=0,"",'25 (2)'!AM5) | F28: =IF('25 (2)'!AN5=0,"",'25 (2)'!AN5) | G28: =IF('25 (2)'!AO5=0,"",'25 (2)'!AO5) | H28: =IF('25 (2)'!AP5=0,"",'25 (2)'!AP5) | I28: =IF('25 (2)'!AQ5=0,"",'25 (2)'!AQ5) | ... M28: =IF('25 (2)'!AU5=0,"",'25 (2)'!AU5) | N28: =IF(Classes!H31=0,"",Classes!H31)
A29: 26 | B29: =IF('26 (2)'!AJ5=0,"",'26 (2)'!AJ5) | C29: =IF('26 (2)'!AK5=0,"",'26 (2)'!AK5) | D29: =IF('26 (2)'!AL5=0,"",'26 (2)'!AL5) | E29: =IF('26 (2)'!AM5=0,"",'26 (2)'!AM5) | F29: =IF('26 (2)'!AN5=0,"",'26 (2)'!AN5) | G29: =IF('26 (2)'!AO5=0,"",'26 (2)'!AO5) | H29: =IF('26 (2)'!AP5=0,"",'26 (2)'!AP5) | I29: =IF('26 (2)'!AQ5=0,"",'26 (2)'!AQ5) | ... M29: =IF('26 (2)'!AU5=0,"",'26 (2)'!AU5) | N29: =IF(Classes!H32=0,"",Classes!H32)
A30: 27 | B30: =IF('27 (2)'!AJ5=0,"",'27 (2)'!AJ5) | C30: =IF('27 (2)'!AK5=0,"",'27 (2)'!AK5) | D30: =IF('27 (2)'!AL5=0,"",'27 (2)'!AL5) | E30: =IF('27 (2)'!AM5=0,"",'27 (2)'!AM5) | F30: =IF('27 (2)'!AN5=0,"",'27 (2)'!AN5) | G30: =IF('27 (2)'!AO5=0,"",'27 (2)'!AO5) | H30: =IF('27 (2)'!AP5=0,"",'27 (2)'!AP5) | I30: =IF('27 (2)'!AQ5=0,"",'27 (2)'!AQ5) | ... M30: =IF('27 (2)'!AU5=0,"",'27 (2)'!AU5) | N30: =IF(Classes!H33=0,"",Classes!H33)
A31: 28 | B31: =IF('28 (2)'!AJ5=0,"",'28 (2)'!AJ5) | C31: =IF('28 (2)'!AK5=0,"",'28 (2)'!AK5) | D31: =IF('28 (2)'!AL5=0,"",'28 (2)'!AL5) | E31: =IF('28 (2)'!AM5=0,"",'28 (2)'!AM5) | F31: =IF('28 (2)'!AN5=0,"",'28 (2)'!AN5) | G31: =IF('28 (2)'!AO5=0,"",'28 (2)'!AO5) | H31: =IF('28 (2)'!AP5=0,"",'28 (2)'!AP5) | I31: =IF('28 (2)'!AQ5=0,"",'28 (2)'!AQ5) | ... M31: =IF('28 (2)'!AU5=0,"",'28 (2)'!AU5) | N31: =IF(Classes!H34=0,"",Classes!H34)
A32: 29 | B32: =IF('29 (2)'!AJ5=0,"",'29 (2)'!AJ5) | C32: =IF('29 (2)'!AK5=0,"",'29 (2)'!AK5) | D32: =IF('29 (2)'!AL5=0,"",'29 (2)'!AL5) | E32: =IF('29 (2)'!AM5=0,"",'29 (2)'!AM5) | F32: =IF('29 (2)'!AN5=0,"",'29 (2)'!AN5) | G32: =IF('29 (2)'!AO5=0,"",'29 (2)'!AO5) | H32: =IF('29 (2)'!AP5=0,"",'29 (2)'!AP5) | I32: =IF('29 (2)'!AQ5=0,"",'29 (2)'!AQ5) | ... M32: =IF('29 (2)'!AU5=0,"",'29 (2)'!AU5) | N32: =IF(Classes!H35=0,"",Classes!H35)
A33: 30 | B33: =IF('30 (2)'!AJ5=0,"",'30 (2)'!AJ5) | C33: =IF('30 (2)'!AK5=0,"",'30 (2)'!AK5) | D33: =IF('30 (2)'!AL5=0,"",'30 (2)'!AL5) | E33: =IF('30 (2)'!AM5=0,"",'30 (2)'!AM5) | F33: =IF('30 (2)'!AN5=0,"",'30 (2)'!AN5) | G33: =IF('30 (2)'!AO5=0,"",'30 (2)'!AO5) | H33: =IF('30 (2)'!AP5=0,"",'30 (2)'!AP5) | I33: =IF('30 (2)'!AQ5=0,"",'30 (2)'!AQ5) | ... M33: =IF('30 (2)'!AU5=0,"",'30 (2)'!AU5) | N33: =IF(Classes!H36=0,"",Classes!H36)

Sheet K1 (iii)
A1: COERR Language Skills Center | E1: PROGRESS REPORT - SESSION : | H1: ='To Update'!E3 -> February-July 2026 | L1: Kid Program
A2: BR: | B2: ='1 (3)'!Q3 -> 0 | C2: LEVEL: | D2: ='1 (3)'!Q2 -> 0 | E2: TIME: | F2: ='1 (3)'!W2 -> 0 | H2: ROOM: | I2: ='1 (3)'!AD2 -> 0 | J2: TEACHER: | K2: ='1 (3)'!X3 -> 0
A3: NO | B3: NAME | C3: U-L CASE | D3: ALP.SOUND | E3: ALP.NAME | F3: VOCAB | G3: SPROUTS | H3: PHONICS | I3: MATH | J3: SCIENCE | K3: TRACING | L3: ART.MUS.PE | M3: CHA.DEV | N3: NOTE
A4: 1 | B4: =IF('1 (3)'!AJ5=0,"",'1 (3)'!AJ5) | C4: =IF('1 (3)'!AK5=0,"",'1 (3)'!AK5) | D4: =IF('1 (3)'!AL5=0,"",'1 (3)'!AL5) | E4: =IF('1 (3)'!AM5=0,"",'1 (3)'!AM5) | F4: =IF('1 (3)'!AN5=0,"",'1 (3)'!AN5) | G4: =IF('1 (3)'!AO5=0,"",'1 (3)'!AO5) | H4: =IF('1 (3)'!AP5=0,"",'1 (3)'!AP5) | I4: =IF('1 (3)'!AQ5=0,"",'1 (3)'!AQ5) | ... M4: =IF('1 (3)'!AU5=0,"",'1 (3)'!AU5) | N4: =IF(Classes!L7=0,"",Classes!L7)
A5: 2 | B5: =IF('2 (3)'!AJ5=0,"",'2 (3)'!AJ5) | C5: =IF('2 (3)'!AK5=0,"",'2 (3)'!AK5) | D5: =IF('2 (3)'!AL5=0,"",'2 (3)'!AL5) | E5: =IF('2 (3)'!AM5=0,"",'2 (3)'!AM5) | F5: =IF('2 (3)'!AN5=0,"",'2 (3)'!AN5) | G5: =IF('2 (3)'!AO5=0,"",'2 (3)'!AO5) | H5: =IF('2 (3)'!AP5=0,"",'2 (3)'!AP5) | I5: =IF('2 (3)'!AQ5=0,"",'2 (3)'!AQ5) | ... M5: =IF('2 (3)'!AU5=0,"",'2 (3)'!AU5) | N5: =IF(Classes!L8=0,"",Classes!L8)
A6: 3 | B6: =IF('3 (3)'!AJ5=0,"",'3 (3)'!AJ5) | C6: =IF('3 (3)'!AK5=0,"",'3 (3)'!AK5) | D6: =IF('3 (3)'!AL5=0,"",'3 (3)'!AL5) | E6: =IF('3 (3)'!AM5=0,"",'3 (3)'!AM5) | F6: =IF('3 (3)'!AN5=0,"",'3 (3)'!AN5) | G6: =IF('3 (3)'!AO5=0,"",'3 (3)'!AO5) | H6: =IF('3 (3)'!AP5=0,"",'3 (3)'!AP5) | I6: =IF('3 (3)'!AQ5=0,"",'3 (3)'!AQ5) | ... M6: =IF('3 (3)'!AU5=0,"",'3 (3)'!AU5) | N6: =IF(Classes!L9=0,"",Classes!L9)
A7: 4 | B7: =IF('4 (3)'!AJ5=0,"",'4 (3)'!AJ5) | C7: =IF('4 (3)'!AK5=0,"",'4 (3)'!AK5) | D7: =IF('4 (3)'!AL5=0,"",'4 (3)'!AL5) | E7: =IF('4 (3)'!AM5=0,"",'4 (3)'!AM5) | F7: =IF('4 (3)'!AN5=0,"",'4 (3)'!AN5) | G7: =IF('4 (3)'!AO5=0,"",'4 (3)'!AO5) | H7: =IF('4 (3)'!AP5=0,"",'4 (3)'!AP5) | I7: =IF('4 (3)'!AQ5=0,"",'4 (3)'!AQ5) | ... M7: =IF('4 (3)'!AU5=0,"",'4 (3)'!AU5) | N7: =IF(Classes!L10=0,"",Classes!L10)
A8: 5 | B8: =IF('5 (3)'!AJ5=0,"",'5 (3)'!AJ5) | C8: =IF('5 (3)'!AK5=0,"",'5 (3)'!AK5) | D8: =IF('5 (3)'!AL5=0,"",'5 (3)'!AL5) | E8: =IF('5 (3)'!AM5=0,"",'5 (3)'!AM5) | F8: =IF('5 (3)'!AN5=0,"",'5 (3)'!AN5) | G8: =IF('5 (3)'!AO5=0,"",'5 (3)'!AO5) | H8: =IF('5 (3)'!AP5=0,"",'5 (3)'!AP5) | I8: =IF('5 (3)'!AQ5=0,"",'5 (3)'!AQ5) | ... M8: =IF('5 (3)'!AU5=0,"",'5 (3)'!AU5) | N8: =IF(Classes!L11=0,"",Classes!L11)
A9: 6 | B9: =IF('6 (3)'!AJ5=0,"",'6 (3)'!AJ5) | C9: =IF('6 (3)'!AK5=0,"",'6 (3)'!AK5) | D9: =IF('6 (3)'!AL5=0,"",'6 (3)'!AL5) | E9: =IF('6 (3)'!AM5=0,"",'6 (3)'!AM5) | F9: =IF('6 (3)'!AN5=0,"",'6 (3)'!AN5) | G9: =IF('6 (3)'!AO5=0,"",'6 (3)'!AO5) | H9: =IF('6 (3)'!AP5=0,"",'6 (3)'!AP5) | I9: =IF('6 (3)'!AQ5=0,"",'6 (3)'!AQ5) | ... M9: =IF('6 (3)'!AU5=0,"",'6 (3)'!AU5) | N9: =IF(Classes!L12=0,"",Classes!L12)
A10: 7 | B10: =IF('7 (3)'!AJ5=0,"",'7 (3)'!AJ5) | C10: =IF('7 (3)'!AK5=0,"",'7 (3)'!AK5) | D10: =IF('7 (3)'!AL5=0,"",'7 (3)'!AL5) | E10: =IF('7 (3)'!AM5=0,"",'7 (3)'!AM5) | F10: =IF('7 (3)'!AN5=0,"",'7 (3)'!AN5) | G10: =IF('7 (3)'!AO5=0,"",'7 (3)'!AO5) | H10: =IF('7 (3)'!AP5=0,"",'7 (3)'!AP5) | I10: =IF('7 (3)'!AQ5=0,"",'7 (3)'!AQ5) | ... M10: =IF('7 (3)'!AU5=0,"",'7 (3)'!AU5) | N10: =IF(Classes!L13=0,"",Classes!L13)
A11: 8 | B11: =IF('8 (3)'!AJ5=0,"",'8 (3)'!AJ5) | C11: =IF('8 (3)'!AK5=0,"",'8 (3)'!AK5) | D11: =IF('8 (3)'!AL5=0,"",'8 (3)'!AL5) | E11: =IF('8 (3)'!AM5=0,"",'8 (3)'!AM5) | F11: =IF('8 (3)'!AN5=0,"",'8 (3)'!AN5) | G11: =IF('8 (3)'!AO5=0,"",'8 (3)'!AO5) | H11: =IF('8 (3)'!AP5=0,"",'8 (3)'!AP5) | I11: =IF('8 (3)'!AQ5=0,"",'8 (3)'!AQ5) | ... M11: =IF('8 (3)'!AU5=0,"",'8 (3)'!AU5) | N11: =IF(Classes!L14=0,"",Classes!L14)
A12: 9 | B12: =IF('9 (3)'!AJ5=0,"",'9 (3)'!AJ5) | C12: =IF('9 (3)'!AK5=0,"",'9 (3)'!AK5) | D12: =IF('9 (3)'!AL5=0,"",'9 (3)'!AL5) | E12: =IF('9 (3)'!AM5=0,"",'9 (3)'!AM5) | F12: =IF('9 (3)'!AN5=0,"",'9 (3)'!AN5) | G12: =IF('9 (3)'!AO5=0,"",'9 (3)'!AO5) | H12: =IF('9 (3)'!AP5=0,"",'9 (3)'!AP5) | I12: =IF('9 (3)'!AQ5=0,"",'9 (3)'!AQ5) | ... M12: =IF('9 (3)'!AU5=0,"",'9 (3)'!AU5) | N12: =IF(Classes!L15=0,"",Classes!L15)
A13: 10 | B13: =IF('10 (3)'!AJ5=0,"",'10 (3)'!AJ5) | C13: =IF('10 (3)'!AK5=0,"",'10 (3)'!AK5) | D13: =IF('10 (3)'!AL5=0,"",'10 (3)'!AL5) | E13: =IF('10 (3)'!AM5=0,"",'10 (3)'!AM5) | F13: =IF('10 (3)'!AN5=0,"",'10 (3)'!AN5) | G13: =IF('10 (3)'!AO5=0,"",'10 (3)'!AO5) | H13: =IF('10 (3)'!AP5=0,"",'10 (3)'!AP5) | I13: =IF('10 (3)'!AQ5=0,"",'10 (3)'!AQ5) | ... M13: =IF('10 (3)'!AU5=0,"",'10 (3)'!AU5) | N13: =IF(Classes!L16=0,"",Classes!L16)
A14: 11 | B14: =IF('11 (3)'!AJ5=0,"",'11 (3)'!AJ5) | C14: =IF('11 (3)'!AK5=0,"",'11 (3)'!AK5) | D14: =IF('11 (3)'!AL5=0,"",'11 (3)'!AL5) | E14: =IF('11 (3)'!AM5=0,"",'11 (3)'!AM5) | F14: =IF('11 (3)'!AN5=0,"",'11 (3)'!AN5) | G14: =IF('11 (3)'!AO5=0,"",'11 (3)'!AO5) | H14: =IF('11 (3)'!AP5=0,"",'11 (3)'!AP5) | I14: =IF('11 (3)'!AQ5=0,"",'11 (3)'!AQ5) | ... M14: =IF('11 (3)'!AU5=0,"",'11 (3)'!AU5) | N14: =IF(Classes!L17=0,"",Classes!L17)
A15: 12 | B15: =IF('12 (3)'!AJ5=0,"",'12 (3)'!AJ5) | C15: =IF('12 (3)'!AK5=0,"",'12 (3)'!AK5) | D15: =IF('12 (3)'!AL5=0,"",'12 (3)'!AL5) | E15: =IF('12 (3)'!AM5=0,"",'12 (3)'!AM5) | F15: =IF('12 (3)'!AN5=0,"",'12 (3)'!AN5) | G15: =IF('12 (3)'!AO5=0,"",'12 (3)'!AO5) | H15: =IF('12 (3)'!AP5=0,"",'12 (3)'!AP5) | I15: =IF('12 (3)'!AQ5=0,"",'12 (3)'!AQ5) | ... M15: =IF('12 (3)'!AU5=0,"",'12 (3)'!AU5) | N15: =IF(Classes!L18=0,"",Classes!L18)
A16: 13 | B16: =IF('13 (3)'!AJ5=0,"",'13 (3)'!AJ5) | C16: =IF('13 (3)'!AK5=0,"",'13 (3)'!AK5) | D16: =IF('13 (3)'!AL5=0,"",'13 (3)'!AL5) | E16: =IF('13 (3)'!AM5=0,"",'13 (3)'!AM5) | F16: =IF('13 (3)'!AN5=0,"",'13 (3)'!AN5) | G16: =IF('13 (3)'!AO5=0,"",'13 (3)'!AO5) | H16: =IF('13 (3)'!AP5=0,"",'13 (3)'!AP5) | I16: =IF('13 (3)'!AQ5=0,"",'13 (3)'!AQ5) | ... M16: =IF('13 (3)'!AU5=0,"",'13 (3)'!AU5) | N16: =IF(Classes!L19=0,"",Classes!L19)
A17: 14 | B17: =IF('14 (3)'!AJ5=0,"",'14 (3)'!AJ5) | C17: =IF('14 (3)'!AK5=0,"",'14 (3)'!AK5) | D17: =IF('14 (3)'!AL5=0,"",'14 (3)'!AL5) | E17: =IF('14 (3)'!AM5=0,"",'14 (3)'!AM5) | F17: =IF('14 (3)'!AN5=0,"",'14 (3)'!AN5) | G17: =IF('14 (3)'!AO5=0,"",'14 (3)'!AO5) | H17: =IF('14 (3)'!AP5=0,"",'14 (3)'!AP5) | I17: =IF('14 (3)'!AQ5=0,"",'14 (3)'!AQ5) | ... M17: =IF('14 (3)'!AU5=0,"",'14 (3)'!AU5) | N17: =IF(Classes!L20=0,"",Classes!L20)
A18: 15 | B18: =IF('15 (3)'!AJ5=0,"",'15 (3)'!AJ5) | C18: =IF('15 (3)'!AK5=0,"",'15 (3)'!AK5) | D18: =IF('15 (3)'!AL5=0,"",'15 (3)'!AL5) | E18: =IF('15 (3)'!AM5=0,"",'15 (3)'!AM5) | F18: =IF('15 (3)'!AN5=0,"",'15 (3)'!AN5) | G18: =IF('15 (3)'!AO5=0,"",'15 (3)'!AO5) | H18: =IF('15 (3)'!AP5=0,"",'15 (3)'!AP5) | I18: =IF('15 (3)'!AQ5=0,"",'15 (3)'!AQ5) | ... M18: =IF('15 (3)'!AU5=0,"",'15 (3)'!AU5) | N18: =IF(Classes!L21=0,"",Classes!L21)
A19: 16 | B19: =IF('16 (3)'!AJ5=0,"",'16 (3)'!AJ5) | C19: =IF('16 (3)'!AK5=0,"",'16 (3)'!AK5) | D19: =IF('16 (3)'!AL5=0,"",'16 (3)'!AL5) | E19: =IF('16 (3)'!AM5=0,"",'16 (3)'!AM5) | F19: =IF('16 (3)'!AN5=0,"",'16 (3)'!AN5) | G19: =IF('16 (3)'!AO5=0,"",'16 (3)'!AO5) | H19: =IF('16 (3)'!AP5=0,"",'16 (3)'!AP5) | I19: =IF('16 (3)'!AQ5=0,"",'16 (3)'!AQ5) | ... M19: =IF('16 (3)'!AU5=0,"",'16 (3)'!AU5) | N19: =IF(Classes!L22=0,"",Classes!L22)
A20: 17 | B20: =IF('17 (3)'!AJ5=0,"",'17 (3)'!AJ5) | C20: =IF('17 (3)'!AK5=0,"",'17 (3)'!AK5) | D20: =IF('17 (3)'!AL5=0,"",'17 (3)'!AL5) | E20: =IF('17 (3)'!AM5=0,"",'17 (3)'!AM5) | F20: =IF('17 (3)'!AN5=0,"",'17 (3)'!AN5) | G20: =IF('17 (3)'!AO5=0,"",'17 (3)'!AO5) | H20: =IF('17 (3)'!AP5=0,"",'17 (3)'!AP5) | I20: =IF('17 (3)'!AQ5=0,"",'17 (3)'!AQ5) | ... M20: =IF('17 (3)'!AU5=0,"",'17 (3)'!AU5) | N20: =IF(Classes!L23=0,"",Classes!L23)
A21: 18 | B21: =IF('18 (3)'!AJ5=0,"",'18 (3)'!AJ5) | C21: =IF('18 (3)'!AK5=0,"",'18 (3)'!AK5) | D21: =IF('18 (3)'!AL5=0,"",'18 (3)'!AL5) | E21: =IF('18 (3)'!AM5=0,"",'18 (3)'!AM5) | F21: =IF('18 (3)'!AN5=0,"",'18 (3)'!AN5) | G21: =IF('18 (3)'!AO5=0,"",'18 (3)'!AO5) | H21: =IF('18 (3)'!AP5=0,"",'18 (3)'!AP5) | I21: =IF('18 (3)'!AQ5=0,"",'18 (3)'!AQ5) | ... M21: =IF('18 (3)'!AU5=0,"",'18 (3)'!AU5) | N21: =IF(Classes!L24=0,"",Classes!L24)
A22: 19 | B22: =IF('19 (3)'!AJ5=0,"",'19 (3)'!AJ5) | C22: =IF('19 (3)'!AK5=0,"",'19 (3)'!AK5) | D22: =IF('19 (3)'!AL5=0,"",'19 (3)'!AL5) | E22: =IF('19 (3)'!AM5=0,"",'19 (3)'!AM5) | F22: =IF('19 (3)'!AN5=0,"",'19 (3)'!AN5) | G22: =IF('19 (3)'!AO5=0,"",'19 (3)'!AO5) | H22: =IF('19 (3)'!AP5=0,"",'19 (3)'!AP5) | I22: =IF('19 (3)'!AQ5=0,"",'19 (3)'!AQ5) | ... M22: =IF('19 (3)'!AU5=0,"",'19 (3)'!AU5) | N22: =IF(Classes!L25=0,"",Classes!L25)
A23: 20 | B23: =IF('20 (3)'!AJ5=0,"",'20 (3)'!AJ5) | C23: =IF('20 (3)'!AK5=0,"",'20 (3)'!AK5) | D23: =IF('20 (3)'!AL5=0,"",'20 (3)'!AL5) | E23: =IF('20 (3)'!AM5=0,"",'20 (3)'!AM5) | F23: =IF('20 (3)'!AN5=0,"",'20 (3)'!AN5) | G23: =IF('20 (3)'!AO5=0,"",'20 (3)'!AO5) | H23: =IF('20 (3)'!AP5=0,"",'20 (3)'!AP5) | I23: =IF('20 (3)'!AQ5=0,"",'20 (3)'!AQ5) | ... M23: =IF('20 (3)'!AU5=0,"",'20 (3)'!AU5) | N23: =IF(Classes!L26=0,"",Classes!L26)
A24: 21 | B24: =IF('21 (3)'!AJ5=0,"",'21 (3)'!AJ5) | C24: =IF('21 (3)'!AK5=0,"",'21 (3)'!AK5) | D24: =IF('21 (3)'!AL5=0,"",'21 (3)'!AL5) | E24: =IF('21 (3)'!AM5=0,"",'21 (3)'!AM5) | F24: =IF('21 (3)'!AN5=0,"",'21 (3)'!AN5) | G24: =IF('21 (3)'!AO5=0,"",'21 (3)'!AO5) | H24: =IF('21 (3)'!AP5=0,"",'21 (3)'!AP5) | I24: =IF('21 (3)'!AQ5=0,"",'21 (3)'!AQ5) | ... M24: =IF('21 (3)'!AU5=0,"",'21 (3)'!AU5) | N24: =IF(Classes!L27=0,"",Classes!L27)
A25: 22 | B25: =IF('22 (3)'!AJ5=0,"",'22 (3)'!AJ5) | C25: =IF('22 (3)'!AK5=0,"",'22 (3)'!AK5) | D25: =IF('22 (3)'!AL5=0,"",'22 (3)'!AL5) | E25: =IF('22 (3)'!AM5=0,"",'22 (3)'!AM5) | F25: =IF('22 (3)'!AN5=0,"",'22 (3)'!AN5) | G25: =IF('22 (3)'!AO5=0,"",'22 (3)'!AO5) | H25: =IF('22 (3)'!AP5=0,"",'22 (3)'!AP5) | I25: =IF('22 (3)'!AQ5=0,"",'22 (3)'!AQ5) | ... M25: =IF('22 (3)'!AU5=0,"",'22 (3)'!AU5) | N25: =IF(Classes!L28=0,"",Classes!L28)
A26: 23 | B26: =IF('23 (3)'!AJ5=0,"",'23 (3)'!AJ5) | C26: =IF('23 (3)'!AK5=0,"",'23 (3)'!AK5) | D26: =IF('23 (3)'!AL5=0,"",'23 (3)'!AL5) | E26: =IF('23 (3)'!AM5=0,"",'23 (3)'!AM5) | F26: =IF('23 (3)'!AN5=0,"",'23 (3)'!AN5) | G26: =IF('23 (3)'!AO5=0,"",'23 (3)'!AO5) | H26: =IF('23 (3)'!AP5=0,"",'23 (3)'!AP5) | I26: =IF('23 (3)'!AQ5=0,"",'23 (3)'!AQ5) | ... M26: =IF('23 (3)'!AU5=0,"",'23 (3)'!AU5) | N26: =IF(Classes!L29=0,"",Classes!L29)
A27: 24 | B27: =IF('24 (3)'!AJ5=0,"",'24 (3)'!AJ5) | C27: =IF('24 (3)'!AK5=0,"",'24 (3)'!AK5) | D27: =IF('24 (3)'!AL5=0,"",'24 (3)'!AL5) | E27: =IF('24 (3)'!AM5=0,"",'24 (3)'!AM5) | F27: =IF('24 (3)'!AN5=0,"",'24 (3)'!AN5) | G27: =IF('24 (3)'!AO5=0,"",'24 (3)'!AO5) | H27: =IF('24 (3)'!AP5=0,"",'24 (3)'!AP5) | I27: =IF('24 (3)'!AQ5=0,"",'24 (3)'!AQ5) | ... M27: =IF('24 (3)'!AU5=0,"",'24 (3)'!AU5) | N27: =IF(Classes!L30=0,"",Classes!L30)
A28: 25 | B28: =IF('25 (3)'!AJ5=0,"",'25 (3)'!AJ5) | C28: =IF('25 (3)'!AK5=0,"",'25 (3)'!AK5) | D28: =IF('25 (3)'!AL5=0,"",'25 (3)'!AL5) | E28: =IF('25 (3)'!AM5=0,"",'25 (3)'!AM5) | F28: =IF('25 (3)'!AN5=0,"",'25 (3)'!AN5) | G28: =IF('25 (3)'!AO5=0,"",'25 (3)'!AO5) | H28: =IF('25 (3)'!AP5=0,"",'25 (3)'!AP5) | I28: =IF('25 (3)'!AQ5=0,"",'25 (3)'!AQ5) | ... M28: =IF('25 (3)'!AU5=0,"",'25 (3)'!AU5) | N28: =IF(Classes!L31=0,"",Classes!L31)
A29: 26 | B29: =IF('26 (3)'!AJ5=0,"",'26 (3)'!AJ5) | C29: =IF('26 (3)'!AK5=0,"",'26 (3)'!AK5) | D29: =IF('26 (3)'!AL5=0,"",'26 (3)'!AL5) | E29: =IF('26 (3)'!AM5=0,"",'26 (3)'!AM5) | F29: =IF('26 (3)'!AN5=0,"",'26 (3)'!AN5) | G29: =IF('26 (3)'!AO5=0,"",'26 (3)'!AO5) | H29: =IF('26 (3)'!AP5=0,"",'26 (3)'!AP5) | I29: =IF('26 (3)'!AQ5=0,"",'26 (3)'!AQ5) | ... M29: =IF('26 (3)'!AU5=0,"",'26 (3)'!AU5) | N29: =IF(Classes!L32=0,"",Classes!L32)
A30: 27 | B30: =IF('27 (3)'!AJ5=0,"",'27 (3)'!AJ5) | C30: =IF('27 (3)'!AK5=0,"",'27 (3)'!AK5) | D30: =IF('27 (3)'!AL5=0,"",'27 (3)'!AL5) | E30: =IF('27 (3)'!AM5=0,"",'27 (3)'!AM5) | F30: =IF('27 (3)'!AN5=0,"",'27 (3)'!AN5) | G30: =IF('27 (3)'!AO5=0,"",'27 (3)'!AO5) | H30: =IF('27 (3)'!AP5=0,"",'27 (3)'!AP5) | I30: =IF('27 (3)'!AQ5=0,"",'27 (3)'!AQ5) | ... M30: =IF('27 (3)'!AU5=0,"",'27 (3)'!AU5) | N30: =IF(Classes!L33=0,"",Classes!L33)
A31: 28 | B31: =IF('28 (3)'!AJ5=0,"",'28 (3)'!AJ5) | C31: =IF('28 (3)'!AK5=0,"",'28 (3)'!AK5) | D31: =IF('28 (3)'!AL5=0,"",'28 (3)'!AL5) | E31: =IF('28 (3)'!AM5=0,"",'28 (3)'!AM5) | F31: =IF('28 (3)'!AN5=0,"",'28 (3)'!AN5) | G31: =IF('28 (3)'!AO5=0,"",'28 (3)'!AO5) | H31: =IF('28 (3)'!AP5=0,"",'28 (3)'!AP5) | I31: =IF('28 (3)'!AQ5=0,"",'28 (3)'!AQ5) | ... M31: =IF('28 (3)'!AU5=0,"",'28 (3)'!AU5) | N31: =IF(Classes!L34=0,"",Classes!L34)
A32: 29 | B32: =IF('29 (3)'!AJ5=0,"",'29 (3)'!AJ5) | C32: =IF('29 (3)'!AK5=0,"",'29 (3)'!AK5) | D32: =IF('29 (3)'!AL5=0,"",'29 (3)'!AL5) | E32: =IF('29 (3)'!AM5=0,"",'29 (3)'!AM5) | F32: =IF('29 (3)'!AN5=0,"",'29 (3)'!AN5) | G32: =IF('29 (3)'!AO5=0,"",'29 (3)'!AO5) | H32: =IF('29 (3)'!AP5=0,"",'29 (3)'!AP5) | I32: =IF('29 (3)'!AQ5=0,"",'29 (3)'!AQ5) | ... M32: =IF('29 (3)'!AU5=0,"",'29 (3)'!AU5) | N32: =IF(Classes!L35=0,"",Classes!L35)
A33: 30 | B33: =IF('30 (3)'!AJ5=0,"",'30 (3)'!AJ5) | C33: =IF('30 (3)'!AK5=0,"",'30 (3)'!AK5) | D33: =IF('30 (3)'!AL5=0,"",'30 (3)'!AL5) | E33: =IF('30 (3)'!AM5=0,"",'30 (3)'!AM5) | F33: =IF('30 (3)'!AN5=0,"",'30 (3)'!AN5) | G33: =IF('30 (3)'!AO5=0,"",'30 (3)'!AO5) | H33: =IF('30 (3)'!AP5=0,"",'30 (3)'!AP5) | I33: =IF('30 (3)'!AQ5=0,"",'30 (3)'!AQ5) | ... M33: =IF('30 (3)'!AU5=0,"",'30 (3)'!AU5) | N33: =IF(Classes!L36=0,"",Classes!L36)

Sheet K1 (iv)
A1: COERR Language Skills Center | E1: PROGRESS REPORT - SESSION : | H1: ='To Update'!E3 -> February-July 2026 | L1: Kid Program
A2: BR: | B2: ='1 (4)'!Q3 -> 0 | C2: LEVEL: | D2: ='1 (4)'!Q2 -> 0 | E2: TIME: | F2: ='1 (4)'!W2 -> 0 | H2: ROOM: | I2: ='1 (4)'!AD2 -> 0 | J2: TEACHER: | K2: ='1 (4)'!X3 -> 0
A3: NO | B3: NAME | C3: U-L CASE | D3: ALP.SOUND | E3: ALP.NAME | F3: VOCAB | G3: SPROUTS | H3: PHONICS | I3: MATH | J3: SCIENCE | K3: TRACING | L3: ART.MUS.PE | M3: CHA.DEV | N3: NOTE
A4: 1 | B4: =IF('1 (4)'!AJ5=0,"",'1 (4)'!AJ5) | C4: =IF('1 (4)'!AK5=0,"",'1 (4)'!AK5) | D4: =IF('1 (4)'!AL5=0,"",'1 (4)'!AL5) | E4: =IF('1 (4)'!AM5=0,"",'1 (4)'!AM5) | F4: =IF('1 (4)'!AN5=0,"",'1 (4)'!AN5) | G4: =IF('1 (4)'!AO5=0,"",'1 (4)'!AO5) | H4: =IF('1 (4)'!AP5=0,"",'1 (4)'!AP5) | I4: =IF('1 (4)'!AQ5=0,"",'1 (4)'!AQ5) | ... M4: =IF('1 (4)'!AU5=0,"",'1 (4)'!AU5) | N4: =IF(Classes!P7=0,"",Classes!P7)
A5: 2 | B5: =IF('2 (4)'!AJ5=0,"",'2 (4)'!AJ5) | C5: =IF('2 (4)'!AK5=0,"",'2 (4)'!AK5) | D5: =IF('2 (4)'!AL5=0,"",'2 (4)'!AL5) | E5: =IF('2 (4)'!AM5=0,"",'2 (4)'!AM5) | F5: =IF('2 (4)'!AN5=0,"",'2 (4)'!AN5) | G5: =IF('2 (4)'!AO5=0,"",'2 (4)'!AO5) | H5: =IF('2 (4)'!AP5=0,"",'2 (4)'!AP5) | I5: =IF('2 (4)'!AQ5=0,"",'2 (4)'!AQ5) | ... M5: =IF('2 (4)'!AU5=0,"",'2 (4)'!AU5) | N5: =IF(Classes!L8=0,"",Classes!L8)
A6: 3 | B6: =IF('3 (4)'!AJ5=0,"",'3 (4)'!AJ5) | C6: =IF('3 (4)'!AK5=0,"",'3 (4)'!AK5) | D6: =IF('3 (4)'!AL5=0,"",'3 (4)'!AL5) | E6: =IF('3 (4)'!AM5=0,"",'3 (4)'!AM5) | F6: =IF('3 (4)'!AN5=0,"",'3 (4)'!AN5) | G6: =IF('3 (4)'!AO5=0,"",'3 (4)'!AO5) | H6: =IF('3 (4)'!AP5=0,"",'3 (4)'!AP5) | I6: =IF('3 (4)'!AQ5=0,"",'3 (4)'!AQ5) | ... M6: =IF('3 (4)'!AU5=0,"",'3 (4)'!AU5) | N6: =IF(Classes!L9=0,"",Classes!L9)
A7: 4 | B7: =IF('4 (4)'!AJ5=0,"",'4 (4)'!AJ5) | C7: =IF('4 (4)'!AK5=0,"",'4 (4)'!AK5) | D7: =IF('4 (4)'!AL5=0,"",'4 (4)'!AL5) | E7: =IF('4 (4)'!AM5=0,"",'4 (4)'!AM5) | F7: =IF('4 (4)'!AN5=0,"",'4 (4)'!AN5) | G7: =IF('4 (4)'!AO5=0,"",'4 (4)'!AO5) | H7: =IF('4 (4)'!AP5=0,"",'4 (4)'!AP5) | I7: =IF('4 (4)'!AQ5=0,"",'4 (4)'!AQ5) | ... M7: =IF('4 (4)'!AU5=0,"",'4 (4)'!AU5) | N7: =IF(Classes!L10=0,"",Classes!L10)
A8: 5 | B8: =IF('5 (4)'!AJ5=0,"",'5 (4)'!AJ5) | C8: =IF('5 (4)'!AK5=0,"",'5 (4)'!AK5) | D8: =IF('5 (4)'!AL5=0,"",'5 (4)'!AL5) | E8: =IF('5 (4)'!AM5=0,"",'5 (4)'!AM5) | F8: =IF('5 (4)'!AN5=0,"",'5 (4)'!AN5) | G8: =IF('5 (4)'!AO5=0,"",'5 (4)'!AO5) | H8: =IF('5 (4)'!AP5=0,"",'5 (4)'!AP5) | I8: =IF('5 (4)'!AQ5=0,"",'5 (4)'!AQ5) | ... M8: =IF('5 (4)'!AU5=0,"",'5 (4)'!AU5) | N8: =IF(Classes!L11=0,"",Classes!L11)
A9: 6 | B9: =IF('6 (4)'!AJ5=0,"",'6 (4)'!AJ5) | C9: =IF('6 (4)'!AK5=0,"",'6 (4)'!AK5) | D9: =IF('6 (4)'!AL5=0,"",'6 (4)'!AL5) | E9: =IF('6 (4)'!AM5=0,"",'6 (4)'!AM5) | F9: =IF('6 (4)'!AN5=0,"",'6 (4)'!AN5) | G9: =IF('6 (4)'!AO5=0,"",'6 (4)'!AO5) | H9: =IF('6 (4)'!AP5=0,"",'6 (4)'!AP5) | I9: =IF('6 (4)'!AQ5=0,"",'6 (4)'!AQ5) | ... M9: =IF('6 (4)'!AU5=0,"",'6 (4)'!AU5) | N9: =IF(Classes!L12=0,"",Classes!L12)
A10: 7 | B10: =IF('7 (4)'!AJ5=0,"",'7 (4)'!AJ5) | C10: =IF('7 (4)'!AK5=0,"",'7 (4)'!AK5) | D10: =IF('7 (4)'!AL5=0,"",'7 (4)'!AL5) | E10: =IF('7 (4)'!AM5=0,"",'7 (4)'!AM5) | F10: =IF('7 (4)'!AN5=0,"",'7 (4)'!AN5) | G10: =IF('7 (4)'!AO5=0,"",'7 (4)'!AO5) | H10: =IF('7 (4)'!AP5=0,"",'7 (4)'!AP5) | I10: =IF('7 (4)'!AQ5=0,"",'7 (4)'!AQ5) | ... M10: =IF('7 (4)'!AU5=0,"",'7 (4)'!AU5) | N10: =IF(Classes!L13=0,"",Classes!L13)
A11: 8 | B11: =IF('8 (4)'!AJ5=0,"",'8 (4)'!AJ5) | C11: =IF('8 (4)'!AK5=0,"",'8 (4)'!AK5) | D11: =IF('8 (4)'!AL5=0,"",'8 (4)'!AL5) | E11: =IF('8 (4)'!AM5=0,"",'8 (4)'!AM5) | F11: =IF('8 (4)'!AN5=0,"",'8 (4)'!AN5) | G11: =IF('8 (4)'!AO5=0,"",'8 (4)'!AO5) | H11: =IF('8 (4)'!AP5=0,"",'8 (4)'!AP5) | I11: =IF('8 (4)'!AQ5=0,"",'8 (4)'!AQ5) | ... M11: =IF('8 (4)'!AU5=0,"",'8 (4)'!AU5) | N11: =IF(Classes!L14=0,"",Classes!L14)
A12: 9 | B12: =IF('9 (4)'!AJ5=0,"",'9 (4)'!AJ5) | C12: =IF('9 (4)'!AK5=0,"",'9 (4)'!AK5) | D12: =IF('9 (4)'!AL5=0,"",'9 (4)'!AL5) | E12: =IF('9 (4)'!AM5=0,"",'9 (4)'!AM5) | F12: =IF('9 (4)'!AN5=0,"",'9 (4)'!AN5) | G12: =IF('9 (4)'!AO5=0,"",'9 (4)'!AO5) | H12: =IF('9 (4)'!AP5=0,"",'9 (4)'!AP5) | I12: =IF('9 (4)'!AQ5=0,"",'9 (4)'!AQ5) | ... M12: =IF('9 (4)'!AU5=0,"",'9 (4)'!AU5) | N12: =IF(Classes!L15=0,"",Classes!L15)
A13: 10 | B13: =IF('10 (4)'!AJ5=0,"",'10 (4)'!AJ5) | C13: =IF('10 (4)'!AK5=0,"",'10 (4)'!AK5) | D13: =IF('10 (4)'!AL5=0,"",'10 (4)'!AL5) | E13: =IF('10 (4)'!AM5=0,"",'10 (4)'!AM5) | F13: =IF('10 (4)'!AN5=0,"",'10 (4)'!AN5) | G13: =IF('10 (4)'!AO5=0,"",'10 (4)'!AO5) | H13: =IF('10 (4)'!AP5=0,"",'10 (4)'!AP5) | I13: =IF('10 (4)'!AQ5=0,"",'10 (4)'!AQ5) | ... M13: =IF('10 (4)'!AU5=0,"",'10 (4)'!AU5) | N13: =IF(Classes!L16=0,"",Classes!L16)
A14: 11 | B14: =IF('11 (4)'!AJ5=0,"",'11 (4)'!AJ5) | C14: =IF('11 (4)'!AK5=0,"",'11 (4)'!AK5) | D14: =IF('11 (4)'!AL5=0,"",'11 (4)'!AL5) | E14: =IF('11 (4)'!AM5=0,"",'11 (4)'!AM5) | F14: =IF('11 (4)'!AN5=0,"",'11 (4)'!AN5) | G14: =IF('11 (4)'!AO5=0,"",'11 (4)'!AO5) | H14: =IF('11 (4)'!AP5=0,"",'11 (4)'!AP5) | I14: =IF('11 (4)'!AQ5=0,"",'11 (4)'!AQ5) | ... M14: =IF('11 (4)'!AU5=0,"",'11 (4)'!AU5) | N14: =IF(Classes!L17=0,"",Classes!L17)
A15: 12 | B15: =IF('12 (4)'!AJ5=0,"",'12 (4)'!AJ5) | C15: =IF('12 (4)'!AK5=0,"",'12 (4)'!AK5) | D15: =IF('12 (4)'!AL5=0,"",'12 (4)'!AL5) | E15: =IF('12 (4)'!AM5=0,"",'12 (4)'!AM5) | F15: =IF('12 (4)'!AN5=0,"",'12 (4)'!AN5) | G15: =IF('12 (4)'!AO5=0,"",'12 (4)'!AO5) | H15: =IF('12 (4)'!AP5=0,"",'12 (4)'!AP5) | I15: =IF('12 (4)'!AQ5=0,"",'12 (4)'!AQ5) | ... M15: =IF('12 (4)'!AU5=0,"",'12 (4)'!AU5) | N15: =IF(Classes!L18=0,"",Classes!L18)
A16: 13 | B16: =IF('13 (4)'!AJ5=0,"",'13 (4)'!AJ5) | C16: =IF('13 (4)'!AK5=0,"",'13 (4)'!AK5) | D16: =IF('13 (4)'!AL5=0,"",'13 (4)'!AL5) | E16: =IF('13 (4)'!AM5=0,"",'13 (4)'!AM5) | F16: =IF('13 (4)'!AN5=0,"",'13 (4)'!AN5) | G16: =IF('13 (4)'!AO5=0,"",'13 (4)'!AO5) | H16: =IF('13 (4)'!AP5=0,"",'13 (4)'!AP5) | I16: =IF('13 (4)'!AQ5=0,"",'13 (4)'!AQ5) | ... M16: =IF('13 (4)'!AU5=0,"",'13 (4)'!AU5) | N16: =IF(Classes!L19=0,"",Classes!L19)
A17: 14 | B17: =IF('14 (4)'!AJ5=0,"",'14 (4)'!AJ5) | C17: =IF('14 (4)'!AK5=0,"",'14 (4)'!AK5) | D17: =IF('14 (4)'!AL5=0,"",'14 (4)'!AL5) | E17: =IF('14 (4)'!AM5=0,"",'14 (4)'!AM5) | F17: =IF('14 (4)'!AN5=0,"",'14 (4)'!AN5) | G17: =IF('14 (4)'!AO5=0,"",'14 (4)'!AO5) | H17: =IF('14 (4)'!AP5=0,"",'14 (4)'!AP5) | I17: =IF('14 (4)'!AQ5=0,"",'14 (4)'!AQ5) | ... M17: =IF('14 (4)'!AU5=0,"",'14 (4)'!AU5) | N17: =IF(Classes!L20=0,"",Classes!L20)
A18: 15 | B18: =IF('15 (4)'!AJ5=0,"",'15 (4)'!AJ5) | C18: =IF('15 (4)'!AK5=0,"",'15 (4)'!AK5) | D18: =IF('15 (4)'!AL5=0,"",'15 (4)'!AL5) | E18: =IF('15 (4)'!AM5=0,"",'15 (4)'!AM5) | F18: =IF('15 (4)'!AN5=0,"",'15 (4)'!AN5) | G18: =IF('15 (4)'!AO5=0,"",'15 (4)'!AO5) | H18: =IF('15 (4)'!AP5=0,"",'15 (4)'!AP5) | I18: =IF('15 (4)'!AQ5=0,"",'15 (4)'!AQ5) | ... M18: =IF('15 (4)'!AU5=0,"",'15 (4)'!AU5) | N18: =IF(Classes!L21=0,"",Classes!L21)
A19: 16 | B19: =IF('16 (4)'!AJ5=0,"",'16 (4)'!AJ5) | C19: =IF('16 (4)'!AK5=0,"",'16 (4)'!AK5) | D19: =IF('16 (4)'!AL5=0,"",'16 (4)'!AL5) | E19: =IF('16 (4)'!AM5=0,"",'16 (4)'!AM5) | F19: =IF('16 (4)'!AN5=0,"",'16 (4)'!AN5) | G19: =IF('16 (4)'!AO5=0,"",'16 (4)'!AO5) | H19: =IF('16 (4)'!AP5=0,"",'16 (4)'!AP5) | I19: =IF('16 (4)'!AQ5=0,"",'16 (4)'!AQ5) | ... M19: =IF('16 (4)'!AU5=0,"",'16 (4)'!AU5) | N19: =IF(Classes!L22=0,"",Classes!L22)
A20: 17 | B20: =IF('17 (4)'!AJ5=0,"",'17 (4)'!AJ5) | C20: =IF('17 (4)'!AK5=0,"",'17 (4)'!AK5) | D20: =IF('17 (4)'!AL5=0,"",'17 (4)'!AL5) | E20: =IF('17 (4)'!AM5=0,"",'17 (4)'!AM5) | F20: =IF('17 (4)'!AN5=0,"",'17 (4)'!AN5) | G20: =IF('17 (4)'!AO5=0,"",'17 (4)'!AO5) | H20: =IF('17 (4)'!AP5=0,"",'17 (4)'!AP5) | I20: =IF('17 (4)'!AQ5=0,"",'17 (4)'!AQ5) | ... M20: =IF('17 (4)'!AU5=0,"",'17 (4)'!AU5) | N20: =IF(Classes!L23=0,"",Classes!L23)
A21: 18 | B21: =IF('18 (4)'!AJ5=0,"",'18 (4)'!AJ5) | C21: =IF('18 (4)'!AK5=0,"",'18 (4)'!AK5) | D21: =IF('18 (4)'!AL5=0,"",'18 (4)'!AL5) | E21: =IF('18 (4)'!AM5=0,"",'18 (4)'!AM5) | F21: =IF('18 (4)'!AN5=0,"",'18 (4)'!AN5) | G21: =IF('18 (4)'!AO5=0,"",'18 (4)'!AO5) | H21: =IF('18 (4)'!AP5=0,"",'18 (4)'!AP5) | I21: =IF('18 (4)'!AQ5=0,"",'18 (4)'!AQ5) | ... M21: =IF('18 (4)'!AU5=0,"",'18 (4)'!AU5) | N21: =IF(Classes!L24=0,"",Classes!L24)
A22: 19 | B22: =IF('19 (4)'!AJ5=0,"",'19 (4)'!AJ5) | C22: =IF('19 (4)'!AK5=0,"",'19 (4)'!AK5) | D22: =IF('19 (4)'!AL5=0,"",'19 (4)'!AL5) | E22: =IF('19 (4)'!AM5=0,"",'19 (4)'!AM5) | F22: =IF('19 (4)'!AN5=0,"",'19 (4)'!AN5) | G22: =IF('19 (4)'!AO5=0,"",'19 (4)'!AO5) | H22: =IF('19 (4)'!AP5=0,"",'19 (4)'!AP5) | I22: =IF('19 (4)'!AQ5=0,"",'19 (4)'!AQ5) | ... M22: =IF('19 (4)'!AU5=0,"",'19 (4)'!AU5) | N22: =IF(Classes!L25=0,"",Classes!L25)
A23: 20 | B23: =IF('20 (4)'!AJ5=0,"",'20 (4)'!AJ5) | C23: =IF('20 (4)'!AK5=0,"",'20 (4)'!AK5) | D23: =IF('20 (4)'!AL5=0,"",'20 (4)'!AL5) | E23: =IF('20 (4)'!AM5=0,"",'20 (4)'!AM5) | F23: =IF('20 (4)'!AN5=0,"",'20 (4)'!AN5) | G23: =IF('20 (4)'!AO5=0,"",'20 (4)'!AO5) | H23: =IF('20 (4)'!AP5=0,"",'20 (4)'!AP5) | I23: =IF('20 (4)'!AQ5=0,"",'20 (4)'!AQ5) | ... M23: =IF('20 (4)'!AU5=0,"",'20 (4)'!AU5) | N23: =IF(Classes!L26=0,"",Classes!L26)
A24: 21 | B24: =IF('21 (4)'!AJ5=0,"",'21 (4)'!AJ5) | C24: =IF('21 (4)'!AK5=0,"",'21 (4)'!AK5) | D24: =IF('21 (4)'!AL5=0,"",'21 (4)'!AL5) | E24: =IF('21 (4)'!AM5=0,"",'21 (4)'!AM5) | F24: =IF('21 (4)'!AN5=0,"",'21 (4)'!AN5) | G24: =IF('21 (4)'!AO5=0,"",'21 (4)'!AO5) | H24: =IF('21 (4)'!AP5=0,"",'21 (4)'!AP5) | I24: =IF('21 (4)'!AQ5=0,"",'21 (4)'!AQ5) | ... M24: =IF('21 (4)'!AU5=0,"",'21 (4)'!AU5) | N24: =IF(Classes!L27=0,"",Classes!L27)
A25: 22 | B25: =IF('22 (4)'!AJ5=0,"",'22 (4)'!AJ5) | C25: =IF('22 (4)'!AK5=0,"",'22 (4)'!AK5) | D25: =IF('22 (4)'!AL5=0,"",'22 (4)'!AL5) | E25: =IF('22 (4)'!AM5=0,"",'22 (4)'!AM5) | F25: =IF('22 (4)'!AN5=0,"",'22 (4)'!AN5) | G25: =IF('22 (4)'!AO5=0,"",'22 (4)'!AO5) | H25: =IF('22 (4)'!AP5=0,"",'22 (4)'!AP5) | I25: =IF('22 (4)'!AQ5=0,"",'22 (4)'!AQ5) | ... M25: =IF('22 (4)'!AU5=0,"",'22 (4)'!AU5) | N25: =IF(Classes!L28=0,"",Classes!L28)
A26: 23 | B26: =IF('23 (4)'!AJ5=0,"",'23 (4)'!AJ5) | C26: =IF('23 (4)'!AK5=0,"",'23 (4)'!AK5) | D26: =IF('23 (4)'!AL5=0,"",'23 (4)'!AL5) | E26: =IF('23 (4)'!AM5=0,"",'23 (4)'!AM5) | F26: =IF('23 (4)'!AN5=0,"",'23 (4)'!AN5) | G26: =IF('23 (4)'!AO5=0,"",'23 (4)'!AO5) | H26: =IF('23 (4)'!AP5=0,"",'23 (4)'!AP5) | I26: =IF('23 (4)'!AQ5=0,"",'23 (4)'!AQ5) | ... M26: =IF('23 (4)'!AU5=0,"",'23 (4)'!AU5) | N26: =IF(Classes!L29=0,"",Classes!L29)
A27: 24 | B27: =IF('24 (4)'!AJ5=0,"",'24 (4)'!AJ5) | C27: =IF('24 (4)'!AK5=0,"",'24 (4)'!AK5) | D27: =IF('24 (4)'!AL5=0,"",'24 (4)'!AL5) | E27: =IF('24 (4)'!AM5=0,"",'24 (4)'!AM5) | F27: =IF('24 (4)'!AN5=0,"",'24 (4)'!AN5) | G27: =IF('24 (4)'!AO5=0,"",'24 (4)'!AO5) | H27: =IF('24 (4)'!AP5=0,"",'24 (4)'!AP5) | I27: =IF('24 (4)'!AQ5=0,"",'24 (4)'!AQ5) | ... M27: =IF('24 (4)'!AU5=0,"",'24 (4)'!AU5) | N27: =IF(Classes!L30=0,"",Classes!L30)
A28: 25 | B28: =IF('25 (4)'!AJ5=0,"",'25 (4)'!AJ5) | C28: =IF('25 (4)'!AK5=0,"",'25 (4)'!AK5) | D28: =IF('25 (4)'!AL5=0,"",'25 (4)'!AL5) | E28: =IF('25 (4)'!AM5=0,"",'25 (4)'!AM5) | F28: =IF('25 (4)'!AN5=0,"",'25 (4)'!AN5) | G28: =IF('25 (4)'!AO5=0,"",'25 (4)'!AO5) | H28: =IF('25 (4)'!AP5=0,"",'25 (4)'!AP5) | I28: =IF('25 (4)'!AQ5=0,"",'25 (4)'!AQ5) | ... M28: =IF('25 (4)'!AU5=0,"",'25 (4)'!AU5) | N28: =IF(Classes!L31=0,"",Classes!L31)
A29: 26 | B29: =IF('26 (4)'!AJ5=0,"",'26 (4)'!AJ5) | C29: =IF('26 (4)'!AK5=0,"",'26 (4)'!AK5) | D29: =IF('26 (4)'!AL5=0,"",'26 (4)'!AL5) | E29: =IF('26 (4)'!AM5=0,"",'26 (4)'!AM5) | F29: =IF('26 (4)'!AN5=0,"",'26 (4)'!AN5) | G29: =IF('26 (4)'!AO5=0,"",'26 (4)'!AO5) | H29: =IF('26 (4)'!AP5=0,"",'26 (4)'!AP5) | I29: =IF('26 (4)'!AQ5=0,"",'26 (4)'!AQ5) | ... M29: =IF('26 (4)'!AU5=0,"",'26 (4)'!AU5) | N29: =IF(Classes!L32=0,"",Classes!L32)
A30: 27 | B30: =IF('27 (4)'!AJ5=0,"",'27 (4)'!AJ5) | C30: =IF('27 (4)'!AK5=0,"",'27 (4)'!AK5) | D30: =IF('27 (4)'!AL5=0,"",'27 (4)'!AL5) | E30: =IF('27 (4)'!AM5=0,"",'27 (4)'!AM5) | F30: =IF('27 (4)'!AN5=0,"",'27 (4)'!AN5) | G30: =IF('27 (4)'!AO5=0,"",'27 (4)'!AO5) | H30: =IF('27 (4)'!AP5=0,"",'27 (4)'!AP5) | I30: =IF('27 (4)'!AQ5=0,"",'27 (4)'!AQ5) | ... M30: =IF('27 (4)'!AU5=0,"",'27 (4)'!AU5) | N30: =IF(Classes!L33=0,"",Classes!L33)
A31: 28 | B31: =IF('28 (4)'!AJ5=0,"",'28 (4)'!AJ5) | C31: =IF('28 (4)'!AK5=0,"",'28 (4)'!AK5) | D31: =IF('28 (4)'!AL5=0,"",'28 (4)'!AL5) | E31: =IF('28 (4)'!AM5=0,"",'28 (4)'!AM5) | F31: =IF('28 (4)'!AN5=0,"",'28 (4)'!AN5) | G31: =IF('28 (4)'!AO5=0,"",'28 (4)'!AO5) | H31: =IF('28 (4)'!AP5=0,"",'28 (4)'!AP5) | I31: =IF('28 (4)'!AQ5=0,"",'28 (4)'!AQ5) | ... M31: =IF('28 (4)'!AU5=0,"",'28 (4)'!AU5) | N31: =IF(Classes!L34=0,"",Classes!L34)
A32: 29 | B32: =IF('29 (4)'!AJ5=0,"",'29 (4)'!AJ5) | C32: =IF('29 (4)'!AK5=0,"",'29 (4)'!AK5) | D32: =IF('29 (4)'!AL5=0,"",'29 (4)'!AL5) | E32: =IF('29 (4)'!AM5=0,"",'29 (4)'!AM5) | F32: =IF('29 (4)'!AN5=0,"",'29 (4)'!AN5) | G32: =IF('29 (4)'!AO5=0,"",'29 (4)'!AO5) | H32: =IF('29 (4)'!AP5=0,"",'29 (4)'!AP5) | I32: =IF('29 (4)'!AQ5=0,"",'29 (4)'!AQ5) | ... M32: =IF('29 (4)'!AU5=0,"",'29 (4)'!AU5) | N32: =IF(Classes!L35=0,"",Classes!L35)
A33: 30 | B33: =IF('30 (4)'!AJ5=0,"",'30 (4)'!AJ5) | C33: =IF('30 (4)'!AK5=0,"",'30 (4)'!AK5) | D33: =IF('30 (4)'!AL5=0,"",'30 (4)'!AL5) | E33: =IF('30 (4)'!AM5=0,"",'30 (4)'!AM5) | F33: =IF('30 (4)'!AN5=0,"",'30 (4)'!AN5) | G33: =IF('30 (4)'!AO5=0,"",'30 (4)'!AO5) | H33: =IF('30 (4)'!AP5=0,"",'30 (4)'!AP5) | I33: =IF('30 (4)'!AQ5=0,"",'30 (4)'!AQ5) | ... M33: =IF('30 (4)'!AU5=0,"",'30 (4)'!AU5) | N33: =IF(Classes!L36=0,"",Classes!L36)

Sheet To Update
A1: PROGRESS REPORT : DAILY EVALUATION
A2: NAME: | D2: =Classes!B7 -> Chhim Chansithika | N2: LEVEL: | Q2: =Classes!B2 -> K1B | U2: TIME: | W2: =Classes!B3 -> 3:00-5:30 | AB2: ROOM: | AD2: =Classes!B4 -> 5
A3: SESSION: | E3: February-July 2026 | N3: BRANCH: | Q3: =Classes!B1 -> C2 | U3: TEACHER: | X3: =Classes!B5 -> Hong Leeheng
A4: DESCRIPTIONS | O4: MIDTERM | Y4: PROMOTION
O5: FEB | R5: =IF(O5="FEB","MAR","SEP") -> MAR | U5: =IF(R5="MAR","APR","OCT") -> APR | X5: AV | Y5: =IF(U5="APR","MAY","NOV") -> MAY | AB5: =IF(Y5="MAY","JUN","DEC") -> JUN | AE5: =IF(AB5="JUN","JUL","JAN") -> JUL | AH5: AV
D10: Update:
G12: Æ | I12: Session
G14: Æ | I14: First month of the session

Sheet Guide
A1: HOW TO RECORD PROGRESS REPORT SCORES
A2: In order to record the scores of progress report,
B3:  | C3: go to "Classes"
B4:  | C4: click on the ordinal number of any kid you want to record the scores
C5: For example, you click on "15" of K1 from 3:00 to 5:00 if you want to record the score for "Phy Sorphea"
B29:  | C29: now as you reach the page for "Phy Sorphea", you can record the score
B30:  | C30: after you do so, you should click right mose on the left scroller " < " at the bottom left in order to go back to "Classes"
B57:  | C57: when you click right mose on the left scroller " < " at the bottom left, the Activate boad appears
B58:  | C58: click on "Classes" and then "OK"

Sheet Classes
A1: Br: | B1: C2 | E1: Br: | I1: Br: | M1: Br:
A2: Level: | B2: K1B | E2: Level: | I2: Level: | M2: Level:
A3: Time: | B3: 3:00-5:30 | E3: Time: | I3: Time: | M3: Time:
A4: Room: | B4: 5 | D4: Stop | E4: Room: | H4: Stop | I4: Room: | L4: Stop | M4: Room: | P4: Stop
A5: TR: | B5: Hong Leeheng | D5: Change | E5: TR: | H5: Change | I5: TR: | L5: Change | M5: TR: | P5: Change
A6: No | B6: Name | C6: Sex | D6: Note | E6: No | F6: Name | G6: Sex | H6: Note | I6: No | J6: Name | K6: Sex | L6: Note | M6: No | N6: Name | O6: Sex | P6: Note
A7: 1 | B7: Chhim Chansithika | C7: F | E7: 1 | I7: 1 | M7: 1
A8: 2 | B8: Chhout Senghour | C8: M | E8: 2 | I8: 2 | M8: 2
A9: 3 | B9: Det Phouri | C9: M | E9: 3 | I9: 3 | M9: 3
A10: 4 | B10: Dy Chanto | C10: M | E10: 4 | I10: 4 | M10: 4
A11: 5 | B11: Dy Meyly | C11: F | E11: 5 | I11: 5 | M11: 5
A12: 6 | B12: Heang Limhak | C12: M | E12: 6 | I12: 6 | M12: 6
A13: 7 | B13: Keo Tepsatsjak | C13: M | E13: 7 | I13: 7 | M13: 7
A14: 8 | B14: Kong Yonghae | C14: M | E14: 8 | I14: 8 | M14: 8
A15: 9 | B15: Lim Davymulika | C15: F | E15: 9 | I15: 9 | M15: 9
A16: 10 | B16: Lot SamAngvichara | C16: F | E16: 10 | I16: 10 | M16: 10
A17: 11 | B17: Lot Vichheka | C17: M | E17: 11 | I17: 11 | M17: 11
A18: 12 | B18: Ly Kanha | C18: F | E18: 12 | I18: 12 | M18: 12
... A25: 19 | B25: Vy Monineath | C25: F | E25: 19 | I25: 19 | M25: 19
A26: 20 | E26: 20 | I26: 20 | M26: 20
A27: 21 | E27: 21 | I27: 21 | M27: 21
A28: 22 | E28: 22 | I28: 22 | M28: 22
A29: 23 | E29: 23 | I29: 23 | M29: 23
A30: 24 | E30: 24 | I30: 24 | M30: 24
A31: 25 | E31: 25 | I31: 25 | M31: 25
A32: 26 | E32: 26 | I32: 26 | M32: 26
A33: 27 | E33: 27 | I33: 27 | M33: 27
A34: 28 | E34: 28 | I34: 28 | M34: 28
A35: 29 | E35: 29 | I35: 29 | M35: 29
A36: 30 | E36: 30 | I36: 30 | M36: 30

Sheet 1
A1: PROGRESS REPORT : DAILY EVALUATION | AJ1: DO NOT DO ANYTHING
A2: NAME: | D2: =Classes!B7 -> Chhim Chansithika | N2: LEVEL: | Q2: =Classes!$B$2 -> K1B | U2: TIME: | W2: =Classes!$B$3 -> 3:00-5:30 | AB2: ROOM: | AD2: =Classes!$B$4 -> 5 | AJ2: IN THIS RED ZONE!!!
A3: SESSION: | E3: ='To Update'!E3 -> February-July 2026 | N3: BRANCH: | Q3: =Classes!$B$1 -> C2 | U3: TEACHER: | X3: =Classes!$B$5 -> Hong Leeheng | AK3: Up-Low | AL3: Alphab | AM3: Alphab | AT3: Art | AU3: Charact
A4: DESCRIPTIONS | O4: MIDTERM | Y4: PROMOTION | AJ4: Name | AK4: Case | AL4: Sound | AM4: Name | AN4: Vocab | AO4: Sprouts | AP4: Phonics | AQ4: Math | AR4: Science | AS4: Tracing | AT4: Mus.PE | AU4: Develop
O5: ='To Update'!O5 -> FEB | R5: ='To Update'!R5 -> MAR | U5: ='To Update'!U5 -> APR | X5: AV | Y5: ='To Update'!Y5 -> MAY | AB5: ='To Update'!AB5 -> JUN | AE5: ='To Update'!AE5 -> JUL | AH5: AV | AJ5: =D2 -> Chhim Chansithika | AK5: =IF(SUM(X7,AH7)=0,"",IF(SUM(X7,AH7)>0,AVERAGE(X7,AH7))) | AL5: =IF(SUM(X8,AH8)=0,"",IF(SUM(X8,AH8)>0,AVERAGE(X8,AH8))) | AM5: =IF(SUM(X10,AH10)=0,"",IF(SUM(X10,AH10)>0,AVERAGE(X10,AH10))) | AN5: =IF(SUM(X14,AH14)=0,"",IF(SUM(X14,AH14)>0,AVERAGE(X14,AH14))) | AO5: =IF(SUM(X19,AH19)=0,"",IF(SUM(X19,AH19)>0,AVERAGE(X19,AH19))) | AP5: =IF(SUM(X21,AH21)=0,"",IF(SUM(X21,AH21)>0,AVERAGE(X21,AH21))) | AQ5: =IF(SUM(X25,AH25)=0,"",IF(SUM(X25,AH25)>0,AVERAGE(X25,AH25))) | AR5: =IF(SUM(X33,AH33)=0,"",IF(SUM(X33,AH33),AVERAGE(X33,AH33))) | AS5: =IF(SUM(X36,AH36)=0,"",IF(SUM(X36,AH36)>0,AVERAGE(X36,AH36))) | AT5: =IF(SUM(X41,AH41)=0,"",IF(SUM(X41,AH41)>0,AVERAGE(X41,AH41))) | AU5: =IF(SUM(X45,AH45)=0,"",IF(SUM(X45,AH45)>0,AVERAGE(X45,AH45)))
A6: READING READINESS
A7:  | B7: Identifies uppercase and lowercase | X7: =IF(COUNTA(O7:W7)=0,"",IF(COUNTA(O7:W7)>0,AVERAGE(O7:W7))) | AH7: =IF(COUNTA(Y7:AG7)=0,"",IF(COUNTA(Y7:AG7)>0,AVERAGE(Y7:AG7)))
A8:  | B8: Identifies sounds of consonants (Aa-Mm) | X8: =IF(COUNTA(O8:W9)=0,"",IF(COUNTA(O8:W9)>0,AVERAGE(O8:W9))) | AH8: =IF(COUNTA(Y8:AG9)=0,"",IF(COUNTA(Y8:AG9)>0,AVERAGE(Y8:AG9)))
A9:  | B9: Listens for sounds at beginning of words (Aa-Mm) | X9: =IF(COUNTA(O9:W9)=0,"",IF(COUNTA(O9:W9)>0,AVERAGE(O9:W9))) | AH9: =IF(COUNTA(Y9:AG9)=0,"",IF(COUNTA(Y9:AG9)>0,AVERAGE(Y9:AG9)))
A10:  | B10: Names the following letters: Aa, Bb, Cc, Dd, ..., Mm | X10: =IF(COUNTA(O10:W11)=0,"",IF(COUNTA(O10:W11)>0,AVERAGE(O10:W11))) | AH10: =IF(COUNTA(Y10:AG11)=0,"",IF(COUNTA(Y10:AG11)>0,AVERAGE(Y10:AG11)))
A11:  | B11: Recognizes own name in print | X11: =IF(COUNTA(O11:W11)=0,"",IF(COUNTA(O11:W11)>0,AVERAGE(O11:W11))) | AH11: =IF(COUNTA(Y11:AG11)=0,"",IF(COUNTA(Y11:AG11)>0,AVERAGE(Y11:AG11)))
A12: LANGUAGE DEVELOPMENT
A13: Vocabulary:
A14:  | B14: Recognizes the phonic words: Letters Aa-Mm | X14: =IF(COUNTA(O14:W17)=0,"",IF(COUNTA(O14:W17)>0,AVERAGE(O14:W17))) | AH14: =IF(COUNTA(Y14:AG17)=0,"",IF(COUNTA(Y14:AG17)>0,AVERAGE(Y14:AG17)))
A15:  | B15: Identifies colors: black, white, red, yellow etc. | X15: =IF(COUNTA(O15:W15)=0,"",IF(COUNTA(O15:W15)>0,AVERAGE(O15:W15))) | AH15: =IF(COUNTA(Y15:AG15)=0,"",IF(COUNTA(Y15:AG15)>0,AVERAGE(Y15:AG15)))
A16:  | B16: Names the days of the week: Monday, Tuesday, etc. | X16: =IF(COUNTA(O16:W16)=0,"",IF(COUNTA(O16:W16)>0,AVERAGE(O16:W16))) | AH16: =IF(COUNTA(Y16:AG16)=0,"",IF(COUNTA(Y16:AG16)>0,AVERAGE(Y16:AG16)))
A17:  | B17: Describes location/position: in front, behind, in, etc. | X17: =IF(COUNTA(O17:W17)=0,"",IF(COUNTA(O17:W17)>0,AVERAGE(O17:W17))) | AH17: =IF(COUNTA(Y17:AG17)=0,"",IF(COUNTA(Y17:AG17)>0,AVERAGE(Y17:AG17)))
A18: Sprouts:
A19:  | B19: Sounds & formations of Jj, Ss, Tt, Mm | X19: =IF(COUNTA(O19:W19)=0,"",IF(COUNTA(O19:W19)>0,AVERAGE(O19:W19))) | AH19: =IF(COUNTA(Y19:AG19)=0,"",IF(COUNTA(Y19:AG19)>0,AVERAGE(Y19:AG19)))
A20: Phonics:
A21:  | B21: Listen, points and repeats targets sounds: | X21: =IF(COUNTA(O21:W23)=0,"",IF(COUNTA(O21:W23)>0,AVERAGE(O21:W23))) | AH21: =IF(COUNTA(Y21:AG23)=0,"",IF(COUNTA(Y21:AG23)>0,AVERAGE(Y21:AG23)))
B22: the alphabets: Aa, Bb, Cc, Dd, Ee, Ff, …, Ll | X22: =IF(COUNTA(O22:W22)=0,"",IF(COUNTA(O22:W22)>0,AVERAGE(O22:W22))) | AH22: =IF(COUNTA(Y22:AG22)=0,"",IF(COUNTA(Y22:AG22)>0,AVERAGE(Y22:AG22)))
A23:  | B23: Traces, writes, and says target aphabets | X23: =IF(COUNTA(O23:W23)=0,"",IF(COUNTA(O23:W23)>0,AVERAGE(O23:W23))) | AH23: =IF(COUNTA(Y23:AG23)=0,"",IF(COUNTA(Y23:AG23)>0,AVERAGE(Y23:AG23)))
A24: MATH CONCEPTS
A25:  | B25: Counts by rote to (1-10) | X25: =IF(COUNTA(O25:W31)=0,"",IF(COUNTA(O25:W31)>0,AVERAGE(O25:W31))) | AH25: =IF(COUNTA(Y25:AG31)=0,"",IF(COUNTA(Y25:AG31)>0,AVERAGE(Y25:AG31)))
A26:  | B26: Counts objects to (1-10)
A27:  | B27: Makes sets with objects to (10)
A28:  | B28: Matches numerals to sets
A29:  | B29: Shapes: | E29: * Recognizes:
E30: * Names:
