Workbook

Sheet Guide
B1: SCORE SHEET for KID PROGRAM
C3:  | D3: Beside teaching, evaluating learners' performance is necessary.
C4:  | D4: For the student performance evaluation at our center, we have score sheet as a tool for our teachers to record their kids' performance
D5: including class participation, oral or written work and exams, and other activities such as projects and presentations.
C6:  | D6: Our score sheet file contains 7 main worksheets as follows:
D7: (1). Classes is where you can add more kids when they are officially allowed to move in and correct the kid's name in terms of speeling
D8: (2). Midterm Daily is the score sheet for teacher to record students' daily scores in the period of midterm's time
D9: (3). Midterm Exam is for teacher to record the scores of Midterm exam
D10: (4). Midterm Results is a worksheet which covers both midterm daily scores and midterm exam scores
D11: (5). Promotion Daily is the score sheet for teacher to record students' daily socres in the period of promotion's time
D12: (6). Promotion Exam is for teacher to record the scores of Promotion exam
D13: (7). Promotion Results is the worksheet that covers all scores from Midterm Daily to Promotion Exam.
C14:  | D14: The operation below shows how to use each worksheet along with some examples of problems frequently happen and solutions for them
C16: OPERATION
C17: (1). Classes
C18:  | D18: Below is a class of K1 from 8:00 to 10:00 in the morning. From the beginning, this class has 10 kids from KID 1 to KID 10.
C19:  | D19: Later on, the office allows one new kid to move in. The TEACHER adds her after KID 10 in the (1).Classes worksheet.
C30: (2). Midterm Daily
D31: Why are KID 2, KID 5, and KID 9 incomplete?
C32:  | D32: KID 2 is incomplete because the TEACHER misses his Sprouts score. You should give 0 like KID 3 if he doesn't do it.
C33:  | D33: KID 5 is incomplete because the TEACHER misses his Science and Tracing scores. If he changes time, you should mark Change like KID 6.
C34:  | D34: KID 9 is incomplete because the TEACHER misses her scores of Phonics, Math, Shape, Science, and Tracing scores. If she stops, you
D35: should mark Stop like KID 10.
C36: Û | D36: Please use only the terms "Change" or "Stop" given to mark your students in case they change time or stop and other cases alike.
C51: (3). Midterm Exam
D52: Why are KID 3 and KID 7 incomplete?
C53:  | D53: KID 3 is incomplete because he did not take midterm exam. If he stops, you should mark Stop like KID 4.
C54:  | D54: KID 7 is incomplete because she misses two tests of midterm exam - Science and Tracing. He asks for permission and will come back to
D55: do them later, so you should mark Late Exam like KID 8.
C56: Û | D56: Please use only the terms "Stop" or "Late Exam" given to mark your students in case they stop or will do midterm exam later.
C73: (4). Midterm Results
C88:  | D88: Midterm result worksheet is designed for our students to see the results of their study for around three months.
C89:  | D89: Midterm result covers both midterm daily score and midterm exam score.
C90:  | D90: We consider the total of midterm daily score as 20% and the total of midterm exam score as 80%, so the total score of midterm result is
D91: 100%. Please have a look at the formula as follows:
E93: Midterm Result | H93: = | I93: Midterm dialy | K93: + | L93: Midterm exam | N93: = | O93: TOTAL
I94: 0.2 | L94: 0.8 | O94: 1
C96: (5). Promotion Daily (the same as Midterm Daily)
C97: (6). Promotion Exam (the same as Promotion Exam)
C98: (7). Promotion Results
...

Sheet How to record the scores
A1: HOW TO RECORD THE SCORES INTO SCORE SHEET
A3: Our score sheet is designed to show only integers, not decimals.
A5: However, our teachers are required to record the real scores.
A7: The real score, here, means the score that a student gets from an assignment, a quiz, or a test.
A9: Please do not worry about how it appears.
D13: Real Score | M13: The score | V13: The score | AE13: The score
D15: Example: Listening | M15: you MUST record | V15: that appears | AE15: that excel determines
D17: Student 1 gets 6.75 | M17: 6.75 | V17: 7 | AE17: 6.75
D19: Student 2 gets 7.25 | M19: 7.25 | V19: 7 | AE19: 7.25
D21: Student 3 gets 7.75 | M21: 7.75 | V21: 8 | AE21: 7.75
V23: ÇDon't worry about it Ç
A26: The explanation above is very short, so please call me if you are still not clear.
A28: It is always my pleasure to answer your questions.

Sheet (1).Classes
A1: Br: | B1: C2 | E1: Br: | I1: Br: | N1: To update
A2: Level: | B2: K1B | E2: Level: | I2: Level:
A3: Time: | B3: 3:00-5:30 | E3: Time: | I3: Time: | N3: FEBRUARY - JULY 2026
A4: Room: | B4: 5 | E4: Room: | I4: Room:
A5: Tr: | B5: Hong Leeheng | E5: Tr: | I5: Tr:
A6: NO | B6: Name | C6: Sex | D6: Phone | E6: NO | F6: Name | G6: Sex | H6: Phone | I6: NO | J6: NAME | K6: SEX | L6: PHONE
A7: 1 | B7: Chhim Chansithika | C7: F | D7: 012 447681 | E7: 1 | I7: 1
A8: 2 | B8: Chhout Senghour | C8: M | D8: 078 886898 | E8: 2 | I8: 2
A9: 3 | B9: Det Phouri | C9: M | D9: 010 222025 | E9: 3 | I9: 3
A10: 4 | B10: Dy Chanto | C10: M | D10: 086 944449 | E10: 4 | I10: 4
A11: 5 | B11: Dy Meyly | C11: F | D11: 086 944449 | E11: 5 | I11: 5
A12: 6 | B12: Heang Limhak | C12: M | D12: 086 606067 | E12: 6 | I12: 6
A13: 7 | B13: Keo Tepsatsjak | C13: M | D13: 092 609960 | E13: 7 | I13: 7
A14: 8 | B14: Kong Yonghae | C14: M | E14: 8 | I14: 8
A15: 9 | B15: Lim Davymulika | C15: F | D15: 069 332143 | E15: 9 | I15: 9
A16: 10 | B16: Lot SamAngvichara | C16: F | D16: 096 3933822 | E16: 10 | I16: 10
A17: 11 | B17: Lot Vichheka | C17: M | D17: 096 3933822 | E17: 11 | I17: 11
A18: 12 | B18: Ly Kanha | C18: F | D18: 098 339928 | E18: 12 | I18: 12
A19: 13 | B19: Ly Sanmoniroth | C19: F | D19: 077 630577 | E19: 13 | I19: 13
A20: 14 | B20: Noun Thoreakrith | C20: M | D20: 090 934444 | E20: 14 | I20: 14
A21: 15 | B21: OL Amara | C21: F | D21: 016 213706 | E21: 15 | I21: 15
A22: 16 | B22: Prom Monometa | C22: M | D22: 011 999239 | E22: 16 | I22: 16
A23: 17 | B23: Seng Moamunyriangsey | C23: F | D23: 012 446232 | E23: 17 | I23: 17
A24: 18 | B24: Thuy Chanmeylinh | C24: F | D24: 081 788855 | E24: 18 | I24: 18
A25: 19 | B25: Vy Monineath | C25: F | D25: 096 2979797 | E25: 19 | I25: 19
A26: 20 | E26: 20 | I26: 20
A27: 21 | E27: 21 | I27: 21
A28: 22 | E28: 22 | I28: 22
A29: 23 | E29: 23 | I29: 23
A30: 24 | E30: 24 | I30: 24
A31: 25 | E31: 25 | I31: 25
A32: 26 | E32: 26 | I32: 26
A33: 27 | E33: 27 | I33: 27
A34: 28 | E34: 28 | I34: 28
A35: 29 | E35: 29 | I35: 29
A36: 30 | E36: 30 | I36: 30
A37: Br: | E37: Br: | I37: Br:
A38: Level: | E38: Level: | I38: Level:
A39: Time: | E39: Time: | I39: Time:
A40: Room: | E40: Room: | I40: Room:
...

Sheet (2).Midterm Daily
A1: Br: | B1: ='(1).Classes'!B1 -> C2 | D1: MIDTERM DAILY SCORE SHEET
A2: Level: | B2: ='(1).Classes'!B2 -> K1B
A3: Time: | B3: ='(1).Classes'!B3 -> 3:00-5:30 | D3: ='(1).Classes'!N3 -> FEBRUARY - JULY 2026
A4: Room: | B4: ='(1).Classes'!B4 -> 5
A5: Tr: | B5: ='(1).Classes'!B5 -> Hong Leeheng | D5: =IF(OR($B2="K5",$B2="K6",$B2="K7",$B2="K8",$B2="K9",$B2="K10"),"Listening","Up-Low C") -> Up-Low C | G5: =IF(OR($B2="K5",$B2="K6",$B2="K7",$B2="K8",$B2="K9",$B2="K10"),"Speaking","Alphabet N") -> Alphabet N | J5: =IF(OR($B2="K5",$B2="K6",$B2="K7",$B2="K8",$B2="K9",$B2="K10"),"Reading","Alphabet S") -> Alphabet S | M5: =IF(OR($B2="K5",$B2="K6",$B2="K7",$B2="K8",$B2="K9",$B2="K10"),"Writing","Vocabulary") -> Vocabulary | P5: =IF(OR($B2="K5",$B2="K6",$B2="K7",$B2="K8",$B2="K9",$B2="K10"),"Gram/Vocab","Sprouts") -> Sprouts | S5: =IF(OR($B2="K5",$B2="K6",$B2="K7",$B2="K8",$B2="K9",$B2="K10"),"Roots","Phonics") -> Phonics | V5: =IF(OR($B2="K5",$B2="K6",$B2="K7",$B2="K8",$B2="K9",$B2="K10"),"Phonics","Math") -> Math | Y5: =IF(OR($B2="K5",$B2="K6",$B2="K7",$B2="K8",$B2="K9",$B2="K10"),"Math","Shape") -> Shape | AB5: Science | AE5: =IF(OR($B2="K5",$B2="K6",$B2="K7",$B2="K8",$B2="K9",$B2="K10"),"Homework","Tracing") -> Tracing | AH5: Change
A6: NO | B6: NAME | C6: SEX | D6: 10 points | G6: 10 points | J6: 10 points | M6: 10 points | P6: 10 points | S6: 10 points | V6: 10 points | Y6: 10 points | AB6: 10 points | AE6: 10 points | AH6: Stop
A7: 1 | B7: =IF('(1).Classes'!B7="","",'(1).Classes'!B7) -> Chhim Chansithika | C7: =IF('(1).Classes'!C7="","",'(1).Classes'!C7) -> F | D7: 10 | E7: 10 | G7: 9 | H7: 10 | J7: 8 | K7: 6 | M7: 9.5 | N7: 9 | P7: 6 | Q7: 6.5 | S7: 10 | T7: 6 | V7: 10 | W7: 9.5 | Y7: 10 | Z7: 7 | AB7: 10 | AC7: 7 | AE7: 8.5 | AF7: 9.75 | AH7: =IF(B7="","",IF(COUNT(D7:F7)=0,"Incomplete",IF(COUNT(G7:I7)=0,"Incomplete",IF(COUNT(J7:L7)=0,"Incomplete",IF(COUNT(M7:O7)=0,"Incomplete",IF(COUNT(P7:R7)=0,"Incomplete",IF(COUNT(S7:U7)=0,"Incomplete",IF(COUNT(V7:X7)=0,"Incomplete",IF(COUNT(Y7:AA7)=0,"Incomplete",IF(COUNT(AB7:AD7)=0,"Incomplete",IF(COUNT(AE7:AG7)=0,"Incomplete",AVERAGEIF(D7:F7,">=0")+AVERAGEIF(G7:I7,">=0")+AVERAGEIF(J7:L7,">=0")+AVERAGEIF(M7:O7,">=0")+AVERAGEIF(P7:R7,">=0")+AVERAGEIF(S7:U7,">=0")+AVERAGEIF(V7:X7,">=0")+AVERAGEIF(Y7:AA7,">=0")+AVERAGEIF(AB7:AD7,">=0")+AVERAGEIF(AE7:AG7,">=0")))))))))))) -> 85.875
A8: 2 | B8: =IF('(1).Classes'!B8="","",'(1).Classes'!B8) -> Chhout Senghour | C8: =IF('(1).Classes'!C8="","",'(1).Classes'!C8) -> M | D8: 8 | E8: 7 | G8: 8 | H8: 5 | J8: 5 | K8: 4 | M8: 4 | N8: 9 | P8: 6.5 | Q8: 6 | S8: 3 | T8: 5 | V8: 9.5 | W8: 9 | Y8: 10 | Z8: 8 | AB8: 9 | AC8: 6 | AE8: 5.5 | AF8: 7 | AH8: =IF(B8="","",IF(COUNT(D8:F8)=0,"Incomplete",IF(COUNT(G8:I8)=0,"Incomplete",IF(COUNT(J8:L8)=0,"Incomplete",IF(COUNT(M8:O8)=0,"Incomplete",IF(COUNT(P8:R8)=0,"Incomplete",IF(COUNT(S8:U8)=0,"Incomplete",IF(COUNT(V8:X8)=0,"Incomplete",IF(COUNT(Y8:AA8)=0,"Incomplete",IF(COUNT(AB8:AD8)=0,"Incomplete",IF(COUNT(AE8:AG8)=0,"Incomplete",AVERAGEIF(D8:F8,">=0")+AVERAGEIF(G8:I8,">=0")+AVERAGEIF(J8:L8,">=0")+AVERAGEIF(M8:O8,">=0")+AVERAGEIF(P8:R8,">=0")+AVERAGEIF(S8:U8,">=0")+AVERAGEIF(V8:X8,">=0")+AVERAGEIF(Y8:AA8,">=0")+AVERAGEIF(AB8:AD8,">=0")+AVERAGEIF(AE8:AG8,">=0")))))))))))) -> 67.25
A9: 3 | B9: =IF('(1).Classes'!B9="","",'(1).Classes'!B9) -> Det Phouri | C9: =IF('(1).Classes'!C9="","",'(1).Classes'!C9) -> M | D9: 10 | E9: 9.25 | G9: 5.5 | H9: 10 | J9: 8 | K9: 9 | M9: 10 | N9: 10 | P9: 5 | Q9: 9 | S9: 9 | T9: 9.5 | V9: 10 | W9: 9.5 | Y9: 10 | Z9: 9 | AB9: 9 | AC9: 9.5 | AE9: 8.5 | AF9: 9.5 | AH9: =IF(B9="","",IF(COUNT(D9:F9)=0,"Incomplete",IF(COUNT(G9:I9)=0,"Incomplete",IF(COUNT(J9:L9)=0,"Incomplete",IF(COUNT(M9:O9)=0,"Incomplete",IF(COUNT(P9:R9)=0,"Incomplete",IF(COUNT(S9:U9)=0,"Incomplete",IF(COUNT(V9:X9)=0,"Incomplete",IF(COUNT(Y9:AA9)=0,"Incomplete",IF(COUNT(AB9:AD9)=0,"Incomplete",IF(COUNT(AE9:AG9)=0,"Incomplete",AVERAGEIF(D9:F9,">=0")+AVERAGEIF(G9:I9,">=0")+AVERAGEIF(J9:L9,">=0")+AVERAGEIF(M9:O9,">=0")+AVERAGEIF(P9:R9,">=0")+AVERAGEIF(S9:U9,">=0")+AVERAGEIF(V9:X9,">=0")+AVERAGEIF(Y9:AA9,">=0")+AVERAGEIF(AB9:AD9,">=0")+AVERAGEIF(AE9:AG9,">=0")))))))))))) -> 89.625
A10: 4 | B10: =IF('(1).Classes'!B10="","",'(1).Classes'!B10) -> Dy Chanto | C10: =IF('(1).Classes'!C10="","",'(1).Classes'!C10) -> M | D10: 7 | E10: 1.5 | G10: 3.5 | H10: 4 | J10: 6 | K10: 3 | M10: 5 | N10: 3 | P10: 5 | Q10: 3 | S10: 3 | T10: 5 | V10: 10 | W10: 4 | Y10: 6 | Z10: 5 | AB10: 9 | AC10: 5 | AE10: 5 | AF10: 5 | AH10: =IF(B10="","",IF(COUNT(D10:F10)=0,"Incomplete",IF(COUNT(G10:I10)=0,"Incomplete",IF(COUNT(J10:L10)=0,"Incomplete",IF(COUNT(M10:O10)=0,"Incomplete",IF(COUNT(P10:R10)=0,"Incomplete",IF(COUNT(S10:U10)=0,"Incomplete",IF(COUNT(V10:X10)=0,"Incomplete",IF(COUNT(Y10:AA10)=0,"Incomplete",IF(COUNT(AB10:AD10)=0,"Incomplete",IF(COUNT(AE10:AG10)=0,"Incomplete",AVERAGEIF(D10:F10,">=0")+AVERAGEIF(G10:I10,">=0")+AVERAGEIF(J10:L10,">=0")+AVERAGEIF(M10:O10,">=0")+AVERAGEIF(P10:R10,">=0")+AVERAGEIF(S10:U10,">=0")+AVERAGEIF(V10:X10,">=0")+AVERAGEIF(Y10:AA10,">=0")+AVERAGEIF(AB10:AD10,">=0")+AVERAGEIF(AE10:AG10,">=0")))))))))))) -> 49
A11: 5 | B11: =IF('(1).Classes'!B11="","",'(1).Classes'!B11) -> Dy Meyly | C11: =IF('(1).Classes'!C11="","",'(1).Classes'!C11) -> F | D11: 10 | E11: 10 | G11: 10 | H11: 10 | J11: 8 | K11: 9 | M11: 10 | N11: 10 | P11: 10 | Q11: 9.5 | S11: 10 | T11: 9 | V11: 10 | W11: 9.5 | Y11: 10 | Z11: 9 | AB11: 10 | AC11: 9.5 | AE11: 9.75 | AF11: 10 | AH11: =IF(B11="","",IF(COUNT(D11:F11)=0,"Incomplete",IF(COUNT(G11:I11)=0,"Incomplete",IF(COUNT(J11:L11)=0,"Incomplete",IF(COUNT(M11:O11)=0,"Incomplete",IF(COUNT(P11:R11)=0,"Incomplete",IF(COUNT(S11:U11)=0,"Incomplete",IF(COUNT(V11:X11)=0,"Incomplete",IF(COUNT(Y11:AA11)=0,"Incomplete",IF(COUNT(AB11:AD11)=0,"Incomplete",IF(COUNT(AE11:AG11)=0,"Incomplete",AVERAGEIF(D11:F11,">=0")+AVERAGEIF(G11:I11,">=0")+AVERAGEIF(J11:L11,">=0")+AVERAGEIF(M11:O11,">=0")+AVERAGEIF(P11:R11,">=0")+AVERAGEIF(S11:U11,">=0")+AVERAGEIF(V11:X11,">=0")+AVERAGEIF(Y11:AA11,">=0")+AVERAGEIF(AB11:AD11,">=0")+AVERAGEIF(AE11:AG11,">=0")))))))))))) -> 96.625
A12: 6 | B12: =IF('(1).Classes'!B12="","",'(1).Classes'!B12) -> Heang Limhak | C12: =IF('(1).Classes'!C12="","",'(1).Classes'!C12) -> M | D12: 10 | E12: 7 | G12: 9.5 | H12: 10 | J12: 10 | K12: 8 | M12: 7 | N12: 10 | P12: 7 | Q12: 8 | S12: 8 | T12: 9 | V12: 9 | W12: 4 | Y12: 10 | Z12: 9 | AB12: 10 | AC12: 8 | AE12: 8 | AF12: 5 | AH12: =IF(B12="","",IF(COUNT(D12:F12)=0,"Incomplete",IF(COUNT(G12:I12)=0,"Incomplete",IF(COUNT(J12:L12)=0,"Incomplete",IF(COUNT(M12:O12)=0,"Incomplete",IF(COUNT(P12:R12)=0,"Incomplete",IF(COUNT(S12:U12)=0,"Incomplete",IF(COUNT(V12:X12)=0,"Incomplete",IF(COUNT(Y12:AA12)=0,"Incomplete",IF(COUNT(AB12:AD12)=0,"Incomplete",IF(COUNT(AE12:AG12)=0,"Incomplete",AVERAGEIF(D12:F12,">=0")+AVERAGEIF(G12:I12,">=0")+AVERAGEIF(J12:L12,">=0")+AVERAGEIF(M12:O12,">=0")+AVERAGEIF(P12:R12,">=0")+AVERAGEIF(S12:U12,">=0")+AVERAGEIF(V12:X12,">=0")+AVERAGEIF(Y12:AA12,">=0")+AVERAGEIF(AB12:AD12,">=0")+AVERAGEIF(AE12:AG12,">=0")))))))))))) -> 83.25
A13: 7 | B13: =IF('(1).Classes'!B13="","",'(1).Classes'!B13) -> Keo Tepsatsjak | C13: =IF('(1).Classes'!C13="","",'(1).Classes'!C13) -> M | D13: 10 | E13: 8.75 | G13: 9 | H13: 10 | J13: 10 | K13: 8.5 | M13: 10 | N13: 8.5 | P13: 9.5 | Q13: 9 | S13: 10 | T13: 9.5 | V13: 10 | W13: 9 | Y13: 6 | Z13: 9 | AB13: 9 | AC13: 9 | AE13: 8.5 | AF13: 9.75 | AH13: =IF(B13="","",IF(COUNT(D13:F13)=0,"Incomplete",IF(COUNT(G13:I13)=0,"Incomplete",IF(COUNT(J13:L13)=0,"Incomplete",IF(COUNT(M13:O13)=0,"Incomplete",IF(COUNT(P13:R13)=0,"Incomplete",IF(COUNT(S13:U13)=0,"Incomplete",IF(COUNT(V13:X13)=0,"Incomplete",IF(COUNT(Y13:AA13)=0,"Incomplete",IF(COUNT(AB13:AD13)=0,"Incomplete",IF(COUNT(AE13:AG13)=0,"Incomplete",AVERAGEIF(D13:F13,">=0")+AVERAGEIF(G13:I13,">=0")+AVERAGEIF(J13:L13,">=0")+AVERAGEIF(M13:O13,">=0")+AVERAGEIF(P13:R13,">=0")+AVERAGEIF(S13:U13,">=0")+AVERAGEIF(V13:X13,">=0")+AVERAGEIF(Y13:AA13,">=0")+AVERAGEIF(AB13:AD13,">=0")+AVERAGEIF(AE13:AG13,">=0")))))))))))) -> 91.5
A14: 8 | B14: =IF('(1).Classes'!B14="","",'(1).Classes'!B14) -> Kong Yonghae | C14: =IF('(1).Classes'!C14="","",'(1).Classes'!C14) -> M | D14: 10 | E14: 8.5 | G14: 8.5 | H14: 10 | J14: 10 | K14: 7 | M14: 10 | N14: 9 | P14: 9 | Q14: 8 | S14: 10 | T14: 8 | V14: 10 | W14: 10 | Y14: 10 | Z14: 9 | AB14: 9 | AC14: 8 | AE14: 8 | AF14: 10 | AH14: =IF(B14="","",IF(COUNT(D14:F14)=0,"Incomplete",IF(COUNT(G14:I14)=0,"Incomplete",IF(COUNT(J14:L14)=0,"Incomplete",IF(COUNT(M14:O14)=0,"Incomplete",IF(COUNT(P14:R14)=0,"Incomplete",IF(COUNT(S14:U14)=0,"Incomplete",IF(COUNT(V14:X14)=0,"Incomplete",IF(COUNT(Y14:AA14)=0,"Incomplete",IF(COUNT(AB14:AD14)=0,"Incomplete",IF(COUNT(AE14:AG14)=0,"Incomplete",AVERAGEIF(D14:F14,">=0")+AVERAGEIF(G14:I14,">=0")+AVERAGEIF(J14:L14,">=0")+AVERAGEIF(M14:O14,">=0")+AVERAGEIF(P14:R14,">=0")+AVERAGEIF(S14:U14,">=0")+AVERAGEIF(V14:X14,">=0")+AVERAGEIF(Y14:AA14,">=0")+AVERAGEIF(AB14:AD14,">=0")+AVERAGEIF(AE14:AG14,">=0")))))))))))) -> 91
A15: 9 | B15: =IF('(1).Classes'!B15="","",'(1).Classes'!B15) -> Lim Davymulika | C15: =IF('(1).Classes'!C15="","",'(1).Classes'!C15) -> F | D15: 6 | E15: 6.75 | G15: 6.5 | H15: 6 | J15: 5 | K15: 4 | M15: 6 | N15: 8 | P15: 5 | Q15: 4.5 | S15: 7 | T15: 6 | V15: 8 | W15: 4 | Y15: 6 | Z15: 5 | AB15: 5 | AC15: 6 | AE15: 8 | AF15: 9 | AH15: =IF(B15="","",IF(COUNT(D15:F15)=0,"Incomplete",IF(COUNT(G15:I15)=0,"Incomplete",IF(COUNT(J15:L15)=0,"Incomplete",IF(COUNT(M15:O15)=0,"Incomplete",IF(COUNT(P15:R15)=0,"Incomplete",IF(COUNT(S15:U15)=0,"Incomplete",IF(COUNT(V15:X15)=0,"Incomplete",IF(COUNT(Y15:AA15)=0,"Incomplete",IF(COUNT(AB15:AD15)=0,"Incomplete",IF(COUNT(AE15:AG15)=0,"Incomplete",AVERAGEIF(D15:F15,">=0")+AVERAGEIF(G15:I15,">=0")+AVERAGEIF(J15:L15,">=0")+AVERAGEIF(M15:O15,">=0")+AVERAGEIF(P15:R15,">=0")+AVERAGEIF(S15:U15,">=0")+AVERAGEIF(V15:X15,">=0")+AVERAGEIF(Y15:AA15,">=0")+AVERAGEIF(AB15:AD15,">=0")+AVERAGEIF(AE15:AG15,">=0")))))))))))) -> 60.875
A16: 10 | B16: =IF('(1).Classes'!B16="","",'(1).Classes'!B16) -> Lot SamAngvichara | C16: =IF('(1).Classes'!C16="","",'(1).Classes'!C16) -> F | D16: 10 | E16: 10 | G16: 10 | H16: 10 | J16: 10 | K16: 9.5 | M16: 10 | N16: 10 | P16: 8 | Q16: 9 | S16: 10 | T16: 9 | V16: 9.5 | W16: 10 | Y16: 10 | Z16: 9 | AB16: 8 | AC16: 9 | AE16: 8 | AF16: 8 | AH16: =IF(B16="","",IF(COUNT(D16:F16)=0,"Incomplete",IF(COUNT(G16:I16)=0,"Incomplete",IF(COUNT(J16:L16)=0,"Incomplete",IF(COUNT(M16:O16)=0,"Incomplete",IF(COUNT(P16:R16)=0,"Incomplete",IF(COUNT(S16:U16)=0,"Incomplete",IF(COUNT(V16:X16)=0,"Incomplete",IF(COUNT(Y16:AA16)=0,"Incomplete",IF(COUNT(AB16:AD16)=0,"Incomplete",IF(COUNT(AE16:AG16)=0,"Incomplete",AVERAGEIF(D16:F16,">=0")+AVERAGEIF(G16:I16,">=0")+AVERAGEIF(J16:L16,">=0")+AVERAGEIF(M16:O16,">=0")+AVERAGEIF(P16:R16,">=0")+AVERAGEIF(S16:U16,">=0")+AVERAGEIF(V16:X16,">=0")+AVERAGEIF(Y16:AA16,">=0")+AVERAGEIF(AB16:AD16,">=0")+AVERAGEIF(AE16:AG16,">=0")))))))))))) -> 93.5
A17: 11 | B17: =IF('(1).Classes'!B17="","",'(1).Classes'!B17) -> Lot Vichheka | C17: =IF('(1).Classes'!C17="","",'(1).Classes'!C17) -> M | D17: 10 | E17: 10 | G17: 8.5 | H17: 10 | J17: 9 | K17: 9 | M17: 10 | N17: 10 | P17: 8 | Q17: 9 | S17: 10 | T17: 9 | V17: 9.5 | W17: 10 | Y17: 10 | Z17: 8 | AB17: 9 | AC17: 9 | AE17: 7 | AF17: 9 | AH17: =IF(B17="","",IF(COUNT(D17:F17)=0,"Incomplete",IF(COUNT(G17:I17)=0,"Incomplete",IF(COUNT(J17:L17)=0,"Incomplete",IF(COUNT(M17:O17)=0,"Incomplete",IF(COUNT(P17:R17)=0,"Incomplete",IF(COUNT(S17:U17)=0,"Incomplete",IF(COUNT(V17:X17)=0,"Incomplete",IF(COUNT(Y17:AA17)=0,"Incomplete",IF(COUNT(AB17:AD17)=0,"Incomplete",IF(COUNT(AE17:AG17)=0,"Incomplete",AVERAGEIF(D17:F17,">=0")+AVERAGEIF(G17:I17,">=0")+AVERAGEIF(J17:L17,">=0")+AVERAGEIF(M17:O17,">=0")+AVERAGEIF(P17:R17,">=0")+AVERAGEIF(S17:U17,">=0")+AVERAGEIF(V17:X17,">=0")+AVERAGEIF(Y17:AA17,">=0")+AVERAGEIF(AB17:AD17,">=0")+AVERAGEIF(AE17:AG17,">=0")))))))))))) -> 92
A18: 12 | B18: =IF('(1).Classes'!B18="","",'(1).Classes'!B18) -> Ly Kanha | C18: =IF('(1).Classes'!C18="","",'(1).Classes'!C18) -> F | D18: 6 | E18: 8.75 | G18: 8.5 | H18: 7 | J18: 10 | K18: 9 | M18: 9 | N18: 10 | P18: 9 | Q18: 9.5 | S18: 10 | T18: 8.5 | V18: 10 | W18: 8 | Y18: 10 | Z18: 9 | AB18: 9 | AC18: 9 | AE18: 9 | AF18: 9.75 | AH18: =IF(B18="","",IF(COUNT(D18:F18)=0,"Incomplete",IF(COUNT(G18:I18)=0,"Incomplete",IF(COUNT(J18:L18)=0,"Incomplete",IF(COUNT(M18:O18)=0,"Incomplete",IF(COUNT(P18:R18)=0,"Incomplete",IF(COUNT(S18:U18)=0,"Incomplete",IF(COUNT(V18:X18)=0,"Incomplete",IF(COUNT(Y18:AA18)=0,"Incomplete",IF(COUNT(AB18:AD18)=0,"Incomplete",IF(COUNT(AE18:AG18)=0,"Incomplete",AVERAGEIF(D18:F18,">=0")+AVERAGEIF(G18:I18,">=0")+AVERAGEIF(J18:L18,">=0")+AVERAGEIF(M18:O18,">=0")+AVERAGEIF(P18:R18,">=0")+AVERAGEIF(S18:U18,">=0")+AVERAGEIF(V18:X18,">=0")+AVERAGEIF(Y18:AA18,">=0")+AVERAGEIF(AB18:AD18,">=0")+AVERAGEIF(AE18:AG18,">=0")))))))))))) -> 89.5
... A25: 19 | B25: =IF('(1).Classes'!B25="","",'(1).Classes'!B25) -> Vy Monineath | C25: =IF('(1).Classes'!C25="","",'(1).Classes'!C25) -> F | D25: 8 | E25: 10 | G25: 10 | H25: 10 | J25: 10 | K25: 9.5 | M25: 9 | N25: 10 | P25: 10 | Q25: 9.5 | S25: 10 | T25: 9.5 | V25: 10 | W25: 10 | Y25: 10 | Z25: 9 | AB25: 10 | AC25: 9 | AE25: 9.75 | AF25: 10 | AH25: =IF(B25="","",IF(COUNT(D25:F25)=0,"Incomplete",IF(COUNT(G25:I25)=0,"Incomplete",IF(COUNT(J25:L25)=0,"Incomplete",IF(COUNT(M25:O25)=0,"Incomplete",IF(COUNT(P25:R25)=0,"Incomplete",IF(COUNT(S25:U25)=0,"Incomplete",IF(COUNT(V25:X25)=0,"Incomplete",IF(COUNT(Y25:AA25)=0,"Incomplete",IF(COUNT(AB25:AD25)=0,"Incomplete",IF(COUNT(AE25:AG25)=0,"Incomplete",AVERAGEIF(D25:F25,">=0")+AVERAGEIF(G25:I25,">=0")+AVERAGEIF(J25:L25,">=0")+AVERAGEIF(M25:O25,">=0")+AVERAGEIF(P25:R25,">=0")+AVERAGEIF(S25:U25,">=0")+AVERAGEIF(V25:X25,">=0")+AVERAGEIF(Y25:AA25,">=0")+AVERAGEIF(AB25:AD25,">=0")+AVERAGEIF(AE25:AG25,">=0")))))))))))) -> 96.625
A26: 20 | B26: =IF('(1).Classes'!B26="","",'(1).Classes'!B26) | C26: =IF('(1).Classes'!C26="","",'(1).Classes'!C26) | AH26: =IF(B26="","",IF(COUNT(D26:F26)=0,"Incomplete",IF(COUNT(G26:I26)=0,"Incomplete",IF(COUNT(J26:L26)=0,"Incomplete",IF(COUNT(M26:O26)=0,"Incomplete",IF(COUNT(P26:R26)=0,"Incomplete",IF(COUNT(S26:U26)=0,"Incomplete",IF(COUNT(V26:X26)=0,"Incomplete",IF(COUNT(Y26:AA26)=0,"Incomplete",IF(COUNT(AB26:AD26)=0,"Incomplete",IF(COUNT(AE26:AG26)=0,"Incomplete",AVERAGEIF(D26:F26,">=0")+AVERAGEIF(G26:I26,">=0")+AVERAGEIF(J26:L26,">=0")+AVERAGEIF(M26:O26,">=0")+AVERAGEIF(P26:R26,">=0")+AVERAGEIF(S26:U26,">=0")+AVERAGEIF(V26:X26,">=0")+AVERAGEIF(Y26:AA26,">=0")+AVERAGEIF(AB26:AD26,">=0")+AVERAGEIF(AE26:AG26,">=0"))))))))))))
A27: 21 | B27: =IF('(1).Classes'!B27="","",'(1).Classes'!B27) | C27: =IF('(1).Classes'!C27="","",'(1).Classes'!C27) | AH27: =IF(B27="","",IF(COUNT(D27:F27)=0,"Incomplete",IF(COUNT(G27:I27)=0,"Incomplete",IF(COUNT(J27:L27)=0,"Incomplete",IF(COUNT(M27:O27)=0,"Incomplete",IF(COUNT(P27:R27)=0,"Incomplete",IF(COUNT(S27:U27)=0,"Incomplete",IF(COUNT(V27:X27)=0,"Incomplete",IF(COUNT(Y27:AA27)=0,"Incomplete",IF(COUNT(AB27:AD27)=0,"Incomplete",IF(COUNT(AE27:AG27)=0,"Incomplete",AVERAGEIF(D27:F27,">=0")+AVERAGEIF(G27:I27,">=0")+AVERAGEIF(J27:L27,">=0")+AVERAGEIF(M27:O27,">=0")+AVERAGEIF(P27:R27,">=0")+AVERAGEIF(S27:U27,">=0")+AVERAGEIF(V27:X27,">=0")+AVERAGEIF(Y27:AA27,">=0")+AVERAGEIF(AB27:AD27,">=0")+AVERAGEIF(AE27:AG27,">=0"))))))))))))
A28: 22 | B28: =IF('(1).Classes'!B28="","",'(1).Classes'!B28) | C28: =IF('(1).Classes'!C28="","",'(1).Classes'!C28) | AH28: =IF(B28="","",IF(COUNT(D28:F28)=0,"Incomplete",IF(COUNT(G28:I28)=0,"Incomplete",IF(COUNT(J28:L28)=0,"Incomplete",IF(COUNT(M28:O28)=0,"Incomplete",IF(COUNT(P28:R28)=0,"Incomplete",IF(COUNT(S28:U28)=0,"Incomplete",IF(COUNT(V28:X28)=0,"Incomplete",IF(COUNT(Y28:AA28)=0,"Incomplete",IF(COUNT(AB28:AD28)=0,"Incomplete",IF(COUNT(AE28:AG28)=0,"Incomplete",AVERAGEIF(D28:F28,">=0")+AVERAGEIF(G28:I28,">=0")+AVERAGEIF(J28:L28,">=0")+AVERAGEIF(M28:O28,">=0")+AVERAGEIF(P28:R28,">=0")+AVERAGEIF(S28:U28,">=0")+AVERAGEIF(V28:X28,">=0")+AVERAGEIF(Y28:AA28,">=0")+AVERAGEIF(AB28:AD28,">=0")+AVERAGEIF(AE28:AG28,">=0"))))))))))))
A29: 23 | B29: =IF('(1).Classes'!B29="","",'(1).Classes'!B29) | C29: =IF('(1).Classes'!C29="","",'(1).Classes'!C29) | AH29: =IF(B29="","",IF(COUNT(D29:F29)=0,"Incomplete",IF(COUNT(G29:I29)=0,"Incomplete",IF(COUNT(J29:L29)=0,"Incomplete",IF(COUNT(M29:O29)=0,"Incomplete",IF(COUNT(P29:R29)=0,"Incomplete",IF(COUNT(S29:U29)=0,"Incomplete",IF(COUNT(V29:X29)=0,"Incomplete",IF(COUNT(Y29:AA29)=0,"Incomplete",IF(COUNT(AB29:AD29)=0,"Incomplete",IF(COUNT(AE29:AG29)=0,"Incomplete",AVERAGEIF(D29:F29,">=0")+AVERAGEIF(G29:I29,">=0")+AVERAGEIF(J29:L29,">=0")+AVERAGEIF(M29:O29,">=0")+AVERAGEIF(P29:R29,">=0")+AVERAGEIF(S29:U29,">=0")+AVERAGEIF(V29:X29,">=0")+AVERAGEIF(Y29:AA29,">=0")+AVERAGEIF(AB29:AD29,">=0")+AVERAGEIF(AE29:AG29,">=0"))))))))))))
A30: 24 | B30: =IF('(1).Classes'!B30="","",'(1).Classes'!B30) | C30: =IF('(1).Classes'!C30="","",'(1).Classes'!C30) | AH30: =IF(B30="","",IF(COUNT(D30:F30)=0,"Incomplete",IF(COUNT(G30:I30)=0,"Incomplete",IF(COUNT(J30:L30)=0,"Incomplete",IF(COUNT(M30:O30)=0,"Incomplete",IF(COUNT(P30:R30)=0,"Incomplete",IF(COUNT(S30:U30)=0,"Incomplete",IF(COUNT(V30:X30)=0,"Incomplete",IF(COUNT(Y30:AA30)=0,"Incomplete",IF(COUNT(AB30:AD30)=0,"Incomplete",IF(COUNT(AE30:AG30)=0,"Incomplete",AVERAGEIF(D30:F30,">=0")+AVERAGEIF(G30:I30,">=0")+AVERAGEIF(J30:L30,">=0")+AVERAGEIF(M30:O30,">=0")+AVERAGEIF(P30:R30,">=0")+AVERAGEIF(S30:U30,">=0")+AVERAGEIF(V30:X30,">=0")+AVERAGEIF(Y30:AA30,">=0")+AVERAGEIF(AB30:AD30,">=0")+AVERAGEIF(AE30:AG30,">=0"))))))))))))
A31: 25 | B31: =IF('(1).Classes'!B31="","",'(1).Classes'!B31) | C31: =IF('(1).Classes'!C31="","",'(1).Classes'!C31) | AH31: =IF(B31="","",IF(COUNT(D31:F31)=0,"Incomplete",IF(COUNT(G31:I31)=0,"Incomplete",IF(COUNT(J31:L31)=0,"Incomplete",IF(COUNT(M31:O31)=0,"Incomplete",IF(COUNT(P31:R31)=0,"Incomplete",IF(COUNT(S31:U31)=0,"Incomplete",IF(COUNT(V31:X31)=0,"Incomplete",IF(COUNT(Y31:AA31)=0,"Incomplete",IF(COUNT(AB31:AD31)=0,"Incomplete",IF(COUNT(AE31:AG31)=0,"Incomplete",AVERAGEIF(D31:F31,">=0")+AVERAGEIF(G31:I31,">=0")+AVERAGEIF(J31:L31,">=0")+AVERAGEIF(M31:O31,">=0")+AVERAGEIF(P31:R31,">=0")+AVERAGEIF(S31:U31,">=0")+AVERAGEIF(V31:X31,">=0")+AVERAGEIF(Y31:AA31,">=0")+AVERAGEIF(AB31:AD31,">=0")+AVERAGEIF(AE31:AG31,">=0"))))))))))))
A32: 26 | B32: =IF('(1).Classes'!B32="","",'(1).Classes'!B32) | C32: =IF('(1).Classes'!C32="","",'(1).Classes'!C32) | AH32: =IF(B32="","",IF(COUNT(D32:F32)=0,"Incomplete",IF(COUNT(G32:I32)=0,"Incomplete",IF(COUNT(J32:L32)=0,"Incomplete",IF(COUNT(M32:O32)=0,"Incomplete",IF(COUNT(P32:R32)=0,"Incomplete",IF(COUNT(S32:U32)=0,"Incomplete",IF(COUNT(V32:X32)=0,"Incomplete",IF(COUNT(Y32:AA32)=0,"Incomplete",IF(COUNT(AB32:AD32)=0,"Incomplete",IF(COUNT(AE32:AG32)=0,"Incomplete",AVERAGEIF(D32:F32,">=0")+AVERAGEIF(G32:I32,">=0")+AVERAGEIF(J32:L32,">=0")+AVERAGEIF(M32:O32,">=0")+AVERAGEIF(P32:R32,">=0")+AVERAGEIF(S32:U32,">=0")+AVERAGEIF(V32:X32,">=0")+AVERAGEIF(Y32:AA32,">=0")+AVERAGEIF(AB32:AD32,">=0")+AVERAGEIF(AE32:AG32,">=0"))))))))))))
A33: 27 | B33: =IF('(1).Classes'!B33="","",'(1).Classes'!B33) | C33: =IF('(1).Classes'!C33="","",'(1).Classes'!C33) | AH33: =IF(B33="","",IF(COUNT(D33:F33)=0,"Incomplete",IF(COUNT(G33:I33)=0,"Incomplete",IF(COUNT(J33:L33)=0,"Incomplete",IF(COUNT(M33:O33)=0,"Incomplete",IF(COUNT(P33:R33)=0,"Incomplete",IF(COUNT(S33:U33)=0,"Incomplete",IF(COUNT(V33:X33)=0,"Incomplete",IF(COUNT(Y33:AA33)=0,"Incomplete",IF(COUNT(AB33:AD33)=0,"Incomplete",IF(COUNT(AE33:AG33)=0,"Incomplete",AVERAGEIF(D33:F33,">=0")+AVERAGEIF(G33:I33,">=0")+AVERAGEIF(J33:L33,">=0")+AVERAGEIF(M33:O33,">=0")+AVERAGEIF(P33:R33,">=0")+AVERAGEIF(S33:U33,">=0")+AVERAGEIF(V33:X33,">=0")+AVERAGEIF(Y33:AA33,">=0")+AVERAGEIF(AB33:AD33,">=0")+AVERAGEIF(AE33:AG33,">=0"))))))))))))
A34: 28 | B34: =IF('(1).Classes'!B34="","",'(1).Classes'!B34) | C34: =IF('(1).Classes'!C34="","",'(1).Classes'!C34) | AH34: =IF(B34="","",IF(COUNT(D34:F34)=0,"Incomplete",IF(COUNT(G34:I34)=0,"Incomplete",IF(COUNT(J34:L34)=0,"Incomplete",IF(COUNT(M34:O34)=0,"Incomplete",IF(COUNT(P34:R34)=0,"Incomplete",IF(COUNT(S34:U34)=0,"Incomplete",IF(COUNT(V34:X34)=0,"Incomplete",IF(COUNT(Y34:AA34)=0,"Incomplete",IF(COUNT(AB34:AD34)=0,"Incomplete",IF(COUNT(AE34:AG34)=0,"Incomplete",AVERAGEIF(D34:F34,">=0")+AVERAGEIF(G34:I34,">=0")+AVERAGEIF(J34:L34,">=0")+AVERAGEIF(M34:O34,">=0")+AVERAGEIF(P34:R34,">=0")+AVERAGEIF(S34:U34,">=0")+AVERAGEIF(V34:X34,">=0")+AVERAGEIF(Y34:AA34,">=0")+AVERAGEIF(AB34:AD34,">=0")+AVERAGEIF(AE34:AG34,">=0"))))))))))))
A35: 29 | B35: =IF('(1).Classes'!B35="","",'(1).Classes'!B35) | C35: =IF('(1).Classes'!C35="","",'(1).Classes'!C35) | AH35: =IF(B35="","",IF(COUNT(D35:F35)=0,"Incomplete",IF(COUNT(G35:I35)=0,"Incomplete",IF(COUNT(J35:L35)=0,"Incomplete",IF(COUNT(M35:O35)=0,"Incomplete",IF(COUNT(P35:R35)=0,"Incomplete",IF(COUNT(S35:U35)=0,"Incomplete",IF(COUNT(V35:X35)=0,"Incomplete",IF(COUNT(Y35:AA35)=0,"Incomplete",IF(COUNT(AB35:AD35)=0,"Incomplete",IF(COUNT(AE35:AG35)=0,"Incomplete",AVERAGEIF(D35:F35,">=0")+AVERAGEIF(G35:I35,">=0")+AVERAGEIF(J35:L35,">=0")+AVERAGEIF(M35:O35,">=0")+AVERAGEIF(P35:R35,">=0")+AVERAGEIF(S35:U35,">=0")+AVERAGEIF(V35:X35,">=0")+AVERAGEIF(Y35:AA35,">=0")+AVERAGEIF(AB35:AD35,">=0")+AVERAGEIF(AE35:AG35,">=0"))))))))))))
A36: 30 | B36: =IF('(1).Classes'!B36="","",'(1).Classes'!B36) | C36: =IF('(1).Classes'!C36="","",'(1).Classes'!C36) | AH36: =IF(B36="","",IF(COUNT(D36:F36)=0,"Incomplete",IF(COUNT(G36:I36)=0,"Incomplete",IF(COUNT(J36:L36)=0,"Incomplete",IF(COUNT(M36:O36)=0,"Incomplete",IF(COUNT(P36:R36)=0,"Incomplete",IF(COUNT(S36:U36)=0,"Incomplete",IF(COUNT(V36:X36)=0,"Incomplete",IF(COUNT(Y36:AA36)=0,"Incomplete",IF(COUNT(AB36:AD36)=0,"Incomplete",IF(COUNT(AE36:AG36)=0,"Incomplete",AVERAGEIF(D36:F36,">=0")+AVERAGEIF(G36:I36,">=0")+AVERAGEIF(J36:L36,">=0")+AVERAGEIF(M36:O36,">=0")+AVERAGEIF(P36:R36,">=0")+AVERAGEIF(S36:U36,">=0")+AVERAGEIF(V36:X36,">=0")+AVERAGEIF(Y36:AA36,">=0")+AVERAGEIF(AB36:AD36,">=0")+AVERAGEIF(AE36:AG36,">=0"))))))))))))
A37: Br: | B37: ='(1).Classes'!F1 -> 0 | D37: MIDTERM DAILY SCORE SHEET
A38: Level: | B38: ='(1).Classes'!F2 -> 0
A39: Time: | B39: ='(1).Classes'!F3 -> 0 | D39: =D3 -> FEBRUARY - JULY 2026
A40: Room: | B40: ='(1).Classes'!F4 -> 0
A41: Tr: | B41: ='(1).Classes'!F5 -> 0 | D41: =IF(OR($B38="K5",$B38="K6",$B38="K7",$B38="K8",$B38="K9",$B38="K10"),"Listening","Up-Low C") -> Up-Low C | G41: =IF(OR($B38="K5",$B38="K6",$B38="K7",$B38="K8",$B38="K9",$B38="K10"),"Speaking","Alphabet N") -> Alphabet N | J41: =IF(OR($B38="K5",$B38="K6",$B38="K7",$B38="K8",$B38="K9",$B38="K10"),"Reading","Alphabet S") -> Alphabet S | M41: =IF(OR($B38="K5",$B38="K6",$B38="K7",$B38="K8",$B38="K9",$B38="K10"),"Writing","Vocabulary") -> Vocabulary | P41: =IF(OR($B38="K5",$B38="K6",$B38="K7",$B38="K8",$B38="K9",$B38="K10"),"Gram/Vocab","Sprouts") -> Sprouts | S41: =IF(OR($B38="K5",$B38="K6",$B38="K7",$B38="K8",$B38="K9",$B38="K10"),"Roots","Phonics") -> Phonics | V41: =IF(OR($B38="K5",$B38="K6",$B38="K7",$B38="K8",$B38="K9",$B38="K10"),"Phonics","Math") -> Math | Y41: =IF(OR($B38="K5",$B38="K6",$B38="K7",$B38="K8",$B38="K9",$B38="K10"),"Math","Shape") -> Shape | AB41: Science | AE41: =IF(OR($B38="K5",$B38="K6",$B38="K7",$B38="K8",$B38="K9",$B38="K10"),"Homework","Tracing") -> Tracing | AH41: Change
A42: NO | B42: NAME | C42: SEX | D42: 10 points | G42: 10 points | J42: 10 points | M42: 10 points | P42: 10 points | S42: 10 points | V42: 10 points | Y42: 10 points | AB42: 10 points | AE42: 10 points | AH42: Stop
A43: 1 | B43: =IF('(1).Classes'!F7="","",'(1).Classes'!F7) | C43: =IF('(1).Classes'!G7="","",'(1).Classes'!G7) | AH43: =IF(B43="","",IF(COUNT(D43:F43)=0,"Incomplete",IF(COUNT(G43:I43)=0,"Incomplete",IF(COUNT(J43:L43)=0,"Incomplete",IF(COUNT(M43:O43)=0,"Incomplete",IF(COUNT(P43:R43)=0,"Incomplete",IF(COUNT(S43:U43)=0,"Incomplete",IF(COUNT(V43:X43)=0,"Incomplete",IF(COUNT(Y43:AA43)=0,"Incomplete",IF(COUNT(AB43:AD43)=0,"Incomplete",IF(COUNT(AE43:AG43)=0,"Incomplete",AVERAGEIF(D43:F43,">=0")+AVERAGEIF(G43:I43,">=0")+AVERAGEIF(J43:L43,">=0")+AVERAGEIF(M43:O43,">=0")+AVERAGEIF(P43:R43,">=0")+AVERAGEIF(S43:U43,">=0")+AVERAGEIF(V43:X43,">=0")+AVERAGEIF(Y43:AA43,">=0")+AVERAGEIF(AB43:AD43,">=0")+AVERAGEIF(AE43:AG43,">=0"))))))))))))
A44: 2 | B44: =IF('(1).Classes'!F8="","",'(1).Classes'!F8) | C44: =IF('(1).Classes'!G8="","",'(1).Classes'!G8) | AH44: =IF(B44="","",IF(COUNT(D44:F44)=0,"Incomplete",IF(COUNT(G44:I44)=0,"Incomplete",IF(COUNT(J44:L44)=0,"Incomplete",IF(COUNT(M44:O44)=0,"Incomplete",IF(COUNT(P44:R44)=0,"Incomplete",IF(COUNT(S44:U44)=0,"Incomplete",IF(COUNT(V44:X44)=0,"Incomplete",IF(COUNT(Y44:AA44)=0,"Incomplete",IF(COUNT(AB44:AD44)=0,"Incomplete",IF(COUNT(AE44:AG44)=0,"Incomplete",AVERAGEIF(D44:F44,">=0")+AVERAGEIF(G44:I44,">=0")+AVERAGEIF(J44:L44,">=0")+AVERAGEIF(M44:O44,">=0")+AVERAGEIF(P44:R44,">=0")+AVERAGEIF(S44:U44,">=0")+AVERAGEIF(V44:X44,">=0")+AVERAGEIF(Y44:AA44,">=0")+AVERAGEIF(AB44:AD44,">=0")+AVERAGEIF(AE44:AG44,">=0"))))))))))))
A45: 3 | B45: =IF('(1).Classes'!F9="","",'(1).Classes'!F9) | C45: =IF('(1).Classes'!G9="","",'(1).Classes'!G9) | AH45: =IF(B45="","",IF(COUNT(D45:F45)=0,"Incomplete",IF(COUNT(G45:I45)=0,"Incomplete",IF(COUNT(J45:L45)=0,"Incomplete",IF(COUNT(M45:O45)=0,"Incomplete",IF(COUNT(P45:R45)=0,"Incomplete",IF(COUNT(S45:U45)=0,"Incomplete",IF(COUNT(V45:X45)=0,"Incomplete",IF(COUNT(Y45:AA45)=0,"Incomplete",IF(COUNT(AB45:AD45)=0,"Incomplete",IF(COUNT(AE45:AG45)=0,"Incomplete",AVERAGEIF(D45:F45,">=0")+AVERAGEIF(G45:I45,">=0")+AVERAGEIF(J45:L45,">=0")+AVERAGEIF(M45:O45,">=0")+AVERAGEIF(P45:R45,">=0")+AVERAGEIF(S45:U45,">=0")+AVERAGEIF(V45:X45,">=0")+AVERAGEIF(Y45:AA45,">=0")+AVERAGEIF(AB45:AD45,">=0")+AVERAGEIF(AE45:AG45,">=0"))))))))))))
A46: 4 | B46: =IF('(1).Classes'!F10="","",'(1).Classes'!F10) | C46: =IF('(1).Classes'!G10="","",'(1).Classes'!G10) | AH46: =IF(B46="","",IF(COUNT(D46:F46)=0,"Incomplete",IF(COUNT(G46:I46)=0,"Incomplete",IF(COUNT(J46:L46)=0,"Incomplete",IF(COUNT(M46:O46)=0,"Incomplete",IF(COUNT(P46:R46)=0,"Incomplete",IF(COUNT(S46:U46)=0,"Incomplete",IF(COUNT(V46:X46)=0,"Incomplete",IF(COUNT(Y46:AA46)=0,"Incomplete",IF(COUNT(AB46:AD46)=0,"Incomplete",IF(COUNT(AE46:AG46)=0,"Incomplete",AVERAGEIF(D46:F46,">=0")+AVERAGEIF(G46:I46,">=0")+AVERAGEIF(J46:L46,">=0")+AVERAGEIF(M46:O46,">=0")+AVERAGEIF(P46:R46,">=0")+AVERAGEIF(S46:U46,">=0")+AVERAGEIF(V46:X46,">=0")+AVERAGEIF(Y46:AA46,">=0")+AVERAGEIF(AB46:AD46,">=0")+AVERAGEIF(AE46:AG46,">=0"))))))))))))
...

Sheet (3).Midterm Exam
A1: Br: | B1: ='(2).Midterm Daily'!B1 -> C2 | D1: MIDTERM EXAM SCORE SHEET
A2: Level: | B2: ='(2).Midterm Daily'!B2 -> K1B
A3: Time: | B3: ='(2).Midterm Daily'!B3 -> 3:00-5:30 | D3: ='(2).Midterm Daily'!D3 -> FEBRUARY - JULY 2026
A4: Room: | B4: ='(2).Midterm Daily'!B4 -> 5
A5: Tr: | B5: ='(2).Midterm Daily'!B5 -> Hong Leeheng | D5: =IF(OR($B2="K5",$B2="K6",$B2="K7",$B2="K8",$B2="K9",$B2="K10"),"Listening","Up-Low C") -> Up-Low C | E5: =IF(OR($B2="K5",$B2="K6",$B2="K7",$B2="K8",$B2="K9",$B2="K10"),"Speaking","Alphabet N") -> Alphabet N | F5: =IF(OR($B2="K5",$B2="K6",$B2="K7",$B2="K8",$B2="K9",$B2="K10"),"Reading","Alphabet S") -> Alphabet S | G5: =IF(OR($B2="K5",$B2="K6",$B2="K7",$B2="K8",$B2="K9",$B2="K10"),"Writing","Vocabulary") -> Vocabulary | H5: =IF(OR($B2="K5",$B2="K6",$B2="K7",$B2="K8",$B2="K9",$B2="K10"),"Grammar","Sprouts") -> Sprouts | I5: =IF(OR($B2="K5",$B2="K6",$B2="K7",$B2="K8",$B2="K9",$B2="K10"),"Vocabulary","Phonics") -> Phonics | J5: =IF(OR($B2="K5",$B2="K6",$B2="K7",$B2="K8",$B2="K9",$B2="K10"),"Roots","Math") -> Math | K5: =IF(OR($B2="K5",$B2="K6",$B2="K7",$B2="K8",$B2="K9",$B2="K10"),"Phonics","Shape") -> Shape | L5: =IF(OR($B2="K5",$B2="K6",$B2="K7",$B2="K8",$B2="K9",$B2="K10"),"Math","Science") -> Science | M5: =IF(OR($B2="K5",$B2="K6",$B2="K7",$B2="K8",$B2="K9",$B2="K10"),"Science","Tracing") -> Tracing | N5: Stop
A6: NO | B6: NAME | C6: SEX | D6: 10 points | E6: 10 points | F6: 10 points | G6: 10 points | H6: 10 points | I6: 10 points | J6: 10 points | K6: 10 points | L6: 10 points | M6: 10 points | N6: Late Exam
A7: 1 | B7: =IF('(2).Midterm Daily'!B7="","",'(2).Midterm Daily'!B7) -> Chhim Chansithika | C7: =IF('(2).Midterm Daily'!C7="","",'(2).Midterm Daily'!C7) -> F | D7: 9 | E7: 8.5 | F7: 10 | G7: 5.5 | H7: 7.5 | I7: 9 | J7: 10 | K7: 10 | L7: 10 | M7: 8 | N7: =IF('(2).Midterm Daily'!AH7="Change","Change",IF('(2).Midterm Daily'!AH7="Stop","Stop",IF(B7="","",IF(COUNTA(D7:M7)<10,"Incomplete",""))))
A8: 2 | B8: =IF('(2).Midterm Daily'!B8="","",'(2).Midterm Daily'!B8) -> Chhout Senghour | C8: =IF('(2).Midterm Daily'!C8="","",'(2).Midterm Daily'!C8) -> M | D8: 6.5 | E8: 6.75 | F8: 3 | G8: 5 | H8: 2 | I8: 6 | J8: 10 | K8: 7 | L8: 6 | M8: 8 | N8: =IF('(2).Midterm Daily'!AH8="Change","Change",IF('(2).Midterm Daily'!AH8="Stop","Stop",IF(B8="","",IF(COUNTA(D8:M8)<10,"Incomplete",""))))
A9: 3 | B9: =IF('(2).Midterm Daily'!B9="","",'(2).Midterm Daily'!B9) -> Det Phouri | C9: =IF('(2).Midterm Daily'!C9="","",'(2).Midterm Daily'!C9) -> M | D9: 9 | E9: 9 | F9: 8.25 | G9: 8 | H9: 7.25 | I9: 9 | J9: 10 | K9: 8 | L9: 10 | M9: 8.5 | N9: =IF('(2).Midterm Daily'!AH9="Change","Change",IF('(2).Midterm Daily'!AH9="Stop","Stop",IF(B9="","",IF(COUNTA(D9:M9)<10,"Incomplete",""))))
A10: 4 | B10: =IF('(2).Midterm Daily'!B10="","",'(2).Midterm Daily'!B10) -> Dy Chanto | C10: =IF('(2).Midterm Daily'!C10="","",'(2).Midterm Daily'!C10) -> M | D10: 6.5 | E10: 4 | F10: 0.5 | G10: 5.5 | H10: 3 | I10: 2 | J10: 10 | K10: 9 | L10: 6.5 | M10: 8 | N10: =IF('(2).Midterm Daily'!AH10="Change","Change",IF('(2).Midterm Daily'!AH10="Stop","Stop",IF(B10="","",IF(COUNTA(D10:M10)<10,"Incomplete",""))))
A11: 5 | B11: =IF('(2).Midterm Daily'!B11="","",'(2).Midterm Daily'!B11) -> Dy Meyly | C11: =IF('(2).Midterm Daily'!C11="","",'(2).Midterm Daily'!C11) -> F | D11: 10 | E11: 10 | F11: 10 | G11: 10 | H11: 10 | I11: 10 | J11: 10 | K11: 10 | L11: 10 | M11: 10 | N11: =IF('(2).Midterm Daily'!AH11="Change","Change",IF('(2).Midterm Daily'!AH11="Stop","Stop",IF(B11="","",IF(COUNTA(D11:M11)<10,"Incomplete",""))))
A12: 6 | B12: =IF('(2).Midterm Daily'!B12="","",'(2).Midterm Daily'!B12) -> Heang Limhak | C12: =IF('(2).Midterm Daily'!C12="","",'(2).Midterm Daily'!C12) -> M | D12: 9.75 | E12: 8.75 | F12: 9.5 | G12: 8 | H12: 5 | I12: 10 | J12: 7 | K12: 7 | L12: 9 | M12: 9.5 | N12: =IF('(2).Midterm Daily'!AH12="Change","Change",IF('(2).Midterm Daily'!AH12="Stop","Stop",IF(B12="","",IF(COUNTA(D12:M12)<10,"Incomplete",""))))
A13: 7 | B13: =IF('(2).Midterm Daily'!B13="","",'(2).Midterm Daily'!B13) -> Keo Tepsatsjak | C13: =IF('(2).Midterm Daily'!C13="","",'(2).Midterm Daily'!C13) -> M | D13: 9 | E13: 8.5 | F13: 10 | G13: 9.5 | H13: 9 | I13: 10 | J13: 10 | K13: 10 | L13: 10 | M13: 9.75 | N13: =IF('(2).Midterm Daily'!AH13="Change","Change",IF('(2).Midterm Daily'!AH13="Stop","Stop",IF(B13="","",IF(COUNTA(D13:M13)<10,"Incomplete",""))))
A14: 8 | B14: =IF('(2).Midterm Daily'!B14="","",'(2).Midterm Daily'!B14) -> Kong Yonghae | C14: =IF('(2).Midterm Daily'!C14="","",'(2).Midterm Daily'!C14) -> M | D14: 10 | E14: 9.25 | F14: 9.75 | G14: 10 | H14: 9 | I14: 10 | J14: 10 | K14: 10 | L14: 10 | M14: 10 | N14: =IF('(2).Midterm Daily'!AH14="Change","Change",IF('(2).Midterm Daily'!AH14="Stop","Stop",IF(B14="","",IF(COUNTA(D14:M14)<10,"Incomplete",""))))
A15: 9 | B15: =IF('(2).Midterm Daily'!B15="","",'(2).Midterm Daily'!B15) -> Lim Davymulika | C15: =IF('(2).Midterm Daily'!C15="","",'(2).Midterm Daily'!C15) -> F | D15: 9.5 | E15: 7 | F15: 9 | G15: 6 | H15: 7.75 | I15: 7 | J15: 10 | K15: 7 | L15: 10 | M15: 9 | N15: =IF('(2).Midterm Daily'!AH15="Change","Change",IF('(2).Midterm Daily'!AH15="Stop","Stop",IF(B15="","",IF(COUNTA(D15:M15)<10,"Incomplete",""))))
A16: 10 | B16: =IF('(2).Midterm Daily'!B16="","",'(2).Midterm Daily'!B16) -> Lot SamAngvichara | C16: =IF('(2).Midterm Daily'!C16="","",'(2).Midterm Daily'!C16) -> F | D16: 9 | E16: 9.5 | F16: 10 | G16: 10 | H16: 10 | I16: 10 | J16: 10 | K16: 10 | L16: 10 | M16: 9 | N16: =IF('(2).Midterm Daily'!AH16="Change","Change",IF('(2).Midterm Daily'!AH16="Stop","Stop",IF(B16="","",IF(COUNTA(D16:M16)<10,"Incomplete",""))))
A17: 11 | B17: =IF('(2).Midterm Daily'!B17="","",'(2).Midterm Daily'!B17) -> Lot Vichheka | C17: =IF('(2).Midterm Daily'!C17="","",'(2).Midterm Daily'!C17) -> M | D17: 9.5 | E17: 10 | F17: 10 | G17: 10 | H17: 10 | I17: 10 | J17: 10 | K17: 10 | L17: 10 | M17: 9.75 | N17: =IF('(2).Midterm Daily'!AH17="Change","Change",IF('(2).Midterm Daily'!AH17="Stop","Stop",IF(B17="","",IF(COUNTA(D17:M17)<10,"Incomplete",""))))
A18: 12 | B18: =IF('(2).Midterm Daily'!B18="","",'(2).Midterm Daily'!B18) -> Ly Kanha | C18: =IF('(2).Midterm Daily'!C18="","",'(2).Midterm Daily'!C18) -> F | D18: 8 | E18: 8.5 | F18: 10 | G18: 9 | H18: 9 | I18: 9 | J18: 10 | K18: 10 | L18: 8 | M18: 10 | N18: =IF('(2).Midterm Daily'!AH18="Change","Change",IF('(2).Midterm Daily'!AH18="Stop","Stop",IF(B18="","",IF(COUNTA(D18:M18)<10,"Incomplete",""))))
... A25: 19 | B25: =IF('(2).Midterm Daily'!B25="","",'(2).Midterm Daily'!B25) -> Vy Monineath | C25: =IF('(2).Midterm Daily'!C25="","",'(2).Midterm Daily'!C25) -> F | D25: 9 | E25: 10 | F25: 10 | G25: 10 | H25: 9 | I25: 10 | J25: 10 | K25: 10 | L25: 10 | M25: 10 | N25: =IF('(2).Midterm Daily'!AH25="Change","Change",IF('(2).Midterm Daily'!AH25="Stop","Stop",IF(B25="","",IF(COUNTA(D25:M25)<10,"Incomplete",""))))
A26: 20 | B26: =IF('(2).Midterm Daily'!B26="","",'(2).Midterm Daily'!B26) | C26: =IF('(2).Midterm Daily'!C26="","",'(2).Midterm Daily'!C26) | N26: =IF('(2).Midterm Daily'!AH26="Change","Change",IF('(2).Midterm Daily'!AH26="Stop","Stop",IF(B26="","",IF(COUNTA(D26:M26)<10,"Incomplete",""))))
A27: 21 | B27: =IF('(2).Midterm Daily'!B27="","",'(2).Midterm Daily'!B27) | C27: =IF('(2).Midterm Daily'!C27="","",'(2).Midterm Daily'!C27) | N27: =IF('(2).Midterm Daily'!AH27="Change","Change",IF('(2).Midterm Daily'!AH27="Stop","Stop",IF(B27="","",IF(COUNTA(D27:M27)<10,"Incomplete",""))))
A28: 22 | B28: =IF('(2).Midterm Daily'!B28="","",'(2).Midterm Daily'!B28) | C28: =IF('(2).Midterm Daily'!C28="","",'(2).Midterm Daily'!C28) | N28: =IF('(2).Midterm Daily'!AH28="Change","Change",IF('(2).Midterm Daily'!AH28="Stop","Stop",IF(B28="","",IF(COUNTA(D28:M28)<10,"Incomplete",""))))
A29: 23 | B29: =IF('(2).Midterm Daily'!B29="","",'(2).Midterm Daily'!B29) | C29: =IF('(2).Midterm Daily'!C29="","",'(2).Midterm Daily'!C29) | N29: =IF('(2).Midterm Daily'!AH29="Change","Change",IF('(2).Midterm Daily'!AH29="Stop","Stop",IF(B29="","",IF(COUNTA(D29:M29)<10,"Incomplete",""))))
A30: 24 | B30: =IF('(2).Midterm Daily'!B30="","",'(2).Midterm Daily'!B30) | C30: =IF('(2).Midterm Daily'!C30="","",'(2).Midterm Daily'!C30) | N30: =IF('(2).Midterm Daily'!AH30="Change","Change",IF('(2).Midterm Daily'!AH30="Stop","Stop",IF(B30="","",IF(COUNTA(D30:M30)<10,"Incomplete",""))))
A31: 25 | B31: =IF('(2).Midterm Daily'!B31="","",'(2).Midterm Daily'!B31) | C31: =IF('(2).Midterm Daily'!C31="","",'(2).Midterm Daily'!C31) | N31: =IF('(2).Midterm Daily'!AH31="Change","Change",IF('(2).Midterm Daily'!AH31="Stop","Stop",IF(B31="","",IF(COUNTA(D31:M31)<10,"Incomplete",""))))
A32: 26 | B32: =IF('(2).Midterm Daily'!B32="","",'(2).Midterm Daily'!B32) | C32: =IF('(2).Midterm Daily'!C32="","",'(2).Midterm Daily'!C32) | N32: =IF('(2).Midterm Daily'!AH32="Change","Change",IF('(2).Midterm Daily'!AH32="Stop","Stop",IF(B32="","",IF(COUNTA(D32:M32)<10,"Incomplete",""))))
A33: 27 | B33: =IF('(2).Midterm Daily'!B33="","",'(2).Midterm Daily'!B33) | C33: =IF('(2).Midterm Daily'!C33="","",'(2).Midterm Daily'!C33) | N33: =IF('(2).Midterm Daily'!AH33="Change","Change",IF('(2).Midterm Daily'!AH33="Stop","Stop",IF(B33="","",IF(COUNTA(D33:M33)<10,"Incomplete",""))))
A34: 28 | B34: =IF('(2).Midterm Daily'!B34="","",'(2).Midterm Daily'!B34) | C34: =IF('(2).Midterm Daily'!C34="","",'(2).Midterm Daily'!C34) | N34: =IF('(2).Midterm Daily'!AH34="Change","Change",IF('(2).Midterm Daily'!AH34="Stop","Stop",IF(B34="","",IF(COUNTA(D34:M34)<10,"Incomplete",""))))
A35: 29 | B35: =IF('(2).Midterm Daily'!B35="","",'(2).Midterm Daily'!B35) | C35: =IF('(2).Midterm Daily'!C35="","",'(2).Midterm Daily'!C35) | N35: =IF('(2).Midterm Daily'!AH35="Change","Change",IF('(2).Midterm Daily'!AH35="Stop","Stop",IF(B35="","",IF(COUNTA(D35:M35)<10,"Incomplete",""))))
A36: 30 | B36: =IF('(2).Midterm Daily'!B36="","",'(2).Midterm Daily'!B36) | C36: =IF('(2).Midterm Daily'!C36="","",'(2).Midterm Daily'!C36) | N36: =IF('(2).Midterm Daily'!AH36="Change","Change",IF('(2).Midterm Daily'!AH36="Stop","Stop",IF(B36="","",IF(COUNTA(D36:M36)<10,"Incomplete",""))))
A37: Br: | B37: ='(2).Midterm Daily'!B37 -> 0 | D37: MIDTERM EXAM SCORE SHEET
A38: Level: | B38: ='(2).Midterm Daily'!B38 -> 0
A39: Time: | B39: ='(2).Midterm Daily'!B39 -> 0 | D39: ='(2).Midterm Daily'!D39 -> FEBRUARY - JULY 2026
A40: Room: | B40: ='(2).Midterm Daily'!B40 -> 0
A41: Tr: | B41: ='(2).Midterm Daily'!B41 -> 0 | D41: =IF(OR($B38="K5",$B38="K6",$B38="K7",$B38="K8",$B38="K9",$B38="K10"),"Listening","Up-Low C") -> Up-Low C | E41: =IF(OR($B38="K5",$B38="K6",$B38="K7",$B38="K8",$B38="K9",$B38="K10"),"Speaking","Alphabet N") -> Alphabet N | F41: =IF(OR($B38="K5",$B38="K6",$B38="K7",$B38="K8",$B38="K9",$B38="K10"),"Reading","Alphabet S") -> Alphabet S | G41: =IF(OR($B38="K5",$B38="K6",$B38="K7",$B38="K8",$B38="K9",$B38="K10"),"Writing","Vocabulary") -> Vocabulary | H41: =IF(OR($B38="K5",$B38="K6",$B38="K7",$B38="K8",$B38="K9",$B38="K10"),"Grammar","Sprouts") -> Sprouts | I41: =IF(OR($B38="K5",$B38="K6",$B38="K7",$B38="K8",$B38="K9",$B38="K10"),"Vocabulary","Phonics") -> Phonics | J41: =IF(OR($B38="K5",$B38="K6",$B38="K7",$B38="K8",$B38="K9",$B38="K10"),"Roots","Math") -> Math | K41: =IF(OR($B38="K5",$B38="K6",$B38="K7",$B38="K8",$B38="K9",$B38="K10"),"Phonics","Shape") -> Shape | L41: =IF(OR($B38="K5",$B38="K6",$B38="K7",$B38="K8",$B38="K9",$B38="K10"),"Math","Science") -> Science | M41: =IF(OR($B38="K5",$B38="K6",$B38="K7",$B38="K8",$B38="K9",$B38="K10"),"Science","Tracing") -> Tracing | N41: Stop
A42: NO | B42: NAME | C42: SEX | D42: 10 points | E42: 10 points | F42: 10 points | G42: 10 points | H42: 10 points | I42: 10 points | J42: 10 points | K42: 10 points | L42: 10 points | M42: 10 points | N42: Late Exam
A43: 1 | B43: =IF('(2).Midterm Daily'!B43="","",'(2).Midterm Daily'!B43) | C43: =IF('(2).Midterm Daily'!C43="","",'(2).Midterm Daily'!C43) | N43: =IF('(2).Midterm Daily'!AH43="Change","Change",IF('(2).Midterm Daily'!AH43="Stop","Stop",IF(B43="","",IF(COUNTA(D43:M43)<10,"Incomplete",""))))
A44: 2 | B44: =IF('(2).Midterm Daily'!B44="","",'(2).Midterm Daily'!B44) | C44: =IF('(2).Midterm Daily'!C44="","",'(2).Midterm Daily'!C44) | N44: =IF('(2).Midterm Daily'!AH44="Change","Change",IF('(2).Midterm Daily'!AH44="Stop","Stop",IF(B44="","",IF(COUNTA(D44:M44)<10,"Incomplete",""))))
A45: 3 | B45: =IF('(2).Midterm Daily'!B45="","",'(2).Midterm Daily'!B45) | C45: =IF('(2).Midterm Daily'!C45="","",'(2).Midterm Daily'!C45) | N45: =IF('(2).Midterm Daily'!AH45="Change","Change",IF('(2).Midterm Daily'!AH45="Stop","Stop",IF(B45="","",IF(COUNTA(D45:M45)<10,"Incomplete",""))))
A46: 4 | B46: =IF('(2).Midterm Daily'!B46="","",'(2).Midterm Daily'!B46) | C46: =IF('(2).Midterm Daily'!C46="","",'(2).Midterm Daily'!C46) | N46: =IF('(2).Midterm Daily'!AH46="Change","Change",IF('(2).Midterm Daily'!AH46="Stop","Stop",IF(B46="","",IF(COUNTA(D46:M46)<10,"Incomplete",""))))
...

Sheet (4).Midterm Results
A1: Br: | B1: ='(3).Midterm Exam'!B1 -> C2 | D1: MIDTERM RESULTS
A2: Level: | B2: ='(3).Midterm Exam'!B2 -> K1B | D2: ='(3).Midterm Exam'!D3 -> FEBRUARY - JULY 2026
A3: Time: | B3: ='(3).Midterm Exam'!B3 -> 3:00-5:30 | D3: *** Midterm Results (Total Scores) = Midterm Daily (20%) + Midterm Exam (80%) ***
A4: Room: | B4: ='(3).Midterm Exam'!B4 -> 5 | D4: MIDTERM | E4: MIDTERM EXAM | O4: TOTAL
A5: Tr: | B5: ='(3).Midterm Exam'!B5 -> Hong Leeheng | D5: DAILY | E5: =IF(OR($B2="K5",$B2="K6",$B2="K7",$B2="K8",$B2="K9",$B2="K10"),"Listening","Up-Low C") -> Up-Low C | F5: =IF(OR($B2="K5",$B2="K6",$B2="K7",$B2="K8",$B2="K9",$B2="K10"),"Speaking","Alphabet N") -> Alphabet N | G5: =IF(OR($B2="K5",$B2="K6",$B2="K7",$B2="K8",$B2="K9",$B2="K10"),"Reading","Alphabet S") -> Alphabet S | H5: =IF(OR($B2="K5",$B2="K6",$B2="K7",$B2="K8",$B2="K9",$B2="K10"),"Writing","Vocabulary") -> Vocabulary | I5: =IF(OR($B2="K5",$B2="K6",$B2="K7",$B2="K8",$B2="K9",$B2="K10"),"Grammar","Sprouts") -> Sprouts | J5: =IF(OR($B2="K5",$B2="K6",$B2="K7",$B2="K8",$B2="K9",$B2="K10"),"Vocabulary","Phonics") -> Phonics | K5: =IF(OR($B2="K5",$B2="K6",$B2="K7",$B2="K8",$B2="K9",$B2="K10"),"Roots","Math") -> Math | L5: =IF(OR($B2="K5",$B2="K6",$B2="K7",$B2="K8",$B2="K9",$B2="K10"),"Phonics","Shape") -> Shape | M5: =IF(OR($B2="K5",$B2="K6",$B2="K7",$B2="K8",$B2="K9",$B2="K10"),"Math","Science") -> Science | N5: =IF(OR($B2="K5",$B2="K6",$B2="K7",$B2="K8",$B2="K9",$B2="K10"),"Science","Tracing") -> Tracing | O5: SCORES
A6: NO | B6: NAME | C6: SEX | D6: 100 points | E6: 10 points | F6: 10 points | G6: 10 points | H6: 10 points | I6: 10 points | J6: 10 points | K6: 10 points | L6: 10 points | M6: 10 points | N6: 10 points | O6: 100 points
A7: 1 | B7: =IF('(3).Midterm Exam'!B7="","",'(3).Midterm Exam'!B7) -> Chhim Chansithika | C7: =IF('(3).Midterm Exam'!C7="","",'(3).Midterm Exam'!C7) -> F | D7: =IF('(2).Midterm Daily'!AH7="","",'(2).Midterm Daily'!AH7) -> 85.875 | E7: =IF('(3).Midterm Exam'!D7="","",'(3).Midterm Exam'!D7) -> 9 | F7: =IF('(3).Midterm Exam'!E7="","",'(3).Midterm Exam'!E7) -> 8.5 | G7: =IF('(3).Midterm Exam'!F7="","",'(3).Midterm Exam'!F7) -> 10 | H7: =IF('(3).Midterm Exam'!G7="","",'(3).Midterm Exam'!G7) -> 5.5 | I7: =IF('(3).Midterm Exam'!H7="","",'(3).Midterm Exam'!H7) -> 7.5 | J7: =IF('(3).Midterm Exam'!I7="","",'(3).Midterm Exam'!I7) -> 9 | K7: =IF('(3).Midterm Exam'!J7="","",'(3).Midterm Exam'!J7) -> 10 | L7: =IF('(3).Midterm Exam'!K7="","",'(3).Midterm Exam'!K7) -> 10 | ... N7: =IF('(3).Midterm Exam'!M7="","",'(3).Midterm Exam'!M7) -> 8 | O7: =IF(B7="","",IF(D7="Incomplete","Incomplete",IF('(3).Midterm Exam'!N7="Change","Change",IF('(3).Midterm Exam'!N7="Stop","Stop",IF('(3).Midterm Exam'!N7="Incomplete","Incomplete",IF(COUNTBLANK(D7:N7)>=1,"Incomplete",D7*20%+SUM(E7:N7)*80%)))))) -> 87.175
A8: 2 | B8: =IF('(3).Midterm Exam'!B8="","",'(3).Midterm Exam'!B8) -> Chhout Senghour | C8: =IF('(3).Midterm Exam'!C8="","",'(3).Midterm Exam'!C8) -> M | D8: =IF('(2).Midterm Daily'!AH8="","",'(2).Midterm Daily'!AH8) -> 67.25 | E8: =IF('(3).Midterm Exam'!D8="","",'(3).Midterm Exam'!D8) -> 6.5 | F8: =IF('(3).Midterm Exam'!E8="","",'(3).Midterm Exam'!E8) -> 6.75 | G8: =IF('(3).Midterm Exam'!F8="","",'(3).Midterm Exam'!F8) -> 3 | H8: =IF('(3).Midterm Exam'!G8="","",'(3).Midterm Exam'!G8) -> 5 | I8: =IF('(3).Midterm Exam'!H8="","",'(3).Midterm Exam'!H8) -> 2 | J8: =IF('(3).Midterm Exam'!I8="","",'(3).Midterm Exam'!I8) -> 6 | K8: =IF('(3).Midterm Exam'!J8="","",'(3).Midterm Exam'!J8) -> 10 | L8: =IF('(3).Midterm Exam'!K8="","",'(3).Midterm Exam'!K8) -> 7 | ... N8: =IF('(3).Midterm Exam'!M8="","",'(3).Midterm Exam'!M8) -> 8 | O8: =IF(B8="","",IF(D8="Incomplete","Incomplete",IF('(3).Midterm Exam'!N8="Change","Change",IF('(3).Midterm Exam'!N8="Stop","Stop",IF('(3).Midterm Exam'!N8="Incomplete","Incomplete",IF(COUNTBLANK(D8:N8)>=1,"Incomplete",D8*20%+SUM(E8:N8)*80%)))))) -> 61.65
A9: 3 | B9: =IF('(3).Midterm Exam'!B9="","",'(3).Midterm Exam'!B9) -> Det Phouri | C9: =IF('(3).Midterm Exam'!C9="","",'(3).Midterm Exam'!C9) -> M | D9: =IF('(2).Midterm Daily'!AH9="","",'(2).Midterm Daily'!AH9) -> 89.625 | E9: =IF('(3).Midterm Exam'!D9="","",'(3).Midterm Exam'!D9) -> 9 | F9: =IF('(3).Midterm Exam'!E9="","",'(3).Midterm Exam'!E9) -> 9 | G9: =IF('(3).Midterm Exam'!F9="","",'(3).Midterm Exam'!F9) -> 8.25 | H9: =IF('(3).Midterm Exam'!G9="","",'(3).Midterm Exam'!G9) -> 8 | I9: =IF('(3).Midterm Exam'!H9="","",'(3).Midterm Exam'!H9) -> 7.25 | J9: =IF('(3).Midterm Exam'!I9="","",'(3).Midterm Exam'!I9) -> 9 | K9: =IF('(3).Midterm Exam'!J9="","",'(3).Midterm Exam'!J9) -> 10 | L9: =IF('(3).Midterm Exam'!K9="","",'(3).Midterm Exam'!K9) -> 8 | ... N9: =IF('(3).Midterm Exam'!M9="","",'(3).Midterm Exam'!M9) -> 8.5 | O9: =IF(B9="","",IF(D9="Incomplete","Incomplete",IF('(3).Midterm Exam'!N9="Change","Change",IF('(3).Midterm Exam'!N9="Stop","Stop",IF('(3).Midterm Exam'!N9="Incomplete","Incomplete",IF(COUNTBLANK(D9:N9)>=1,"Incomplete",D9*20%+SUM(E9:N9)*80%)))))) -> 87.525
A10: 4 | B10: =IF('(3).Midterm Exam'!B10="","",'(3).Midterm Exam'!B10) -> Dy Chanto | C10: =IF('(3).Midterm Exam'!C10="","",'(3).Midterm Exam'!C10) -> M | D10: =IF('(2).Midterm Daily'!AH10="","",'(2).Midterm Daily'!AH10) -> 49 | E10: =IF('(3).Midterm Exam'!D10="","",'(3).Midterm Exam'!D10) -> 6.5 | F10: =IF('(3).Midterm Exam'!E10="","",'(3).Midterm Exam'!E10) -> 4 | G10: =IF('(3).Midterm Exam'!F10="","",'(3).Midterm Exam'!F10) -> 0.5 | H10: =IF('(3).Midterm Exam'!G10="","",'(3).Midterm Exam'!G10) -> 5.5 | I10: =IF('(3).Midterm Exam'!H10="","",'(3).Midterm Exam'!H10) -> 3 | J10: =IF('(3).Midterm Exam'!I10="","",'(3).Midterm Exam'!I10) -> 2 | K10: =IF('(3).Midterm Exam'!J10="","",'(3).Midterm Exam'!J10) -> 10 | L10: =IF('(3).Midterm Exam'!K10="","",'(3).Midterm Exam'!K10) -> 9 | ... N10: =IF('(3).Midterm Exam'!M10="","",'(3).Midterm Exam'!M10) -> 8 | O10: =IF(B10="","",IF(D10="Incomplete","Incomplete",IF('(3).Midterm Exam'!N10="Change","Change",IF('(3).Midterm Exam'!N10="Stop","Stop",IF('(3).Midterm Exam'!N10="Incomplete","Incomplete",IF(COUNTBLANK(D10:N10)>=1,"Incomplete",D10*20%+SUM(E10:N10)*80%)))))) -> 53.8
A11: 5 | B11: =IF('(3).Midterm Exam'!B11="","",'(3).Midterm Exam'!B11) -> Dy Meyly | C11: =IF('(3).Midterm Exam'!C11="","",'(3).Midterm Exam'!C11) -> F | D11: =IF('(2).Midterm Daily'!AH11="","",'(2).Midterm Daily'!AH11) -> 96.625 | E11: =IF('(3).Midterm Exam'!D11="","",'(3).Midterm Exam'!D11) -> 10 | F11: =IF('(3).Midterm Exam'!E11="","",'(3).Midterm Exam'!E11) -> 10 | G11: =IF('(3).Midterm Exam'!F11="","",'(3).Midterm Exam'!F11) -> 10 | H11: =IF('(3).Midterm Exam'!G11="","",'(3).Midterm Exam'!G11) -> 10 | I11: =IF('(3).Midterm Exam'!H11="","",'(3).Midterm Exam'!H11) -> 10 | J11: =IF('(3).Midterm Exam'!I11="","",'(3).Midterm Exam'!I11) -> 10 | K11: =IF('(3).Midterm Exam'!J11="","",'(3).Midterm Exam'!J11) -> 10 | L11: =IF('(3).Midterm Exam'!K11="","",'(3).Midterm Exam'!K11) -> 10 | ... N11: =IF('(3).Midterm Exam'!M11="","",'(3).Midterm Exam'!M11) -> 10 | O11: =IF(B11="","",IF(D11="Incomplete","Incomplete",IF('(3).Midterm Exam'!N11="Change","Change",IF('(3).Midterm Exam'!N11="Stop","Stop",IF('(3).Midterm Exam'!N11="Incomplete","Incomplete",IF(COUNTBLANK(D11:N11)>=1,"Incomplete",D11*20%+SUM(E11:N11)*80%)))))) -> 99.325
A12: 6 | B12: =IF('(3).Midterm Exam'!B12="","",'(3).Midterm Exam'!B12) -> Heang Limhak | C12: =IF('(3).Midterm Exam'!C12="","",'(3).Midterm Exam'!C12) -> M | D12: =IF('(2).Midterm Daily'!AH12="","",'(2).Midterm Daily'!AH12) -> 83.25 | E12: =IF('(3).Midterm Exam'!D12="","",'(3).Midterm Exam'!D12) -> 9.75 | F12: =IF('(3).Midterm Exam'!E12="","",'(3).Midterm Exam'!E12) -> 8.75 | G12: =IF('(3).Midterm Exam'!F12="","",'(3).Midterm Exam'!F12) -> 9.5 | H12: =IF('(3).Midterm Exam'!G12="","",'(3).Midterm Exam'!G12) -> 8 | I12: =IF('(3).Midterm Exam'!H12="","",'(3).Midterm Exam'!H12) -> 5 | J12: =IF('(3).Midterm Exam'!I12="","",'(3).Midterm Exam'!I12) -> 10 | K12: =IF('(3).Midterm Exam'!J12="","",'(3).Midterm Exam'!J12) -> 7 | L12: =IF('(3).Midterm Exam'!K12="","",'(3).Midterm Exam'!K12) -> 7 | ... N12: =IF('(3).Midterm Exam'!M12="","",'(3).Midterm Exam'!M12) -> 9.5 | O12: =IF(B12="","",IF(D12="Incomplete","Incomplete",IF('(3).Midterm Exam'!N12="Change","Change",IF('(3).Midterm Exam'!N12="Stop","Stop",IF('(3).Midterm Exam'!N12="Incomplete","Incomplete",IF(COUNTBLANK(D12:N12)>=1,"Incomplete",D12*20%+SUM(E12:N12)*80%)))))) -> 83.45
A13: 7 | B13: =IF('(3).Midterm Exam'!B13="","",'(3).Midterm Exam'!B13) -> Keo Tepsatsjak | C13: =IF('(3).Midterm Exam'!C13="","",'(3).Midterm Exam'!C13) -> M | D13: =IF('(2).Midterm Daily'!AH13="","",'(2).Midterm Daily'!AH13) -> 91.5 | E13: =IF('(3).Midterm Exam'!D13="","",'(3).Midterm Exam'!D13) -> 9 | F13: =IF('(3).Midterm Exam'!E13="","",'(3).Midterm Exam'!E13) -> 8.5 | G13: =IF('(3).Midterm Exam'!F13="","",'(3).Midterm Exam'!F13) -> 10 | H13: =IF('(3).Midterm Exam'!G13="","",'(3).Midterm Exam'!G13) -> 9.5 | I13: =IF('(3).Midterm Exam'!H13="","",'(3).Midterm Exam'!H13) -> 9 | J13: =IF('(3).Midterm Exam'!I13="","",'(3).Midterm Exam'!I13) -> 10 | K13: =IF('(3).Midterm Exam'!J13="","",'(3).Midterm Exam'!J13) -> 10 | L13: =IF('(3).Midterm Exam'!K13="","",'(3).Midterm Exam'!K13) -> 10 | ... N13: =IF('(3).Midterm Exam'!M13="","",'(3).Midterm Exam'!M13) -> 9.75 | O13: =IF(B13="","",IF(D13="Incomplete","Incomplete",IF('(3).Midterm Exam'!N13="Change","Change",IF('(3).Midterm Exam'!N13="Stop","Stop",IF('(3).Midterm Exam'!N13="Incomplete","Incomplete",IF(COUNTBLANK(D13:N13)>=1,"Incomplete",D13*20%+SUM(E13:N13)*80%)))))) -> 94.9
A14: 8 | B14: =IF('(3).Midterm Exam'!B14="","",'(3).Midterm Exam'!B14) -> Kong Yonghae | C14: =IF('(3).Midterm Exam'!C14="","",'(3).Midterm Exam'!C14) -> M | D14: =IF('(2).Midterm Daily'!AH14="","",'(2).Midterm Daily'!AH14) -> 91 | E14: =IF('(3).Midterm Exam'!D14="","",'(3).Midterm Exam'!D14) -> 10 | F14: =IF('(3).Midterm Exam'!E14="","",'(3).Midterm Exam'!E14) -> 9.25 | G14: =IF('(3).Midterm Exam'!F14="","",'(3).Midterm Exam'!F14) -> 9.75 | H14: =IF('(3).Midterm Exam'!G14="","",'(3).Midterm Exam'!G14) -> 10 | I14: =IF('(3).Midterm Exam'!H14="","",'(3).Midterm Exam'!H14) -> 9 | J14: =IF('(3).Midterm Exam'!I14="","",'(3).Midterm Exam'!I14) -> 10 | K14: =IF('(3).Midterm Exam'!J14="","",'(3).Midterm Exam'!J14) -> 10 | L14: =IF('(3).Midterm Exam'!K14="","",'(3).Midterm Exam'!K14) -> 10 | ... N14: =IF('(3).Midterm Exam'!M14="","",'(3).Midterm Exam'!M14) -> 10 | O14: =IF(B14="","",IF(D14="Incomplete","Incomplete",IF('(3).Midterm Exam'!N14="Change","Change",IF('(3).Midterm Exam'!N14="Stop","Stop",IF('(3).Midterm Exam'!N14="Incomplete","Incomplete",IF(COUNTBLANK(D14:N14)>=1,"Incomplete",D14*20%+SUM(E14:N14)*80%)))))) -> 96.6
A15: 9 | B15: =IF('(3).Midterm Exam'!B15="","",'(3).Midterm Exam'!B15) -> Lim Davymulika | C15: =IF('(3).Midterm Exam'!C15="","",'(3).Midterm Exam'!C15) -> F | D15: =IF('(2).Midterm Daily'!AH15="","",'(2).Midterm Daily'!AH15) -> 60.875 | E15: =IF('(3).Midterm Exam'!D15="","",'(3).Midterm Exam'!D15) -> 9.5 | F15: =IF('(3).Midterm Exam'!E15="","",'(3).Midterm Exam'!E15) -> 7 | G15: =IF('(3).Midterm Exam'!F15="","",'(3).Midterm Exam'!F15) -> 9 | H15: =IF('(3).Midterm Exam'!G15="","",'(3).Midterm Exam'!G15) -> 6 | I15: =IF('(3).Midterm Exam'!H15="","",'(3).Midterm Exam'!H15) -> 7.75 | J15: =IF('(3).Midterm Exam'!I15="","",'(3).Midterm Exam'!I15) -> 7 | K15: =IF('(3).Midterm Exam'!J15="","",'(3).Midterm Exam'!J15) -> 10 | L15: =IF('(3).Midterm Exam'!K15="","",'(3).Midterm Exam'!K15) -> 7 | ... N15: =IF('(3).Midterm Exam'!M15="","",'(3).Midterm Exam'!M15) -> 9 | O15: =IF(B15="","",IF(D15="Incomplete","Incomplete",IF('(3).Midterm Exam'!N15="Change","Change",IF('(3).Midterm Exam'!N15="Stop","Stop",IF('(3).Midterm Exam'!N15="Incomplete","Incomplete",IF(COUNTBLANK(D15:N15)>=1,"Incomplete",D15*20%+SUM(E15:N15)*80%)))))) -> 77.975
A16: 10 | B16: =IF('(3).Midterm Exam'!B16="","",'(3).Midterm Exam'!B16) -> Lot SamAngvichara | C16: =IF('(3).Midterm Exam'!C16="","",'(3).Midterm Exam'!C16) -> F | D16: =IF('(2).Midterm Daily'!AH16="","",'(2).Midterm Daily'!AH16) -> 93.5 | E16: =IF('(3).Midterm Exam'!D16="","",'(3).Midterm Exam'!D16) -> 9 | F16: =IF('(3).Midterm Exam'!E16="","",'(3).Midterm Exam'!E16) -> 9.5 | G16: =IF('(3).Midterm Exam'!F16="","",'(3).Midterm Exam'!F16) -> 10 | H16: =IF('(3).Midterm Exam'!G16="","",'(3).Midterm Exam'!G16) -> 10 | I16: =IF('(3).Midterm Exam'!H16="","",'(3).Midterm Exam'!H16) -> 10 | J16: =IF('(3).Midterm Exam'!I16="","",'(3).Midterm Exam'!I16) -> 10 | K16: =IF('(3).Midterm Exam'!J16="","",'(3).Midterm Exam'!J16) -> 10 | L16: =IF('(3).Midterm Exam'!K16="","",'(3).Midterm Exam'!K16) -> 10 | ... N16: =IF('(3).Midterm Exam'!M16="","",'(3).Midterm Exam'!M16) -> 9 | O16: =IF(B16="","",IF(D16="Incomplete","Incomplete",IF('(3).Midterm Exam'!N16="Change","Change",IF('(3).Midterm Exam'!N16="Stop","Stop",IF('(3).Midterm Exam'!N16="Incomplete","Incomplete",IF(COUNTBLANK(D16:N16)>=1,"Incomplete",D16*20%+SUM(E16:N16)*80%)))))) -> 96.7
